Workbook

Sheet 01-11-2025
A1: Dailly SMG Pick List | J1: 24AACCN5739J1ZA
A2: Supply Month | B2: 45962
A3: INVOICE NO | B3: KANBAN NO | C3: PART NUMBER | D3: Material Code | E3: PART NAME | F3: SUPPLY DATE | G3: SUPPLY TIME | H3: UNLOADING LOC | I3: Line | J3: Qty Req | K3: Packing Standerd | L3: Packed in | M3: TTL Bin | N3: TORLLY | O3: Vehicle No | P3: Remarks | Q3: Helper Name
A4: G/I/25-26/01061 | B4: 01Y584213272AC5 | C4: 55101M58U10 | D4: =VLOOKUP($C4,Sheet2!$A$2:$B$10,2,0) -> 141110-14600 | E4: CALIPER ASSY,FRONT BRAKE,R | F4: 45962 | G4: 0.35416667 | H4: CA-07 | I4: AC5 | J4: 36 | K4: =VLOOKUP($C4,Sheet2!$A$2:$D$10,4,0) -> 18 | L4: =VLOOKUP($C4,Sheet2!$A$2:$E$10,5,0) -> Trolley (H) | N4: 2 | O4: GJ01ET3377
A5: G/I/25-26/01061 | B5: 01Y584216450AC5 | C5: 55102M58U10 | D5: =VLOOKUP($C5,Sheet2!$A$2:$B$10,2,0) -> 141120-14600 | E5: CALIPER ASSY,FRONT BRAKE,L | F5: 45962 | G5: 0.35416667 | H5: CA-07 | I5: AC5 | J5: 36 | K5: =VLOOKUP($C5,Sheet2!$A$2:$D$10,4,0) -> 18 | L5: =VLOOKUP($C5,Sheet2!$A$2:$E$10,5,0) -> Trolley (H) | O5: GJ01ET3377
A6: G/I/25-26/01061 | B6: 01Y584248335AC5 | C6: 55101M58U10 | D6: =VLOOKUP($C6,Sheet2!$A$2:$B$10,2,0) -> 141110-14600 | E6: CALIPER ASSY,FRONT BRAKE,R | F6: 45962 | G6: 0.35416667 | H6: CA-07 | I6: AC5 | J6: 18 | K6: =VLOOKUP($C6,Sheet2!$A$2:$D$10,4,0) -> 18 | L6: =VLOOKUP($C6,Sheet2!$A$2:$E$10,5,0) -> Trolley (H) | N6: 1 | O6: GJ01ET3377
A7: G/I/25-26/01061 | B7: 01Y584248343AC5 | C7: 55102M58U10 | D7: =VLOOKUP($C7,Sheet2!$A$2:$B$10,2,0) -> 141120-14600 | E7: CALIPER ASSY,FRONT BRAKE,L | F7: 45962 | G7: 0.35416667 | H7: CA-07 | I7: AC5 | J7: 18 | K7: =VLOOKUP($C7,Sheet2!$A$2:$D$10,4,0) -> 18 | L7: =VLOOKUP($C7,Sheet2!$A$2:$E$10,5,0) -> Trolley (H) | O7: GJ01ET3377
A8: G/I/25-26/01061 | B8: 01Y584257091AC5 | C8: 55101M58U10 | D8: =VLOOKUP($C8,Sheet2!$A$2:$B$10,2,0) -> 141110-14600 | E8: CALIPER ASSY,FRONT BRAKE,R | F8: 45962 | G8: 0.35416667 | H8: CA-07 | I8: AC5 | J8: 18 | K8: =VLOOKUP($C8,Sheet2!$A$2:$D$10,4,0) -> 18 | L8: =VLOOKUP($C8,Sheet2!$A$2:$E$10,5,0) -> Trolley (H) | N8: 1 | O8: GJ01ET3377
A9: G/I/25-26/01061 | B9: 01Y584257032AC5 | C9: 55102M58U10 | D9: =VLOOKUP($C9,Sheet2!$A$2:$B$10,2,0) -> 141120-14600 | E9: CALIPER ASSY,FRONT BRAKE,L | F9: 45962 | G9: 0.35416667 | H9: CA-07 | I9: AC5 | J9: 18 | K9: =VLOOKUP($C9,Sheet2!$A$2:$D$10,4,0) -> 18 | L9: =VLOOKUP($C9,Sheet2!$A$2:$E$10,5,0) -> Trolley (H) | O9: GJ01ET3377
A10: G/I/25-26/01061 | B10: 01Y584216484AC5 | C10: 55311M58U00 | D10: =VLOOKUP($C10,Sheet2!$A$2:$B$10,2,0) -> 141185-74670 | E10: DISC,FRONT BRAKE | F10: 45962 | G10: 0.35416667 | H10: CA-07 | I10: AC5 | J10: 40 | K10: =VLOOKUP($C10,Sheet2!$A$2:$D$10,4,0) -> 40 | L10: =VLOOKUP($C10,Sheet2!$A$2:$E$10,5,0) -> Trolley | N10: =J10/K10 -> 1 | O10: GJ01ET3377
A11: G/I/25-26/01061 | B11: 01Y584253371AC5 | C11: 55311M58U00 | D11: =VLOOKUP($C11,Sheet2!$A$2:$B$10,2,0) -> 141185-74670 | E11: DISC,FRONT BRAKE | F11: 45962 | G11: 0.35416667 | H11: CA-07 | I11: AC5 | J11: 40 | K11: =VLOOKUP($C11,Sheet2!$A$2:$D$10,4,0) -> 40 | L11: =VLOOKUP($C11,Sheet2!$A$2:$E$10,5,0) -> Trolley | N11: =J11/K11 -> 1 | O11: GJ01ET3377
A12: G/I/25-26/01061 | B12: 01Y584216514AC5 | C12: 55401M58U00 | D12: =VLOOKUP($C12,Sheet2!$A$2:$B$10,2,0) -> 141140-91211 | E12: CALIPER ASSY,REAR BRAKE,R | F12: 45962 | G12: 0.35416667 | H12: CA-21 | I12: AC5 | J12: 12 | K12: =VLOOKUP($C12,Sheet2!$A$2:$D$10,4,0) -> 2 | L12: =VLOOKUP($C12,Sheet2!$A$2:$E$10,5,0) -> Bin | M12: =J12/K12 -> 6 | O12: GJ01ET3377
A13: G/I/25-26/01061 | B13: 01Y584256036AC5 | C13: 55401M58U00 | D13: =VLOOKUP($C13,Sheet2!$A$2:$B$10,2,0) -> 141140-91211 | E13: CALIPER ASSY,REAR BRAKE,R | F13: 45962 | G13: 0.35416667 | H13: CA-21 | I13: AC5 | J13: 12 | K13: =VLOOKUP($C13,Sheet2!$A$2:$D$10,4,0) -> 2 | L13: =VLOOKUP($C13,Sheet2!$A$2:$E$10,5,0) -> Bin | M13: =J13/K13 -> 6 | O13: GJ01ET3377
A14: G/I/25-26/01061 | B14: 01Y584216557AC5 | C14: 55402M58U00 | D14: =VLOOKUP($C14,Sheet2!$A$2:$B$10,2,0) -> 141150-91211 | E14: CALIPER ASSY,REAR BRAKE,L | F14: 45962 | G14: 0.35416667 | H14: CA-21 | I14: AC5 | J14: 12 | K14: =VLOOKUP($C14,Sheet2!$A$2:$D$10,4,0) -> 2 | L14: =VLOOKUP($C14,Sheet2!$A$2:$E$10,5,0) -> Bin | M14: =J14/K14 -> 6 | O14: GJ01ET3377
A15: G/I/25-26/01061 | B15: 01Y584248351AC5 | C15: 55402M58U00 | D15: =VLOOKUP($C15,Sheet2!$A$2:$B$10,2,0) -> 141150-91211 | E15: CALIPER ASSY,REAR BRAKE,L | F15: 45962 | G15: 0.35416667 | H15: CA-21 | I15: AC5 | J15: 4 | K15: =VLOOKUP($C15,Sheet2!$A$2:$D$10,4,0) -> 2 | L15: =VLOOKUP($C15,Sheet2!$A$2:$E$10,5,0) -> Bin | M15: =J15/K15 -> 2 | O15: GJ01ET3377
A16: G/I/25-26/01061 | B16: 01Y584254513AC5 | C16: 55402M58U00 | D16: =VLOOKUP($C16,Sheet2!$A$2:$B$10,2,0) -> 141150-91211 | E16: CALIPER ASSY,REAR BRAKE,L | F16: 45962 | G16: 0.35416667 | H16: CA-21 | I16: AC5 | J16: 12 | K16: =VLOOKUP($C16,Sheet2!$A$2:$D$10,4,0) -> 2 | L16: =VLOOKUP($C16,Sheet2!$A$2:$E$10,5,0) -> Bin | M16: =J16/K16 -> 6 | O16: GJ01ET3377
A17: G/I/25-26/01061 | B17: 01Y584216590AC5 | C17: 55611M58U00 | D17: =VLOOKUP($C17,Sheet2!$A$2:$B$10,2,0) -> 141186-74360 | E17: DISC,REAR BRAKE | F17: 45962 | G17: 0.35416667 | H17: CA-21 | I17: AC5 | J17: 40 | K17: =VLOOKUP($C17,Sheet2!$A$2:$D$10,4,0) -> 40 | L17: =VLOOKUP($C17,Sheet2!$A$2:$E$10,5,0) -> Trolley | N17: =J17/K17 -> 1 | O17: GJ01ET3377
A18: G/I/25-26/01062 | B18: 01Y584216620AC5 | C18: 56110M58UA1 | D18: =VLOOKUP($C18,Sheet2!$A$2:$B$10,2,0) -> 116040-92240 | E18: ACTUATOR ASSY,NO VARIANT ESP | F18: 45962 | G18: 0.35416667 | H18: CA-01 | I18: AC5 | J18: 12 | K18: =VLOOKUP($C18,Sheet2!$A$2:$D$10,4,0) -> 6 | L18: =VLOOKUP($C18,Sheet2!$A$2:$E$10,5,0) -> Bin | M18: =J18/K18 -> 2 | O18: GJ01ET3377
A19: G/I/25-26/01062 | B19: 01Y584248360AC5 | C19: 56110M58UA1 | D19: =VLOOKUP($C19,Sheet2!$A$2:$B$10,2,0) -> 116040-92240 | E19: ACTUATOR ASSY,NO VARIANT ESP | F19: 45962 | G19: 0.35416667 | H19: CA-01 | I19: AC5 | J19: 6 | K19: =VLOOKUP($C19,Sheet2!$A$2:$D$10,4,0) -> 6 | L19: =VLOOKUP($C19,Sheet2!$A$2:$E$10,5,0) -> Bin | M19: =J19/K19 -> 1 | O19: GJ01ET3377
A20: G/I/25-26/01062 | B20: 01Y584250887AC5 | C20: 56110M58UA1 | D20: =VLOOKUP($C20,Sheet2!$A$2:$B$10,2,0) -> 116040-92240 | E20: ACTUATOR ASSY,NO VARIANT ESP | F20: 45962 | G20: 0.35416667 | H20: CA-01 | I20: AC5 | J20: 12 | K20: =VLOOKUP($C20,Sheet2!$A$2:$D$10,4,0) -> 6 | L20: =VLOOKUP($C20,Sheet2!$A$2:$E$10,5,0) -> Bin | M20: =J20/K20 -> 2 | O20: GJ01ET3377
A21: G/I/25-26/01062 | B21: 01Y584216662AC5 | C21: 5A120M58U01 | D21: =VLOOKUP($C21,Sheet2!$A$2:$B$10,2,0) -> 114010-50820 | E21: CYLINDER ASSY,BK MASTER W/ECU | F21: 45962 | G21: 0.35416667 | H21: CA-01 | I21: AC5 | J21: 8 | K21: =VLOOKUP($C21,Sheet2!$A$2:$D$10,4,0) -> 1 | L21: =VLOOKUP($C21,Sheet2!$A$2:$E$10,5,0) -> Bin | M21: =J21/K21 -> 8 | O21: GJ01ET3377
A22: G/I/25-26/01062 | B22: 01Y584248378AC5 | C22: 5A120M58U01 | D22: =VLOOKUP($C22,Sheet2!$A$2:$B$10,2,0) -> 114010-50820 | E22: CYLINDER ASSY,BK MASTER W/ECU | F22: 45962 | G22: 0.35416667 | H22: CA-01 | I22: AC5 | J22: 6 | K22: =VLOOKUP($C22,Sheet2!$A$2:$D$10,4,0) -> 1 | L22: =VLOOKUP($C22,Sheet2!$A$2:$E$10,5,0) -> Bin | M22: =J22/K22 -> 6 | O22: GJ01ET3377
A23: G/I/25-26/01062 | B23: 01Y584255480AC5 | C23: 5A120M58U01 | D23: =VLOOKUP($C23,Sheet2!$A$2:$B$10,2,0) -> 114010-50820 | E23: CYLINDER ASSY,BK MASTER W/ECU | F23: 45962 | G23: 0.35416667 | H23: CA-01 | I23: AC5 | J23: 6 | K23: =VLOOKUP($C23,Sheet2!$A$2:$D$10,4,0) -> 1 | L23: =VLOOKUP($C23,Sheet2!$A$2:$E$10,5,0) -> Bin | M23: =J23/K23 -> 6 | O23: GJ01ET3377
A24: G/I/25-26/01062 | B24: 01Y584216700AC5 | C24: 5A120M58U50 | D24: =VLOOKUP($C24,Sheet2!$A$2:$B$10,2,0) -> 114010-50830 | E24: CYLINDER ASSY,BK MASTER W/ECU | F24: 45962 | G24: 0.35416667 | H24: CA-01 | I24: AC5 | J24: 4 | K24: =VLOOKUP($C24,Sheet2!$A$2:$D$10,4,0) -> 1 | L24: =VLOOKUP($C24,Sheet2!$A$2:$E$10,5,0) -> Bin | M24: =J24/K24 -> 4 | O24: GJ01ET3377
A25: G/I/25-26/01062 | B25: 01Y584258764AC5 | C25: 5A120M58U50 | D25: =VLOOKUP($C25,Sheet2!$A$2:$B$10,2,0) -> 114010-50830 | E25: CYLINDER ASSY,BK MASTER W/ECU | F25: 45962 | G25: 0.35416667 | H25: CA-01 | I25: AC5 | J25: 7 | K25: =VLOOKUP($C25,Sheet2!$A$2:$D$10,4,0) -> 1 | L25: =VLOOKUP($C25,Sheet2!$A$2:$E$10,5,0) -> Bin | M25: =J25/K25 -> 7 | O25: GJ01ET3377
M26: 62 | N26: 7
A27: G/I/25-26/01064 | B27: 01Y584213280AC5 | C27: 55101M58U10 | D27: =VLOOKUP($C27,Sheet2!$A$2:$B$10,2,0) -> 141110-14600 | E27: CALIPER ASSY,FRONT BRAKE,R | F27: 45962 | G27: 0.47916667 | H27: CA-07 | I27: AC5 | J27: 18 | K27: =VLOOKUP($C27,Sheet2!$A$2:$D$10,4,0) -> 18 | L27: =VLOOKUP($C27,Sheet2!$A$2:$E$10,5,0) -> Trolley (H) | N27: 1 | O27: GJ27TD4419
A28: G/I/25-26/01064 | B28: 01Y584216468AC5 | C28: 55102M58U10 | D28: =VLOOKUP($C28,Sheet2!$A$2:$B$10,2,0) -> 141120-14600 | E28: CALIPER ASSY,FRONT BRAKE,L | F28: 45962 | G28: 0.47916667 | H28: CA-07 | I28: AC5 | J28: 18 | K28: =VLOOKUP($C28,Sheet2!$A$2:$D$10,4,0) -> 18 | L28: =VLOOKUP($C28,Sheet2!$A$2:$E$10,5,0) -> Trolley (H) | O28: GJ27TD4419
A29: G/I/25-26/01064 | B29: 01Y584216492AC5 | C29: 55311M58U00 | D29: =VLOOKUP($C29,Sheet2!$A$2:$B$10,2,0) -> 141185-74670 | E29: DISC,FRONT BRAKE | F29: 45962 | G29: 0.47916667 | H29: CA-07 | I29: AC5 | J29: 40 | K29: =VLOOKUP($C29,Sheet2!$A$2:$D$10,4,0) -> 40 | L29: =VLOOKUP($C29,Sheet2!$A$2:$E$10,5,0) -> Trolley | N29: =J29/K29 -> 1 | O29: GJ27TD4419
A30: G/I/25-26/01064 | B30: 01Y584216522AC5 | C30: 55401M58U00 | D30: =VLOOKUP($C30,Sheet2!$A$2:$B$10,2,0) -> 141140-91211 | E30: CALIPER ASSY,REAR BRAKE,R | F30: 45962 | G30: 0.47916667 | H30: CA-21 | I30: AC5 | J30: 20 | K30: =VLOOKUP($C30,Sheet2!$A$2:$D$10,4,0) -> 2 | L30: =VLOOKUP($C30,Sheet2!$A$2:$E$10,5,0) -> Bin | M30: =J30/K30 -> 10 | O30: GJ27TD4419
A31: G/I/25-26/01064 | B31: 01Y584216565AC5 | C31: 55402M58U00 | D31: =VLOOKUP($C31,Sheet2!$A$2:$B$10,2,0) -> 141150-91211 | E31: CALIPER ASSY,REAR BRAKE,L | F31: 45962 | G31: 0.47916667 | H31: CA-21 | I31: AC5 | J31: 20 | K31: =VLOOKUP($C31,Sheet2!$A$2:$D$10,4,0) -> 2 | L31: =VLOOKUP($C31,Sheet2!$A$2:$E$10,5,0) -> Bin | M31: =J31/K31 -> 10 | O31: GJ27TD4419
A32: G/I/25-26/01064 | B32: 01Y584216603AC5 | C32: 55611M58U00 | D32: =VLOOKUP($C32,Sheet2!$A$2:$B$10,2,0) -> 141186-74360 | E32: DISC,REAR BRAKE | F32: 45962 | G32: 0.47916667 | H32: CA-21 | I32: AC5 | J32: 40 | K32: =VLOOKUP($C32,Sheet2!$A$2:$D$10,4,0) -> 40 | L32: =VLOOKUP($C32,Sheet2!$A$2:$E$10,5,0) -> Trolley | N32: =J32/K32 -> 1 | O32: GJ27TD4419
A33: G/I/25-26/01063 | B33: 01Y584216638AC5 | C33: 56110M58UA1 | D33: =VLOOKUP($C33,Sheet2!$A$2:$B$10,2,0) -> 116040-92240 | E33: ACTUATOR ASSY,NO VARIANT ESP | F33: 45962 | G33: 0.47916667 | H33: CA-01 | I33: AC5 | J33: 24 | K33: =VLOOKUP($C33,Sheet2!$A$2:$D$10,4,0) -> 6 | L33: =VLOOKUP($C33,Sheet2!$A$2:$E$10,5,0) -> Bin | M33: =J33/K33 -> 4 | O33: GJ27TD4419
A34: G/I/25-26/01063 | B34: 01Y584216670AC5 | C34: 5A120M58U01 | D34: =VLOOKUP($C34,Sheet2!$A$2:$B$10,2,0) -> 114010-50820 | E34: CYLINDER ASSY,BK MASTER W/ECU | F34: 45962 | G34: 0.47916667 | H34: CA-01 | I34: AC5 | J34: 9 | K34: =VLOOKUP($C34,Sheet2!$A$2:$D$10,4,0) -> 1 | L34: =VLOOKUP($C34,Sheet2!$A$2:$E$10,5,0) -> Bin | M34: =J34/K34 -> 9 | O34: GJ27TD4419
A35: G/I/25-26/01063 | B35: 01Y584216719AC5 | C35: 5A120M58U50 | D35: =VLOOKUP($C35,Sheet2!$A$2:$B$10,2,0) -> 114010-50830 | E35: CYLINDER ASSY,BK MASTER W/ECU | F35: 45962 | G35: 0.47916667 | H35: CA-01 | I35: AC5 | J35: 11 | K35: =VLOOKUP($C35,Sheet2!$A$2:$D$10,4,0) -> 1 | L35: =VLOOKUP($C35,Sheet2!$A$2:$E$10,5,0) -> Bin | M35: =J35/K35 -> 11 | O35: GJ27TD4419
M36: 44 | N36: 3
A37: G/I/25-26/01065 | B37: 01Y584213264AC5 | C37: 55101M58U10 | D37: =VLOOKUP($C37,Sheet2!$A$2:$B$10,2,0) -> 141110-14600 | E37: CALIPER ASSY,FRONT BRAKE,R | F37: 45962 | G37: 0.6875 | H37: CA-07 | I37: AC5 | J37: 18 | K37: =VLOOKUP($C37,Sheet2!$A$2:$D$10,4,0) -> 18 | L37: =VLOOKUP($C37,Sheet2!$A$2:$E$10,5,0) -> Trolley (H) | N37: 1 | O37: GJ07TU3500
A38: G/I/25-26/01065 | B38: 01Y584213299AC5 | C38: 55102M58U10 | D38: =VLOOKUP($C38,Sheet2!$A$2:$B$10,2,0) -> 141120-14600 | E38: CALIPER ASSY,FRONT BRAKE,L | F38: 45962 | G38: 0.6875 | H38: CA-07 | I38: AC5 | J38: 18 | K38: =VLOOKUP($C38,Sheet2!$A$2:$D$10,4,0) -> 18 | L38: =VLOOKUP($C38,Sheet2!$A$2:$E$10,5,0) -> Trolley (H) | O38: GJ07TU3500
A39: G/I/25-26/01065 | B39: 01Y584216476AC5 | C39: 55311M58U00 | D39: =VLOOKUP($C39,Sheet2!$A$2:$B$10,2,0) -> 141185-74670 | E39: DISC,FRONT BRAKE | F39: 45962 | G39: 0.6875 | H39: CA-07 | I39: AC5 | J39: 80 | K39: =VLOOKUP($C39,Sheet2!$A$2:$D$10,4,0) -> 40 | L39: =VLOOKUP($C39,Sheet2!$A$2:$E$10,5,0) -> Trolley | N39: =J39/K39 -> 2 | O39: GJ07TU3500
A40: G/I/25-26/01065 | B40: 01Y584216530AC5 | C40: 55401M58U00 | D40: =VLOOKUP($C40,Sheet2!$A$2:$B$10,2,0) -> 141140-91211 | E40: CALIPER ASSY,REAR BRAKE,R | F40: 45962 | G40: 0.6875 | H40: CA-21 | I40: AC5 | J40: 20 | K40: =VLOOKUP($C40,Sheet2!$A$2:$D$10,4,0) -> 2 | L40: =VLOOKUP($C40,Sheet2!$A$2:$E$10,5,0) -> Bin | M40: =J40/K40 -> 10 | O40: GJ07TU3500
...

Sheet 03-11-2025
A1: Dailly SMG Pick List | J1: 24AACCN5739J1ZA
A2: Supply Month | B2: 45964
A3: INVOICE NO | B3: KANBAN NO | C3: PART NUMBER | D3: Material Code | E3: PART NAME | F3: SUPPLY DATE | G3: SUPPLY TIME | H3: UNLOADING LOC | I3: Line | J3: Qty Req | K3: Packing Standerd | L3: Packed in | M3: TTL Bin | N3: TORLLY | O3: Vehicle No | P3: Remarks | Q3: Helper Name
A4: G/I/25-26/01069 | B4: 03Y584852410AC5 | C4: 55101M58U10 | D4: =VLOOKUP($C4,Sheet2!$A$2:$B$10,2,0) -> 141110-14600 | E4: CALIPER ASSY,FRONT BRAKE,R | F4: 45964 | G4: 0.35416667 | H4: CA-07 | I4: AC5 | J4: 18 | K4: =VLOOKUP($C4,Sheet2!$A$2:$D$10,4,0) -> 18 | L4: =VLOOKUP($C4,Sheet2!$A$2:$E$10,5,0) -> Trolley (H) | N4: 1 | O4: GJ23Y8525
A5: G/I/25-26/01069 | B5: 03Y584852453AC5 | C5: 55102M58U10 | D5: =VLOOKUP($C5,Sheet2!$A$2:$B$10,2,0) -> 141120-14600 | E5: CALIPER ASSY,FRONT BRAKE,L | F5: 45964 | G5: 0.35416667 | H5: CA-07 | I5: AC5 | J5: 18 | K5: =VLOOKUP($C5,Sheet2!$A$2:$D$10,4,0) -> 18 | L5: =VLOOKUP($C5,Sheet2!$A$2:$E$10,5,0) -> Trolley (H) | O5: GJ23Y8525
A6: G/I/25-26/01069 | B6: 03Y584852488AC5 | C6: 55311M58U00 | D6: =VLOOKUP($C6,Sheet2!$A$2:$B$10,2,0) -> 141185-74670 | E6: DISC,FRONT BRAKE | F6: 45964 | G6: 0.35416667 | H6: CA-07 | I6: AC5 | J6: 40 | K6: =VLOOKUP($C6,Sheet2!$A$2:$D$10,4,0) -> 40 | L6: =VLOOKUP($C6,Sheet2!$A$2:$E$10,5,0) -> Trolley | N6: =J6/K6 -> 1 | O6: GJ23Y8525
A7: G/I/25-26/01069 | B7: 03Y584886218AC5 | C7: 55311M58U00 | D7: =VLOOKUP($C7,Sheet2!$A$2:$B$10,2,0) -> 141185-74670 | E7: DISC,FRONT BRAKE | F7: 45964 | G7: 0.35416667 | H7: CA-07 | I7: AC5 | J7: 40 | K7: =VLOOKUP($C7,Sheet2!$A$2:$D$10,4,0) -> 40 | L7: =VLOOKUP($C7,Sheet2!$A$2:$E$10,5,0) -> Trolley | N7: =J7/K7 -> 1 | O7: GJ23Y8525
A8: G/I/25-26/01069 | B8: 03Y584852526AC5 | C8: 55401M58U00 | D8: =VLOOKUP($C8,Sheet2!$A$2:$B$10,2,0) -> 141140-91211 | E8: CALIPER ASSY,REAR BRAKE,R | F8: 45964 | G8: 0.35416667 | H8: CA-21 | I8: AC5 | J8: 20 | K8: =VLOOKUP($C8,Sheet2!$A$2:$D$10,4,0) -> 2 | L8: =VLOOKUP($C8,Sheet2!$A$2:$E$10,5,0) -> Bin | M8: =J8/K8 -> 10 | O8: GJ23Y8525
A9: G/I/25-26/01069 | B9: 03Y584888768AC5 | C9: 55401M58U00 | D9: =VLOOKUP($C9,Sheet2!$A$2:$B$10,2,0) -> 141140-91211 | E9: CALIPER ASSY,REAR BRAKE,R | F9: 45964 | G9: 0.35416667 | H9: CA-21 | I9: AC5 | J9: 4 | K9: =VLOOKUP($C9,Sheet2!$A$2:$D$10,4,0) -> 2 | L9: =VLOOKUP($C9,Sheet2!$A$2:$E$10,5,0) -> Bin | M9: =J9/K9 -> 2 | O9: GJ23Y8525
A10: G/I/25-26/01069 | B10: 03Y584852569AC5 | C10: 55402M58U00 | D10: =VLOOKUP($C10,Sheet2!$A$2:$B$10,2,0) -> 141150-91211 | E10: CALIPER ASSY,REAR BRAKE,L | F10: 45964 | G10: 0.35416667 | H10: CA-21 | I10: AC5 | J10: 20 | K10: =VLOOKUP($C10,Sheet2!$A$2:$D$10,4,0) -> 2 | L10: =VLOOKUP($C10,Sheet2!$A$2:$E$10,5,0) -> Bin | M10: =J10/K10 -> 10 | O10: GJ23Y8525
A11: G/I/25-26/01069 | B11: 03Y584881259AC5 | C11: 55402M58U00 | D11: =VLOOKUP($C11,Sheet2!$A$2:$B$10,2,0) -> 141150-91211 | E11: CALIPER ASSY,REAR BRAKE,L | F11: 45964 | G11: 0.35416667 | H11: CA-21 | I11: AC5 | J11: 4 | K11: =VLOOKUP($C11,Sheet2!$A$2:$D$10,4,0) -> 2 | L11: =VLOOKUP($C11,Sheet2!$A$2:$E$10,5,0) -> Bin | M11: =J11/K11 -> 2 | O11: GJ23Y8525
A12: G/I/25-26/01069 | B12: 03Y584852607AC5 | C12: 55611M58U00 | D12: =VLOOKUP($C12,Sheet2!$A$2:$B$10,2,0) -> 141186-74360 | E12: DISC,REAR BRAKE | F12: 45964 | G12: 0.35416667 | H12: CA-21 | I12: AC5 | J12: 40 | K12: =VLOOKUP($C12,Sheet2!$A$2:$D$10,4,0) -> 40 | L12: =VLOOKUP($C12,Sheet2!$A$2:$E$10,5,0) -> Trolley | N12: =J12/K12 -> 1 | O12: GJ23Y8525
A13: G/I/25-26/01070 | B13: 03Y584852640AC5 | C13: 56110M58UA1 | D13: =VLOOKUP($C13,Sheet2!$A$2:$B$10,2,0) -> 116040-92240 | E13: ACTUATOR ASSY,NO VARIANT ESP | F13: 45964 | G13: 0.35416667 | H13: CA-01 | I13: AC5 | J13: 18 | K13: =VLOOKUP($C13,Sheet2!$A$2:$D$10,4,0) -> 6 | L13: =VLOOKUP($C13,Sheet2!$A$2:$E$10,5,0) -> Bin | M13: =J13/K13 -> 3 | O13: GJ23Y8525
A14: G/I/25-26/01070 | B14: 03Y584852682AC5 | C14: 5A120M58U01 | D14: =VLOOKUP($C14,Sheet2!$A$2:$B$10,2,0) -> 114010-50820 | E14: CYLINDER ASSY,BK MASTER W/ECU | F14: 45964 | G14: 0.35416667 | H14: CA-01 | I14: AC5 | J14: 12 | K14: =VLOOKUP($C14,Sheet2!$A$2:$D$10,4,0) -> 1 | L14: =VLOOKUP($C14,Sheet2!$A$2:$E$10,5,0) -> Bin | M14: =J14/K14 -> 12 | O14: GJ23Y8525
A15: G/I/25-26/01070 | B15: 03Y584879408AC5 | C15: 5A120M58U01 | D15: =VLOOKUP($C15,Sheet2!$A$2:$B$10,2,0) -> 114010-50820 | E15: CYLINDER ASSY,BK MASTER W/ECU | F15: 45964 | G15: 0.35416667 | H15: CA-01 | I15: AC5 | J15: 2 | K15: =VLOOKUP($C15,Sheet2!$A$2:$D$10,4,0) -> 1 | L15: =VLOOKUP($C15,Sheet2!$A$2:$E$10,5,0) -> Bin | M15: =J15/K15 -> 2 | O15: GJ23Y8525
A16: G/I/25-26/01070 | B16: 03Y584852720AC5 | C16: 5A120M58U50 | D16: =VLOOKUP($C16,Sheet2!$A$2:$B$10,2,0) -> 114010-50830 | E16: CYLINDER ASSY,BK MASTER W/ECU | F16: 45964 | G16: 0.35416667 | H16: CA-01 | I16: AC5 | J16: 8 | K16: =VLOOKUP($C16,Sheet2!$A$2:$D$10,4,0) -> 1 | L16: =VLOOKUP($C16,Sheet2!$A$2:$E$10,5,0) -> Bin | M16: =J16/K16 -> 8 | O16: GJ23Y8525
A17: G/I/25-26/01070 | B17: 03Y584884010AC5 | C17: 5A120M58U50 | D17: =VLOOKUP($C17,Sheet2!$A$2:$B$10,2,0) -> 114010-50830 | E17: CYLINDER ASSY,BK MASTER W/ECU | F17: 45964 | G17: 0.35416667 | H17: CA-01 | I17: AC5 | J17: 3 | K17: =VLOOKUP($C17,Sheet2!$A$2:$D$10,4,0) -> 1 | L17: =VLOOKUP($C17,Sheet2!$A$2:$E$10,5,0) -> Bin | M17: =J17/K17 -> 3 | O17: GJ23Y8525
M18: 52 | N18: 4
A19: G/I/25-26/01071 | B19: 03Y584852429AC5 | C19: 55101M58U10 | D19: =VLOOKUP($C19,Sheet2!$A$2:$B$10,2,0) -> 141110-14600 | E19: CALIPER ASSY,FRONT BRAKE,R | F19: 45964 | G19: 0.5625 | H19: CA-07 | I19: AC5 | J19: 18 | K19: =VLOOKUP($C19,Sheet2!$A$2:$D$10,4,0) -> 18 | L19: =VLOOKUP($C19,Sheet2!$A$2:$E$10,5,0) -> Trolley (H) | N19: 1 | O19: GJ02ZZ7144
A20: G/I/25-26/01071 | B20: 03Y584852461AC5 | C20: 55102M58U10 | D20: =VLOOKUP($C20,Sheet2!$A$2:$B$10,2,0) -> 141120-14600 | E20: CALIPER ASSY,FRONT BRAKE,L | F20: 45964 | G20: 0.5625 | H20: CA-07 | I20: AC5 | J20: 18 | K20: =VLOOKUP($C20,Sheet2!$A$2:$D$10,4,0) -> 18 | L20: =VLOOKUP($C20,Sheet2!$A$2:$E$10,5,0) -> Trolley (H) | O20: GJ02ZZ7144
A21: G/I/25-26/01071 | B21: 03Y584852496AC5 | C21: 55311M58U00 | D21: =VLOOKUP($C21,Sheet2!$A$2:$B$10,2,0) -> 141185-74670 | E21: DISC,FRONT BRAKE | F21: 45964 | G21: 0.5625 | H21: CA-07 | I21: AC5 | J21: 40 | K21: =VLOOKUP($C21,Sheet2!$A$2:$D$10,4,0) -> 40 | L21: =VLOOKUP($C21,Sheet2!$A$2:$E$10,5,0) -> Trolley | N21: =J21/K21 -> 1 | O21: GJ02ZZ7144
A22: G/I/25-26/01071 | B22: 03Y584852534AC5 | C22: 55401M58U00 | D22: =VLOOKUP($C22,Sheet2!$A$2:$B$10,2,0) -> 141140-91211 | E22: CALIPER ASSY,REAR BRAKE,R | F22: 45964 | G22: 0.5625 | H22: CA-21 | I22: AC5 | J22: 20 | K22: =VLOOKUP($C22,Sheet2!$A$2:$D$10,4,0) -> 2 | L22: =VLOOKUP($C22,Sheet2!$A$2:$E$10,5,0) -> Bin | M22: =J22/K22 -> 10 | O22: GJ02ZZ7144
A23: G/I/25-26/01071 | B23: 03Y584852577AC5 | C23: 55402M58U00 | D23: =VLOOKUP($C23,Sheet2!$A$2:$B$10,2,0) -> 141150-91211 | E23: CALIPER ASSY,REAR BRAKE,L | F23: 45964 | G23: 0.5625 | H23: CA-21 | I23: AC5 | J23: 20 | K23: =VLOOKUP($C23,Sheet2!$A$2:$D$10,4,0) -> 2 | L23: =VLOOKUP($C23,Sheet2!$A$2:$E$10,5,0) -> Bin | M23: =J23/K23 -> 10 | O23: GJ02ZZ7144
A24: G/I/25-26/01071 | B24: 03Y584852615AC5 | C24: 55611M58U00 | D24: =VLOOKUP($C24,Sheet2!$A$2:$B$10,2,0) -> 141186-74360 | E24: DISC,REAR BRAKE | F24: 45964 | G24: 0.5625 | H24: CA-21 | I24: AC5 | J24: 40 | K24: =VLOOKUP($C24,Sheet2!$A$2:$D$10,4,0) -> 40 | L24: =VLOOKUP($C24,Sheet2!$A$2:$E$10,5,0) -> Trolley | N24: =J24/K24 -> 1 | O24: GJ02ZZ7144
A25: G/I/25-26/01072 | B25: 03Y584852658AC5 | C25: 56110M58UA1 | D25: =VLOOKUP($C25,Sheet2!$A$2:$B$10,2,0) -> 116040-92240 | E25: ACTUATOR ASSY,NO VARIANT ESP | F25: 45964 | G25: 0.5625 | H25: CA-01 | I25: AC5 | J25: 18 | K25: =VLOOKUP($C25,Sheet2!$A$2:$D$10,4,0) -> 6 | L25: =VLOOKUP($C25,Sheet2!$A$2:$E$10,5,0) -> Bin | M25: =J25/K25 -> 3 | O25: GJ02ZZ7144
A26: G/I/25-26/01072 | B26: 03Y584852690AC5 | C26: 5A120M58U01 | D26: =VLOOKUP($C26,Sheet2!$A$2:$B$10,2,0) -> 114010-50820 | E26: CYLINDER ASSY,BK MASTER W/ECU | F26: 45964 | G26: 0.5625 | H26: CA-01 | I26: AC5 | J26: 10 | K26: =VLOOKUP($C26,Sheet2!$A$2:$D$10,4,0) -> 1 | L26: =VLOOKUP($C26,Sheet2!$A$2:$E$10,5,0) -> Bin | M26: =J26/K26 -> 10 | O26: GJ02ZZ7144
A27: G/I/25-26/01072 | B27: 03Y584852739AC5 | C27: 5A120M58U50 | D27: =VLOOKUP($C27,Sheet2!$A$2:$B$10,2,0) -> 114010-50830 | E27: CYLINDER ASSY,BK MASTER W/ECU | F27: 45964 | G27: 0.5625 | H27: CA-01 | I27: AC5 | J27: 10 | K27: =VLOOKUP($C27,Sheet2!$A$2:$D$10,4,0) -> 1 | L27: =VLOOKUP($C27,Sheet2!$A$2:$E$10,5,0) -> Bin | M27: =J27/K27 -> 10 | O27: GJ02ZZ7144
M28: 43 | N28: 3
A29: G/I/25-26/01074 | B29: 03Y584852437AC5 | C29: 55101M58U10 | D29: =VLOOKUP($C29,Sheet2!$A$2:$B$10,2,0) -> 141110-14600 | E29: CALIPER ASSY,FRONT BRAKE,R | F29: 45964 | G29: 0.77083333 | H29: CA-07 | I29: AC5 | J29: 18 | K29: =VLOOKUP($C29,Sheet2!$A$2:$D$10,4,0) -> 18 | L29: =VLOOKUP($C29,Sheet2!$A$2:$E$10,5,0) -> Trolley (H) | N29: 1 | O29: GJ27TD4419
A30: G/I/25-26/01074 | B30: 03Y584852470AC5 | C30: 55102M58U10 | D30: =VLOOKUP($C30,Sheet2!$A$2:$B$10,2,0) -> 141120-14600 | E30: CALIPER ASSY,FRONT BRAKE,L | F30: 45964 | G30: 0.77083333 | H30: CA-07 | I30: AC5 | J30: 18 | K30: =VLOOKUP($C30,Sheet2!$A$2:$D$10,4,0) -> 18 | L30: =VLOOKUP($C30,Sheet2!$A$2:$E$10,5,0) -> Trolley (H) | O30: GJ27TD4419
A31: G/I/25-26/01074 | B31: 03Y584852500AC5 | C31: 55311M58U00 | D31: =VLOOKUP($C31,Sheet2!$A$2:$B$10,2,0) -> 141185-74670 | E31: DISC,FRONT BRAKE | F31: 45964 | G31: 0.77083333 | H31: CA-07 | I31: AC5 | J31: 40 | K31: =VLOOKUP($C31,Sheet2!$A$2:$D$10,4,0) -> 40 | L31: =VLOOKUP($C31,Sheet2!$A$2:$E$10,5,0) -> Trolley | N31: =J31/K31 -> 1 | O31: GJ27TD4419
A32: G/I/25-26/01074 | B32: 03Y584852542AC5 | C32: 55401M58U00 | D32: =VLOOKUP($C32,Sheet2!$A$2:$B$10,2,0) -> 141140-91211 | E32: CALIPER ASSY,REAR BRAKE,R | F32: 45964 | G32: 0.77083333 | H32: CA-21 | I32: AC5 | J32: 18 | K32: =VLOOKUP($C32,Sheet2!$A$2:$D$10,4,0) -> 2 | L32: =VLOOKUP($C32,Sheet2!$A$2:$E$10,5,0) -> Bin | M32: =J32/K32 -> 9 | O32: GJ27TD4419
A33: G/I/25-26/01074 | B33: 03Y584852585AC5 | C33: 55402M58U00 | D33: =VLOOKUP($C33,Sheet2!$A$2:$B$10,2,0) -> 141150-91211 | E33: CALIPER ASSY,REAR BRAKE,L | F33: 45964 | G33: 0.77083333 | H33: CA-21 | I33: AC5 | J33: 18 | K33: =VLOOKUP($C33,Sheet2!$A$2:$D$10,4,0) -> 2 | L33: =VLOOKUP($C33,Sheet2!$A$2:$E$10,5,0) -> Bin | M33: =J33/K33 -> 9 | O33: GJ27TD4419
A34: G/I/25-26/01074 | B34: 03Y584852623AC5 | C34: 55611M58U00 | D34: =VLOOKUP($C34,Sheet2!$A$2:$B$10,2,0) -> 141186-74360 | E34: DISC,REAR BRAKE | F34: 45964 | G34: 0.77083333 | H34: CA-21 | I34: AC5 | J34: 40 | K34: =VLOOKUP($C34,Sheet2!$A$2:$D$10,4,0) -> 40 | L34: =VLOOKUP($C34,Sheet2!$A$2:$E$10,5,0) -> Trolley | N34: =J34/K34 -> 1 | O34: GJ27TD4419
A35: G/I/25-26/01075 | B35: 03Y584852666AC5 | C35: 56110M58UA1 | D35: =VLOOKUP($C35,Sheet2!$A$2:$B$10,2,0) -> 116040-92240 | E35: ACTUATOR ASSY,NO VARIANT ESP | F35: 45964 | G35: 0.77083333 | H35: CA-01 | I35: AC5 | J35: 18 | K35: =VLOOKUP($C35,Sheet2!$A$2:$D$10,4,0) -> 6 | L35: =VLOOKUP($C35,Sheet2!$A$2:$E$10,5,0) -> Bin | M35: =J35/K35 -> 3 | O35: GJ27TD4419
A36: G/I/25-26/01075 | B36: 03Y584852704AC5 | C36: 5A120M58U01 | D36: =VLOOKUP($C36,Sheet2!$A$2:$B$10,2,0) -> 114010-50820 | E36: CYLINDER ASSY,BK MASTER W/ECU | F36: 45964 | G36: 0.77083333 | H36: CA-01 | I36: AC5 | J36: 6 | K36: =VLOOKUP($C36,Sheet2!$A$2:$D$10,4,0) -> 1 | L36: =VLOOKUP($C36,Sheet2!$A$2:$E$10,5,0) -> Bin | M36: =J36/K36 -> 6 | O36: GJ27TD4419
A37: G/I/25-26/01075 | B37: 03Y584852747AC5 | C37: 5A120M58U50 | D37: =VLOOKUP($C37,Sheet2!$A$2:$B$10,2,0) -> 114010-50830 | E37: CYLINDER ASSY,BK MASTER W/ECU | F37: 45964 | G37: 0.77083333 | H37: CA-01 | I37: AC5 | J37: 12 | K37: =VLOOKUP($C37,Sheet2!$A$2:$D$10,4,0) -> 1 | L37: =VLOOKUP($C37,Sheet2!$A$2:$E$10,5,0) -> Bin | M37: =J37/K37 -> 12 | O37: GJ27TD4419
M38: 39 | N38: 3
A39: G/I/25-26/01076 | B39: 03Y584852402AC5 | C39: 55101M58U10 | D39: =VLOOKUP($C39,Sheet2!$A$2:$B$10,2,0) -> 141110-14600 | E39: CALIPER ASSY,FRONT BRAKE,R | F39: 45964 | G39: 0.97916667 | H39: CA-07 | I39: AC5 | J39: 18 | K39: =VLOOKUP($C39,Sheet2!$A$2:$D$10,4,0) -> 18 | L39: =VLOOKUP($C39,Sheet2!$A$2:$E$10,5,0) -> Trolley (H) | N39: 1 | O39: GJ23Y8525
A40: G/I/25-26/01076 | B40: 03Y584852445AC5 | C40: 55102M58U10 | D40: =VLOOKUP($C40,Sheet2!$A$2:$B$10,2,0) -> 141120-14600 | E40: CALIPER ASSY,FRONT BRAKE,L | F40: 45964 | G40: 0.97916667 | H40: CA-07 | I40: AC5 | J40: 18 | K40: =VLOOKUP($C40,Sheet2!$A$2:$D$10,4,0) -> 18 | L40: =VLOOKUP($C40,Sheet2!$A$2:$E$10,5,0) -> Trolley (H) | O40: GJ23Y8525
...

Sheet 04-11-2025
A1: Dailly SMG Pick List | J1: 24AACCN5739J1ZA
A2: Supply Month | B2: 45965
A3: INVOICE NO | B3: KANBAN NO | C3: PART NUMBER | D3: Material Code | E3: PART NAME | F3: SUPPLY DATE | G3: SUPPLY TIME | H3: UNLOADING LOC | I3: Line | J3: Qty Req | K3: Packing Standerd | L3: Packed in | M3: TTL Bin | N3: TORLLY | O3: Vehicle No | P3: Remarks | Q3: Helper Name
A4: G/I/25-26/01078 | B4: 04Y585850039AC5 | C4: 55101M58U10 | D4: =VLOOKUP($C4,Sheet2!$A$2:$B$10,2,0) -> 141110-14600 | E4: CALIPER ASSY,FRONT BRAKE,R | F4: 45965 | G4: 0.35416667 | H4: CA-07 | I4: AC5 | J4: 18 | K4: =VLOOKUP($C4,Sheet2!$A$2:$D$10,4,0) -> 18 | L4: =VLOOKUP($C4,Sheet2!$A$2:$E$10,5,0) -> Trolley (H) | N4: 1 | O4: GJ02ZZ7144
A5: G/I/25-26/01078 | B5: 04Y585850063AC5 | C5: 55102M58U10 | D5: =VLOOKUP($C5,Sheet2!$A$2:$B$10,2,0) -> 141120-14600 | E5: CALIPER ASSY,FRONT BRAKE,L | F5: 45965 | G5: 0.35416667 | H5: CA-07 | I5: AC5 | J5: 18 | K5: =VLOOKUP($C5,Sheet2!$A$2:$D$10,4,0) -> 18 | L5: =VLOOKUP($C5,Sheet2!$A$2:$E$10,5,0) -> Trolley (H) | O5: GJ02ZZ7144
A6: G/I/25-26/01078 | B6: 04Y585850080AC5 | C6: 55311M58U00 | D6: =VLOOKUP($C6,Sheet2!$A$2:$B$10,2,0) -> 141185-74670 | E6: DISC,FRONT BRAKE | F6: 45965 | G6: 0.35416667 | H6: CA-07 | I6: AC5 | J6: 40 | K6: =VLOOKUP($C6,Sheet2!$A$2:$D$10,4,0) -> 40 | L6: =VLOOKUP($C6,Sheet2!$A$2:$E$10,5,0) -> Trolley | N6: =J6/K6 -> 1 | O6: GJ02ZZ7144
A7: G/I/25-26/01078 | B7: 04Y585850128AC5 | C7: 55401M58U00 | D7: =VLOOKUP($C7,Sheet2!$A$2:$B$10,2,0) -> 141140-91211 | E7: CALIPER ASSY,REAR BRAKE,R | F7: 45965 | G7: 0.35416667 | H7: CA-21 | I7: AC5 | J7: 20 | K7: =VLOOKUP($C7,Sheet2!$A$2:$D$10,4,0) -> 2 | L7: =VLOOKUP($C7,Sheet2!$A$2:$E$10,5,0) -> Bin | M7: =J7/K7 -> 10 | O7: GJ02ZZ7144
A8: G/I/25-26/01078 | B8: 04Y585850160AC5 | C8: 55402M58U00 | D8: =VLOOKUP($C8,Sheet2!$A$2:$B$10,2,0) -> 141150-91211 | E8: CALIPER ASSY,REAR BRAKE,L | F8: 45965 | G8: 0.35416667 | H8: CA-21 | I8: AC5 | J8: 20 | K8: =VLOOKUP($C8,Sheet2!$A$2:$D$10,4,0) -> 2 | L8: =VLOOKUP($C8,Sheet2!$A$2:$E$10,5,0) -> Bin | M8: =J8/K8 -> 10 | O8: GJ02ZZ7144
A9: G/I/25-26/01078 | B9: 04Y585850209AC5 | C9: 55611M58U00 | D9: =VLOOKUP($C9,Sheet2!$A$2:$B$10,2,0) -> 141186-74360 | E9: DISC,REAR BRAKE | F9: 45965 | G9: 0.35416667 | H9: CA-21 | I9: AC5 | J9: 40 | K9: =VLOOKUP($C9,Sheet2!$A$2:$D$10,4,0) -> 40 | L9: =VLOOKUP($C9,Sheet2!$A$2:$E$10,5,0) -> Trolley | N9: =J9/K9 -> 1 | O9: GJ02ZZ7144
A10: G/I/25-26/01079 | B10: 04Y585850241AC5 | C10: 56110M58UA1 | D10: =VLOOKUP($C10,Sheet2!$A$2:$B$10,2,0) -> 116040-92240 | E10: ACTUATOR ASSY,NO VARIANT ESP | F10: 45965 | G10: 0.35416667 | H10: CA-01 | I10: AC5 | J10: 18 | K10: =VLOOKUP($C10,Sheet2!$A$2:$D$10,4,0) -> 6 | L10: =VLOOKUP($C10,Sheet2!$A$2:$E$10,5,0) -> Bin | M10: =J10/K10 -> 3 | O10: GJ02ZZ7144
A11: G/I/25-26/01079 | B11: 04Y585850284AC5 | C11: 5A120M58U01 | D11: =VLOOKUP($C11,Sheet2!$A$2:$B$10,2,0) -> 114010-50820 | E11: CYLINDER ASSY,BK MASTER W/ECU | F11: 45965 | G11: 0.35416667 | H11: CA-01 | I11: AC5 | J11: 8 | K11: =VLOOKUP($C11,Sheet2!$A$2:$D$10,4,0) -> 1 | L11: =VLOOKUP($C11,Sheet2!$A$2:$E$10,5,0) -> Bin | M11: =J11/K11 -> 8 | O11: GJ02ZZ7144
A12: G/I/25-26/01079 | B12: 04Y585858862AC5 | C12: 5A120M58U50 | D12: =VLOOKUP($C12,Sheet2!$A$2:$B$10,2,0) -> 114010-50830 | E12: CYLINDER ASSY,BK MASTER W/ECU | F12: 45965 | G12: 0.35416667 | H12: CA-01 | I12: AC5 | J12: 12 | K12: =VLOOKUP($C12,Sheet2!$A$2:$D$10,4,0) -> 1 | L12: =VLOOKUP($C12,Sheet2!$A$2:$E$10,5,0) -> Bin | M12: =J12/K12 -> 12 | O12: GJ02ZZ7144
A13: G/I/25-26/01079 | B13: 04Y585884731AC5 | C13: 5A120M58U50 | D13: =VLOOKUP($C13,Sheet2!$A$2:$B$10,2,0) -> 114010-50830 | E13: CYLINDER ASSY,BK MASTER W/ECU | F13: 45965 | G13: 0.35416667 | H13: CA-01 | I13: AC5 | J13: 1 | K13: =VLOOKUP($C13,Sheet2!$A$2:$D$10,4,0) -> 1 | L13: =VLOOKUP($C13,Sheet2!$A$2:$E$10,5,0) -> Bin | M13: =J13/K13 -> 1 | O13: GJ02ZZ7144
M14: 44 | N14: 3
A15: G/I/25-26/01080 | B15: 04Y585850047AC5 | C15: 55101M58U10 | D15: =VLOOKUP($C15,Sheet2!$A$2:$B$10,2,0) -> 141110-14600 | E15: CALIPER ASSY,FRONT BRAKE,R | F15: 45965 | G15: 0.5625 | H15: CA-07 | I15: AC5 | J15: 36 | K15: =VLOOKUP($C15,Sheet2!$A$2:$D$10,4,0) -> 18 | L15: =VLOOKUP($C15,Sheet2!$A$2:$E$10,5,0) -> Trolley (H) | N15: 2 | O15: GJ23Y8525
A16: G/I/25-26/01080 | B16: 04Y585850071AC5 | C16: 55102M58U10 | D16: =VLOOKUP($C16,Sheet2!$A$2:$B$10,2,0) -> 141120-14600 | E16: CALIPER ASSY,FRONT BRAKE,L | F16: 45965 | G16: 0.5625 | H16: CA-07 | I16: AC5 | J16: 36 | K16: =VLOOKUP($C16,Sheet2!$A$2:$D$10,4,0) -> 18 | L16: =VLOOKUP($C16,Sheet2!$A$2:$E$10,5,0) -> Trolley (H) | O16: GJ23Y8525
A17: G/I/25-26/01080 | B17: 04Y585850098AC5 | C17: 55311M58U00 | D17: =VLOOKUP($C17,Sheet2!$A$2:$B$10,2,0) -> 141185-74670 | E17: DISC,FRONT BRAKE | F17: 45965 | G17: 0.5625 | H17: CA-07 | I17: AC5 | J17: 40 | K17: =VLOOKUP($C17,Sheet2!$A$2:$D$10,4,0) -> 40 | L17: =VLOOKUP($C17,Sheet2!$A$2:$E$10,5,0) -> Trolley | N17: =J17/K17 -> 1 | O17: GJ23Y8525
A18: G/I/25-26/01080 | B18: 04Y585850136AC5 | C18: 55401M58U00 | D18: =VLOOKUP($C18,Sheet2!$A$2:$B$10,2,0) -> 141140-91211 | E18: CALIPER ASSY,REAR BRAKE,R | F18: 45965 | G18: 0.5625 | H18: CA-21 | I18: AC5 | J18: 20 | K18: =VLOOKUP($C18,Sheet2!$A$2:$D$10,4,0) -> 2 | L18: =VLOOKUP($C18,Sheet2!$A$2:$E$10,5,0) -> Bin | M18: =J18/K18 -> 10 | O18: GJ23Y8525
A19: G/I/25-26/01080 | B19: 04Y585850179AC5 | C19: 55402M58U00 | D19: =VLOOKUP($C19,Sheet2!$A$2:$B$10,2,0) -> 141150-91211 | E19: CALIPER ASSY,REAR BRAKE,L | F19: 45965 | G19: 0.5625 | H19: CA-21 | I19: AC5 | J19: 20 | K19: =VLOOKUP($C19,Sheet2!$A$2:$D$10,4,0) -> 2 | L19: =VLOOKUP($C19,Sheet2!$A$2:$E$10,5,0) -> Bin | M19: =J19/K19 -> 10 | O19: GJ23Y8525
A20: G/I/25-26/01080 | B20: 04Y585850217AC5 | C20: 55611M58U00 | D20: =VLOOKUP($C20,Sheet2!$A$2:$B$10,2,0) -> 141186-74360 | E20: DISC,REAR BRAKE | F20: 45965 | G20: 0.5625 | H20: CA-21 | I20: AC5 | J20: 40 | K20: =VLOOKUP($C20,Sheet2!$A$2:$D$10,4,0) -> 40 | L20: =VLOOKUP($C20,Sheet2!$A$2:$E$10,5,0) -> Trolley | N20: =J20/K20 -> 1 | O20: GJ23Y8525
A21: G/I/25-26/01081 | B21: 04Y585850250AC5 | C21: 56110M58UA1 | D21: =VLOOKUP($C21,Sheet2!$A$2:$B$10,2,0) -> 116040-92240 | E21: ACTUATOR ASSY,NO VARIANT ESP | F21: 45965 | G21: 0.5625 | H21: CA-01 | I21: AC5 | J21: 24 | K21: =VLOOKUP($C21,Sheet2!$A$2:$D$10,4,0) -> 6 | L21: =VLOOKUP($C21,Sheet2!$A$2:$E$10,5,0) -> Bin | M21: =J21/K21 -> 4 | O21: GJ23Y8525
A22: G/I/25-26/01081 | B22: 04Y585850292AC5 | C22: 5A120M58U01 | D22: =VLOOKUP($C22,Sheet2!$A$2:$B$10,2,0) -> 114010-50820 | E22: CYLINDER ASSY,BK MASTER W/ECU | F22: 45965 | G22: 0.5625 | H22: CA-01 | I22: AC5 | J22: 9 | K22: =VLOOKUP($C22,Sheet2!$A$2:$D$10,4,0) -> 1 | L22: =VLOOKUP($C22,Sheet2!$A$2:$E$10,5,0) -> Bin | M22: =J22/K22 -> 9 | O22: GJ23Y8525
A23: G/I/25-26/01081 | B23: 04Y585858870AC5 | C23: 5A120M58U50 | D23: =VLOOKUP($C23,Sheet2!$A$2:$B$10,2,0) -> 114010-50830 | E23: CYLINDER ASSY,BK MASTER W/ECU | F23: 45965 | G23: 0.5625 | H23: CA-01 | I23: AC5 | J23: 11 | K23: =VLOOKUP($C23,Sheet2!$A$2:$D$10,4,0) -> 1 | L23: =VLOOKUP($C23,Sheet2!$A$2:$E$10,5,0) -> Bin | M23: =J23/K23 -> 11 | O23: GJ23Y8525
M24: 44 | N24: 4
A25: G/I/25-26/01082 | B25: 04Y585850020AC5 | C25: 55101M58U10 | D25: =VLOOKUP($C25,Sheet2!$A$2:$B$10,2,0) -> 141110-14600 | E25: CALIPER ASSY,FRONT BRAKE,R | F25: 45965 | G25: 0.77083333 | H25: CA-07 | I25: AC5 | J25: 36 | K25: =VLOOKUP($C25,Sheet2!$A$2:$D$10,4,0) -> 18 | L25: =VLOOKUP($C25,Sheet2!$A$2:$E$10,5,0) -> Trolley (H) | N25: 2 | O25: GJ27TD4419
A26: G/I/25-26/01082 | B26: 04Y585850055AC5 | C26: 55102M58U10 | D26: =VLOOKUP($C26,Sheet2!$A$2:$B$10,2,0) -> 141120-14600 | E26: CALIPER ASSY,FRONT BRAKE,L | F26: 45965 | G26: 0.77083333 | H26: CA-07 | I26: AC5 | J26: 36 | K26: =VLOOKUP($C26,Sheet2!$A$2:$D$10,4,0) -> 18 | L26: =VLOOKUP($C26,Sheet2!$A$2:$E$10,5,0) -> Trolley (H) | O26: GJ27TD4419
A27: G/I/25-26/01082 | B27: 04Y585850101AC5 | C27: 55311M58U00 | D27: =VLOOKUP($C27,Sheet2!$A$2:$B$10,2,0) -> 141185-74670 | E27: DISC,FRONT BRAKE | F27: 45965 | G27: 0.77083333 | H27: CA-07 | I27: AC5 | J27: 40 | K27: =VLOOKUP($C27,Sheet2!$A$2:$D$10,4,0) -> 40 | L27: =VLOOKUP($C27,Sheet2!$A$2:$E$10,5,0) -> Trolley | N27: =J27/K27 -> 1 | O27: GJ27TD4419
A28: G/I/25-26/01082 | B28: 04Y585850144AC5 | C28: 55401M58U00 | D28: =VLOOKUP($C28,Sheet2!$A$2:$B$10,2,0) -> 141140-91211 | E28: CALIPER ASSY,REAR BRAKE,R | F28: 45965 | G28: 0.77083333 | H28: CA-21 | I28: AC5 | J28: 12 | K28: =VLOOKUP($C28,Sheet2!$A$2:$D$10,4,0) -> 2 | L28: =VLOOKUP($C28,Sheet2!$A$2:$E$10,5,0) -> Bin | M28: =J28/K28 -> 6 | O28: GJ27TD4419
A29: G/I/25-26/01082 | B29: 04Y585850187AC5 | C29: 55402M58U00 | D29: =VLOOKUP($C29,Sheet2!$A$2:$B$10,2,0) -> 141150-91211 | E29: CALIPER ASSY,REAR BRAKE,L | F29: 45965 | G29: 0.77083333 | H29: CA-21 | I29: AC5 | J29: 12 | K29: =VLOOKUP($C29,Sheet2!$A$2:$D$10,4,0) -> 2 | L29: =VLOOKUP($C29,Sheet2!$A$2:$E$10,5,0) -> Bin | M29: =J29/K29 -> 6 | O29: GJ27TD4419
A30: G/I/25-26/01082 | B30: 04Y585850225AC5 | C30: 55611M58U00 | D30: =VLOOKUP($C30,Sheet2!$A$2:$B$10,2,0) -> 141186-74360 | E30: DISC,REAR BRAKE | F30: 45965 | G30: 0.77083333 | H30: CA-21 | I30: AC5 | J30: 40 | K30: =VLOOKUP($C30,Sheet2!$A$2:$D$10,4,0) -> 40 | L30: =VLOOKUP($C30,Sheet2!$A$2:$E$10,5,0) -> Trolley | N30: =J30/K30 -> 1 | O30: GJ27TD4419
A31: G/I/25-26/01083 | B31: 04Y585850268AC5 | C31: 56110M58UA1 | D31: =VLOOKUP($C31,Sheet2!$A$2:$B$10,2,0) -> 116040-92240 | E31: ACTUATOR ASSY,NO VARIANT ESP | F31: 45965 | G31: 0.77083333 | H31: CA-01 | I31: AC5 | J31: 12 | K31: =VLOOKUP($C31,Sheet2!$A$2:$D$10,4,0) -> 6 | L31: =VLOOKUP($C31,Sheet2!$A$2:$E$10,5,0) -> Bin | M31: =J31/K31 -> 2 | O31: GJ27TD4419
A32: G/I/25-26/01083 | B32: 04Y585850306AC5 | C32: 5A120M58U01 | D32: =VLOOKUP($C32,Sheet2!$A$2:$B$10,2,0) -> 114010-50820 | E32: CYLINDER ASSY,BK MASTER W/ECU | F32: 45965 | G32: 0.77083333 | H32: CA-01 | I32: AC5 | J32: 5 | K32: =VLOOKUP($C32,Sheet2!$A$2:$D$10,4,0) -> 1 | L32: =VLOOKUP($C32,Sheet2!$A$2:$E$10,5,0) -> Bin | M32: =J32/K32 -> 5 | O32: GJ27TD4419
A33: G/I/25-26/01083 | B33: 04Y585858889AC5 | C33: 5A120M58U50 | D33: =VLOOKUP($C33,Sheet2!$A$2:$B$10,2,0) -> 114010-50830 | E33: CYLINDER ASSY,BK MASTER W/ECU | F33: 45965 | G33: 0.77083333 | H33: CA-01 | I33: AC5 | J33: 8 | K33: =VLOOKUP($C33,Sheet2!$A$2:$D$10,4,0) -> 1 | L33: =VLOOKUP($C33,Sheet2!$A$2:$E$10,5,0) -> Bin | M33: =J33/K33 -> 8 | O33: GJ27TD4419
A34: G/I/25-26/01087 | B34: 05Y586502190AC5 | C34: 55101M58U10 | D34: =VLOOKUP($C34,Sheet2!$A$2:$B$10,2,0) -> 141110-14600 | E34: CALIPER ASSY,FRONT BRAKE,R | F34: 45965 | G34: 0.78125 | H34: CA-07 | I34: AC5 | J34: 18 | K34: =VLOOKUP($C34,Sheet2!$A$2:$D$10,4,0) -> 18 | L34: =VLOOKUP($C34,Sheet2!$A$2:$E$10,5,0) -> Trolley (H) | N34: 1 | O34: GJ27TD4419
A35: G/I/25-26/01087 | B35: 05Y586502271AC5 | C35: 55102M58U10 | D35: =VLOOKUP($C35,Sheet2!$A$2:$B$10,2,0) -> 141120-14600 | E35: CALIPER ASSY,FRONT BRAKE,L | F35: 45965 | G35: 0.78125 | H35: CA-07 | I35: AC5 | J35: 18 | K35: =VLOOKUP($C35,Sheet2!$A$2:$D$10,4,0) -> 18 | L35: =VLOOKUP($C35,Sheet2!$A$2:$E$10,5,0) -> Trolley (H) | O35: GJ27TD4419
A36: G/I/25-26/01087 | B36: 05Y586500155AC5 | C36: 55311M58U00 | D36: =VLOOKUP($C36,Sheet2!$A$2:$B$10,2,0) -> 141185-74670 | E36: DISC,FRONT BRAKE | F36: 45965 | G36: 0.78125 | H36: CA-07 | I36: AC5 | J36: 40 | K36: =VLOOKUP($C36,Sheet2!$A$2:$D$10,4,0) -> 40 | L36: =VLOOKUP($C36,Sheet2!$A$2:$E$10,5,0) -> Trolley | N36: 1 | O36: GJ27TD4419
A37: G/I/25-26/01087 | B37: 05Y586499742AC5 | C37: 55401M58U00 | D37: =VLOOKUP($C37,Sheet2!$A$2:$B$10,2,0) -> 141140-91211 | E37: CALIPER ASSY,REAR BRAKE,R | F37: 45965 | G37: 0.78125 | H37: CA-21 | I37: AC5 | J37: 12 | K37: =VLOOKUP($C37,Sheet2!$A$2:$D$10,4,0) -> 2 | L37: =VLOOKUP($C37,Sheet2!$A$2:$E$10,5,0) -> Bin | M37: =J37/K37 -> 6 | O37: GJ27TD4419
A38: G/I/25-26/01087 | B38: 05Y586499696AC5 | C38: 55402M58U00 | D38: =VLOOKUP($C38,Sheet2!$A$2:$B$10,2,0) -> 141150-91211 | E38: CALIPER ASSY,REAR BRAKE,L | F38: 45965 | G38: 0.78125 | H38: CA-21 | I38: AC5 | J38: 12 | K38: =VLOOKUP($C38,Sheet2!$A$2:$D$10,4,0) -> 2 | L38: =VLOOKUP($C38,Sheet2!$A$2:$E$10,5,0) -> Bin | M38: =J38/K38 -> 6 | O38: GJ27TD4419
A39: G/I/25-26/01087 | B39: 05Y586498690AC5 | C39: 55611M58U00 | D39: =VLOOKUP($C39,Sheet2!$A$2:$B$10,2,0) -> 141186-74360 | E39: DISC,REAR BRAKE | F39: 45965 | G39: 0.78125 | H39: CA-21 | I39: AC5 | J39: 40 | K39: =VLOOKUP($C39,Sheet2!$A$2:$D$10,4,0) -> 40 | L39: =VLOOKUP($C39,Sheet2!$A$2:$E$10,5,0) -> Trolley | N39: 1 | O39: GJ27TD4419
A40: G/I/25-26/01090 | B40: 05Y586502247AC5 | C40: 56110M58UA1 | D40: =VLOOKUP($C40,Sheet2!$A$2:$B$10,2,0) -> 116040-92240 | E40: ACTUATOR ASSY,NO VARIANT ESP | F40: 45965 | G40: 0.78125 | H40: CA-01 | I40: AC5 | J40: 12 | K40: =VLOOKUP($C40,Sheet2!$A$2:$D$10,4,0) -> 6 | L40: =VLOOKUP($C40,Sheet2!$A$2:$E$10,5,0) -> Bin | M40: =J40/K40 -> 2 | O40: GJ27TD4419
...

Sheet 05-11-2025
A1: Dailly SMG Pick List | J1: 24AACCN5739J1ZA
A2: Supply Month | B2: 45966
A3: INVOICE NO | B3: KANBAN NO | C3: PART NUMBER | D3: Material Code | E3: PART NAME | F3: SUPPLY DATE | G3: SUPPLY TIME | H3: UNLOADING LOC | I3: Line | J3: Qty Req | K3: Packing Standerd | L3: Packed in | M3: TTL Bin | N3: TORLLY | O3: Vehicle No | P3: INV NO
A4: G/I/25-26/01091 | B4: 05Y586426222AC5 | C4: 55101M58U10 | D4: =VLOOKUP($C4,Sheet2!$A$2:$B$10,2,0) -> 141110-14600 | E4: CALIPER ASSY,FRONT BRAKE,R | F4: 45966 | G4: 0.27083333 | H4: CA-07 | I4: AC5 | J4: 18 | K4: =VLOOKUP($C4,Sheet2!$A$2:$D$10,4,0) -> 18 | L4: =VLOOKUP($C4,Sheet2!$A$2:$E$10,5,0) -> Trolley (H) | N4: 1 | O4: GJ23Y8525 | P4: AN0250008197
A5: G/I/25-26/01091 | B5: 05Y586426265AC5 | C5: 55102M58U10 | D5: =VLOOKUP($C5,Sheet2!$A$2:$B$10,2,0) -> 141120-14600 | E5: CALIPER ASSY,FRONT BRAKE,L | F5: 45966 | G5: 0.27083333 | H5: CA-07 | I5: AC5 | J5: 18 | K5: =VLOOKUP($C5,Sheet2!$A$2:$D$10,4,0) -> 18 | L5: =VLOOKUP($C5,Sheet2!$A$2:$E$10,5,0) -> Trolley (H) | O5: GJ23Y8525 | P5: AN0250008197
A6: G/I/25-26/01091 | B6: 05Y586426303AC5 | C6: 55311M58U00 | D6: =VLOOKUP($C6,Sheet2!$A$2:$B$10,2,0) -> 141185-74670 | E6: DISC,FRONT BRAKE | F6: 45966 | G6: 0.27083333 | H6: CA-07 | I6: AC5 | J6: 40 | K6: =VLOOKUP($C6,Sheet2!$A$2:$D$10,4,0) -> 40 | L6: =VLOOKUP($C6,Sheet2!$A$2:$E$10,5,0) -> Trolley | N6: =J6/K6 -> 1 | O6: GJ23Y8525 | P6: 91100866-29 Qty. /9100099020-11 Qty.
A7: G/I/25-26/01091 | B7: 05Y586426346AC5 | C7: 55401M58U00 | D7: =VLOOKUP($C7,Sheet2!$A$2:$B$10,2,0) -> 141140-91211 | E7: CALIPER ASSY,REAR BRAKE,R | F7: 45966 | G7: 0.27083333 | H7: CA-21 | I7: AC5 | J7: 24 | K7: =VLOOKUP($C7,Sheet2!$A$2:$D$10,4,0) -> 2 | L7: =VLOOKUP($C7,Sheet2!$A$2:$E$10,5,0) -> Bin | M7: =J7/K7 -> 12 | O7: GJ23Y8525 | P7: 12508Q100183
A8: G/I/25-26/01091 | B8: 05Y586506331AC5 | C8: 55401M58U00 | D8: =VLOOKUP($C8,Sheet2!$A$2:$B$10,2,0) -> 141140-91211 | E8: CALIPER ASSY,REAR BRAKE,R | F8: 45966 | G8: 0.27083333 | H8: CA-21 | I8: AC5 | J8: 8 | K8: =VLOOKUP($C8,Sheet2!$A$2:$D$10,4,0) -> 2 | L8: =VLOOKUP($C8,Sheet2!$A$2:$E$10,5,0) -> Bin | M8: =J8/K8 -> 4 | O8: GJ23Y8525 | P8: 12508Q100183
A9: G/I/25-26/01091 | B9: 05Y586426389AC5 | C9: 55402M58U00 | D9: =VLOOKUP($C9,Sheet2!$A$2:$B$10,2,0) -> 141150-91211 | E9: CALIPER ASSY,REAR BRAKE,L | F9: 45966 | G9: 0.27083333 | H9: CA-21 | I9: AC5 | J9: 24 | K9: =VLOOKUP($C9,Sheet2!$A$2:$D$10,4,0) -> 2 | L9: =VLOOKUP($C9,Sheet2!$A$2:$E$10,5,0) -> Bin | M9: =J9/K9 -> 12 | O9: GJ23Y8525 | P9: 12508Q100183
A10: G/I/25-26/01091 | B10: 05Y586505637AC5 | C10: 55402M58U00 | D10: =VLOOKUP($C10,Sheet2!$A$2:$B$10,2,0) -> 141150-91211 | E10: CALIPER ASSY,REAR BRAKE,L | F10: 45966 | G10: 0.27083333 | H10: CA-21 | I10: AC5 | J10: 8 | K10: =VLOOKUP($C10,Sheet2!$A$2:$D$10,4,0) -> 2 | L10: =VLOOKUP($C10,Sheet2!$A$2:$E$10,5,0) -> Bin | M10: =J10/K10 -> 4 | O10: GJ23Y8525 | P10: 12508Q100183
A11: G/I/25-26/01091 | B11: 05Y586426427AC5 | C11: 55611M58U00 | D11: =VLOOKUP($C11,Sheet2!$A$2:$B$10,2,0) -> 141186-74360 | E11: DISC,REAR BRAKE | F11: 45966 | G11: 0.27083333 | H11: CA-21 | I11: AC5 | J11: 40 | K11: =VLOOKUP($C11,Sheet2!$A$2:$D$10,4,0) -> 40 | L11: =VLOOKUP($C11,Sheet2!$A$2:$E$10,5,0) -> Trolley | N11: =J11/K11 -> 1 | O11: GJ23Y8525 | P11: 910102103
A12: G/I/25-26/01092 | B12: 05Y586426460AC5 | C12: 56110M58UA1 | D12: =VLOOKUP($C12,Sheet2!$A$2:$B$10,2,0) -> 116040-92240 | E12: ACTUATOR ASSY,NO VARIANT ESP | F12: 45966 | G12: 0.27083333 | H12: CA-01 | I12: AC5 | J12: 24 | K12: =VLOOKUP($C12,Sheet2!$A$2:$D$10,4,0) -> 6 | L12: =VLOOKUP($C12,Sheet2!$A$2:$E$10,5,0) -> Bin | M12: =J12/K12 -> 4 | O12: GJ23Y8525 | P12: NA
A13: G/I/25-26/01092 | B13: 05Y586515624AC5 | C13: 56110M58UA1 | D13: =VLOOKUP($C13,Sheet2!$A$2:$B$10,2,0) -> 116040-92240 | E13: ACTUATOR ASSY,NO VARIANT ESP | F13: 45966 | G13: 0.27083333 | H13: CA-01 | I13: AC5 | J13: 6 | K13: =VLOOKUP($C13,Sheet2!$A$2:$D$10,4,0) -> 6 | L13: =VLOOKUP($C13,Sheet2!$A$2:$E$10,5,0) -> Bin | M13: =J13/K13 -> 1 | O13: GJ23Y8525 | P13: NA
A14: G/I/25-26/01092 | B14: 05Y586426508AC5 | C14: 5A120M58U01 | D14: =VLOOKUP($C14,Sheet2!$A$2:$B$10,2,0) -> 114010-50820 | E14: CYLINDER ASSY,BK MASTER W/ECU | F14: 45966 | G14: 0.27083333 | H14: CA-01 | I14: AC5 | J14: 11 | K14: =VLOOKUP($C14,Sheet2!$A$2:$D$10,4,0) -> 1 | L14: =VLOOKUP($C14,Sheet2!$A$2:$E$10,5,0) -> Bin | M14: =J14/K14 -> 11 | O14: GJ23Y8525 | P14: NA
A15: G/I/25-26/01092 | B15: 05Y586514326AC5 | C15: 5A120M58U01 | D15: =VLOOKUP($C15,Sheet2!$A$2:$B$10,2,0) -> 114010-50820 | E15: CYLINDER ASSY,BK MASTER W/ECU | F15: 45966 | G15: 0.27083333 | H15: CA-01 | I15: AC5 | J15: 3 | K15: =VLOOKUP($C15,Sheet2!$A$2:$D$10,4,0) -> 1 | L15: =VLOOKUP($C15,Sheet2!$A$2:$E$10,5,0) -> Bin | M15: =J15/K15 -> 3 | O15: GJ23Y8525 | P15: NA
A16: G/I/25-26/01092 | B16: 05Y586426540AC5 | C16: 5A120M58U50 | D16: =VLOOKUP($C16,Sheet2!$A$2:$B$10,2,0) -> 114010-50830 | E16: CYLINDER ASSY,BK MASTER W/ECU | F16: 45966 | G16: 0.27083333 | H16: CA-01 | I16: AC5 | J16: 13 | K16: =VLOOKUP($C16,Sheet2!$A$2:$D$10,4,0) -> 1 | L16: =VLOOKUP($C16,Sheet2!$A$2:$E$10,5,0) -> Bin | M16: =J16/K16 -> 13 | O16: GJ23Y8525 | P16: NA
A17: G/I/25-26/01092 | B17: 05Y586508733AC5 | C17: 5A120M58U50 | D17: =VLOOKUP($C17,Sheet2!$A$2:$B$10,2,0) -> 114010-50830 | E17: CYLINDER ASSY,BK MASTER W/ECU | F17: 45966 | G17: 0.27083333 | H17: CA-01 | I17: AC5 | J17: 4 | K17: =VLOOKUP($C17,Sheet2!$A$2:$D$10,4,0) -> 1 | L17: =VLOOKUP($C17,Sheet2!$A$2:$E$10,5,0) -> Bin | M17: =J17/K17 -> 4 | O17: GJ23Y8525 | P17: NA
A18: G/I/25-26/01093 | B18: 05Y586426230AC5 | C18: 55101M58U10 | D18: =VLOOKUP($C18,Sheet2!$A$2:$B$10,2,0) -> 141110-14600 | E18: CALIPER ASSY,FRONT BRAKE,R | F18: 45966 | G18: 0.39583333 | H18: CA-07 | I18: AC5 | J18: 18 | K18: =VLOOKUP($C18,Sheet2!$A$2:$D$10,4,0) -> 18 | L18: =VLOOKUP($C18,Sheet2!$A$2:$E$10,5,0) -> Trolley (H) | N18: 1 | O18: GJ23Y8525 | P18: AN0250008334
A19: G/I/25-26/01093 | B19: 05Y586426273AC5 | C19: 55102M58U10 | D19: =VLOOKUP($C19,Sheet2!$A$2:$B$10,2,0) -> 141120-14600 | E19: CALIPER ASSY,FRONT BRAKE,L | F19: 45966 | G19: 0.39583333 | H19: CA-07 | I19: AC5 | J19: 18 | K19: =VLOOKUP($C19,Sheet2!$A$2:$D$10,4,0) -> 18 | L19: =VLOOKUP($C19,Sheet2!$A$2:$E$10,5,0) -> Trolley (H) | O19: GJ23Y8525 | P19: AN0250008197
A20: G/I/25-26/01093 | B20: 05Y586426311AC5 | C20: 55311M58U00 | D20: =VLOOKUP($C20,Sheet2!$A$2:$B$10,2,0) -> 141185-74670 | E20: DISC,FRONT BRAKE | F20: 45966 | G20: 0.39583333 | H20: CA-07 | I20: AC5 | J20: 40 | K20: =VLOOKUP($C20,Sheet2!$A$2:$D$10,4,0) -> 40 | L20: =VLOOKUP($C20,Sheet2!$A$2:$E$10,5,0) -> Trolley | N20: =J20/K20 -> 1 | O20: GJ23Y8525 | P20: 910099020
A21: G/I/25-26/01093 | B21: 05Y586426354AC5 | C21: 55401M58U00 | D21: =VLOOKUP($C21,Sheet2!$A$2:$B$10,2,0) -> 141140-91211 | E21: CALIPER ASSY,REAR BRAKE,R | F21: 45966 | G21: 0.39583333 | H21: CA-21 | I21: AC5 | J21: 20 | K21: =VLOOKUP($C21,Sheet2!$A$2:$D$10,4,0) -> 2 | L21: =VLOOKUP($C21,Sheet2!$A$2:$E$10,5,0) -> Bin | M21: =J21/K21 -> 10 | O21: GJ23Y8525 | P21: 12508Q100183
A22: G/I/25-26/01093 | B22: 05Y586426397AC5 | C22: 55402M58U00 | D22: =VLOOKUP($C22,Sheet2!$A$2:$B$10,2,0) -> 141150-91211 | E22: CALIPER ASSY,REAR BRAKE,L | F22: 45966 | G22: 0.39583333 | H22: CA-21 | I22: AC5 | J22: 20 | K22: =VLOOKUP($C22,Sheet2!$A$2:$D$10,4,0) -> 2 | L22: =VLOOKUP($C22,Sheet2!$A$2:$E$10,5,0) -> Bin | M22: =J22/K22 -> 10 | O22: GJ23Y8525 | P22: 12508Q100183
A23: G/I/25-26/01093 | B23: 05Y586426435AC5 | C23: 55611M58U00 | D23: =VLOOKUP($C23,Sheet2!$A$2:$B$10,2,0) -> 141186-74360 | E23: DISC,REAR BRAKE | F23: 45966 | G23: 0.39583333 | H23: CA-21 | I23: AC5 | J23: 40 | K23: =VLOOKUP($C23,Sheet2!$A$2:$D$10,4,0) -> 40 | L23: =VLOOKUP($C23,Sheet2!$A$2:$E$10,5,0) -> Trolley | N23: =J23/K23 -> 1 | O23: GJ23Y8525 | P23: 910102103
A24: G/I/25-26/01094 | B24: 05Y586426478AC5 | C24: 56110M58UA1 | D24: =VLOOKUP($C24,Sheet2!$A$2:$B$10,2,0) -> 116040-92240 | E24: ACTUATOR ASSY,NO VARIANT ESP | F24: 45966 | G24: 0.39583333 | H24: CA-01 | I24: AC5 | J24: 18 | K24: =VLOOKUP($C24,Sheet2!$A$2:$D$10,4,0) -> 6 | L24: =VLOOKUP($C24,Sheet2!$A$2:$E$10,5,0) -> Bin | M24: =J24/K24 -> 3 | O24: GJ23Y8525 | P24: NA
A25: G/I/25-26/01094 | B25: 05Y586426516AC5 | C25: 5A120M58U01 | D25: =VLOOKUP($C25,Sheet2!$A$2:$B$10,2,0) -> 114010-50820 | E25: CYLINDER ASSY,BK MASTER W/ECU | F25: 45966 | G25: 0.39583333 | H25: CA-01 | I25: AC5 | J25: 11 | K25: =VLOOKUP($C25,Sheet2!$A$2:$D$10,4,0) -> 1 | L25: =VLOOKUP($C25,Sheet2!$A$2:$E$10,5,0) -> Bin | M25: =J25/K25 -> 11 | O25: GJ23Y8525 | P25: NA
A26: G/I/25-26/01094 | B26: 05Y586426559AC5 | C26: 5A120M58U50 | D26: =VLOOKUP($C26,Sheet2!$A$2:$B$10,2,0) -> 114010-50830 | E26: CYLINDER ASSY,BK MASTER W/ECU | F26: 45966 | G26: 0.39583333 | H26: CA-01 | I26: AC5 | J26: 9 | K26: =VLOOKUP($C26,Sheet2!$A$2:$D$10,4,0) -> 1 | L26: =VLOOKUP($C26,Sheet2!$A$2:$E$10,5,0) -> Bin | M26: =J26/K26 -> 9 | O26: GJ23Y8525 | P26: NA
M27: 111 | N27: 6
A28: G/I/25-26/01095 | B28: 05Y586426249AC5 | C28: 55101M58U10 | D28: =VLOOKUP($C28,Sheet2!$A$2:$B$10,2,0) -> 141110-14600 | E28: CALIPER ASSY,FRONT BRAKE,R | F28: 45966 | G28: 0.64583333 | H28: CA-07 | I28: AC5 | J28: 18 | K28: =VLOOKUP($C28,Sheet2!$A$2:$D$10,4,0) -> 18 | L28: =VLOOKUP($C28,Sheet2!$A$2:$E$10,5,0) -> Trolley (H) | N28: 1 | O28: GJ02ZZ7144 | P28: AN0250008334
A29: G/I/25-26/01095 | B29: 05Y586426281AC5 | C29: 55102M58U10 | D29: =VLOOKUP($C29,Sheet2!$A$2:$B$10,2,0) -> 141120-14600 | E29: CALIPER ASSY,FRONT BRAKE,L | F29: 45966 | G29: 0.64583333 | H29: CA-07 | I29: AC5 | J29: 18 | K29: =VLOOKUP($C29,Sheet2!$A$2:$D$10,4,0) -> 18 | L29: =VLOOKUP($C29,Sheet2!$A$2:$E$10,5,0) -> Trolley (H) | O29: GJ02ZZ7144 | P29: AN0250008334-16 Qty./ AN0250008197-2 Qty.
A30: G/I/25-26/01095 | B30: 05Y586426320AC5 | C30: 55311M58U00 | D30: =VLOOKUP($C30,Sheet2!$A$2:$B$10,2,0) -> 141185-74670 | E30: DISC,FRONT BRAKE | F30: 45966 | G30: 0.64583333 | H30: CA-07 | I30: AC5 | J30: 40 | K30: =VLOOKUP($C30,Sheet2!$A$2:$D$10,4,0) -> 40 | L30: =VLOOKUP($C30,Sheet2!$A$2:$E$10,5,0) -> Trolley | N30: =J30/K30 -> 1 | O30: GJ02ZZ7144 | P30: 910099020
A31: G/I/25-26/01095 | B31: 05Y586426362AC5 | C31: 55401M58U00 | D31: =VLOOKUP($C31,Sheet2!$A$2:$B$10,2,0) -> 141140-91211 | E31: CALIPER ASSY,REAR BRAKE,R | F31: 45966 | G31: 0.64583333 | H31: CA-21 | I31: AC5 | J31: 20 | K31: =VLOOKUP($C31,Sheet2!$A$2:$D$10,4,0) -> 2 | L31: =VLOOKUP($C31,Sheet2!$A$2:$E$10,5,0) -> Bin | M31: =J31/K31 -> 10 | O31: GJ02ZZ7144 | P31: 12508Q100183
A32: G/I/25-26/01095 | B32: 05Y586426400AC5 | C32: 55402M58U00 | D32: =VLOOKUP($C32,Sheet2!$A$2:$B$10,2,0) -> 141150-91211 | E32: CALIPER ASSY,REAR BRAKE,L | F32: 45966 | G32: 0.64583333 | H32: CA-21 | I32: AC5 | J32: 20 | K32: =VLOOKUP($C32,Sheet2!$A$2:$D$10,4,0) -> 2 | L32: =VLOOKUP($C32,Sheet2!$A$2:$E$10,5,0) -> Bin | M32: =J32/K32 -> 10 | O32: GJ02ZZ7144 | P32: 12508Q100183
A33: G/I/25-26/01095 | B33: 05Y586426443AC5 | C33: 55611M58U00 | D33: =VLOOKUP($C33,Sheet2!$A$2:$B$10,2,0) -> 141186-74360 | E33: DISC,REAR BRAKE | F33: 45966 | G33: 0.64583333 | H33: CA-21 | I33: AC5 | J33: 40 | K33: =VLOOKUP($C33,Sheet2!$A$2:$D$10,4,0) -> 40 | L33: =VLOOKUP($C33,Sheet2!$A$2:$E$10,5,0) -> Trolley | N33: =J33/K33 -> 1 | O33: GJ02ZZ7144 | P33: 910102103
A34: G/I/25-26/01096 | B34: 05Y586426486AC5 | C34: 56110M58UA1 | D34: =VLOOKUP($C34,Sheet2!$A$2:$B$10,2,0) -> 116040-92240 | E34: ACTUATOR ASSY,NO VARIANT ESP | F34: 45966 | G34: 0.64583333 | H34: CA-01 | I34: AC5 | J34: 18 | K34: =VLOOKUP($C34,Sheet2!$A$2:$D$10,4,0) -> 6 | L34: =VLOOKUP($C34,Sheet2!$A$2:$E$10,5,0) -> Bin | M34: =J34/K34 -> 3 | O34: GJ02ZZ7144 | P34: NA
A35: G/I/25-26/01096 | B35: 05Y586426524AC5 | C35: 5A120M58U01 | D35: =VLOOKUP($C35,Sheet2!$A$2:$B$10,2,0) -> 114010-50820 | E35: CYLINDER ASSY,BK MASTER W/ECU | F35: 45966 | G35: 0.64583333 | H35: CA-01 | I35: AC5 | J35: 6 | K35: =VLOOKUP($C35,Sheet2!$A$2:$D$10,4,0) -> 1 | L35: =VLOOKUP($C35,Sheet2!$A$2:$E$10,5,0) -> Bin | M35: =J35/K35 -> 6 | O35: GJ02ZZ7144 | P35: NA
A36: G/I/25-26/01096 | B36: 05Y586426567AC5 | C36: 5A120M58U50 | D36: =VLOOKUP($C36,Sheet2!$A$2:$B$10,2,0) -> 114010-50830 | E36: CYLINDER ASSY,BK MASTER W/ECU | F36: 45966 | G36: 0.64583333 | H36: CA-01 | I36: AC5 | J36: 14 | K36: =VLOOKUP($C36,Sheet2!$A$2:$D$10,4,0) -> 1 | L36: =VLOOKUP($C36,Sheet2!$A$2:$E$10,5,0) -> Bin | M36: =J36/K36 -> 14 | O36: GJ02ZZ7144 | P36: NA
M37: 43 | N37: 3
A38: G/I/25-26/01097 | B38: 05Y586426214AC5 | C38: 55101M58U10 | D38: =VLOOKUP($C38,Sheet2!$A$2:$B$10,2,0) -> 141110-14600 | E38: CALIPER ASSY,FRONT BRAKE,R | F38: 45966 | G38: 0.97916667 | H38: CA-07 | I38: AC5 | J38: 36 | K38: =VLOOKUP($C38,Sheet2!$A$2:$D$10,4,0) -> 18 | L38: =VLOOKUP($C38,Sheet2!$A$2:$E$10,5,0) -> Trolley (H) | N38: 2 | O38: GJ27TD4419 | P38: AN0250008334
A39: G/I/25-26/01097 | B39: 05Y586426257AC5 | C39: 55102M58U10 | D39: =VLOOKUP($C39,Sheet2!$A$2:$B$10,2,0) -> 141120-14600 | E39: CALIPER ASSY,FRONT BRAKE,L | F39: 45966 | G39: 0.97916667 | H39: CA-07 | I39: AC5 | J39: 36 | K39: =VLOOKUP($C39,Sheet2!$A$2:$D$10,4,0) -> 18 | L39: =VLOOKUP($C39,Sheet2!$A$2:$E$10,5,0) -> Trolley (H) | O39: GJ27TD4419 | P39: AN0250008334
A40: G/I/25-26/01097 | B40: 05Y586426290AC5 | C40: 55311M58U00 | D40: =VLOOKUP($C40,Sheet2!$A$2:$B$10,2,0) -> 141185-74670 | E40: DISC,FRONT BRAKE | F40: 45966 | G40: 0.97916667 | H40: CA-07 | I40: AC5 | J40: 80 | K40: =VLOOKUP($C40,Sheet2!$A$2:$D$10,4,0) -> 40 | L40: =VLOOKUP($C40,Sheet2!$A$2:$E$10,5,0) -> Trolley | N40: =J40/K40 -> 2 | O40: GJ27TD4419 | P40: 910099020- 13 Qty./ 910101143-67 Qty.
...

Sheet 06-11-2025
A1: Dailly SMG Pick List | J1: 24AACCN5739J1ZA
A2: Supply Month | B2: 45967
A3: INVOICE NO | B3: KANBAN NO | C3: PART NUMBER | D3: Material Code | E3: PART NAME | F3: SUPPLY DATE | G3: SUPPLY TIME | H3: UNLOADING LOC | I3: Line | J3: Qty Req | K3: Packing Standerd | L3: Packed in | M3: TTL Bin | N3: TORLLY | O3: Vehicle No | P3: INV NO
A4: G/I/25-26/01101 | B4: 06Y586605259AC5 | C4: 55101M58U10 | D4: =VLOOKUP($C4,Sheet2!$A$2:$B$10,2,0) -> 141110-14600 | E4: CALIPER ASSY,FRONT BRAKE,R | F4: 45967 | G4: 0.35416667 | H4: CA-07 | I4: AC5 | J4: 18 | K4: =VLOOKUP($C4,Sheet2!$A$2:$D$10,4,0) -> 18 | L4: =VLOOKUP($C4,Sheet2!$A$2:$E$10,5,0) -> Trolley (H) | N4: 1 | O4: GJ23Y8525 | P4: AN0250008334
A5: G/I/25-26/01101 | B5: 06Y586605275AC5 | C5: 55102M58U10 | D5: =VLOOKUP($C5,Sheet2!$A$2:$B$10,2,0) -> 141120-14600 | E5: CALIPER ASSY,FRONT BRAKE,L | F5: 45967 | G5: 0.35416667 | H5: CA-07 | I5: AC5 | J5: 18 | K5: =VLOOKUP($C5,Sheet2!$A$2:$D$10,4,0) -> 18 | L5: =VLOOKUP($C5,Sheet2!$A$2:$E$10,5,0) -> Trolley (H) | O5: GJ23Y8525 | P5: AN0250008334
A6: G/I/25-26/01101 | B6: 06Y586752227AC5 | C6: 55101M58U10 | D6: =VLOOKUP($C6,Sheet2!$A$2:$B$10,2,0) -> 141110-14600 | E6: CALIPER ASSY,FRONT BRAKE,R | F6: 45967 | G6: 0.35416667 | H6: CA-07 | I6: AC5 | J6: 18 | K6: =VLOOKUP($C6,Sheet2!$A$2:$D$10,4,0) -> 18 | L6: =VLOOKUP($C6,Sheet2!$A$2:$E$10,5,0) -> Trolley (H) | N6: 1 | O6: GJ23Y8525 | P6: AN0250008334
A7: G/I/25-26/01101 | B7: 06Y586750950AC5 | C7: 55102M58U10 | D7: =VLOOKUP($C7,Sheet2!$A$2:$B$10,2,0) -> 141120-14600 | E7: CALIPER ASSY,FRONT BRAKE,L | F7: 45967 | G7: 0.35416667 | H7: CA-07 | I7: AC5 | J7: 18 | K7: =VLOOKUP($C7,Sheet2!$A$2:$D$10,4,0) -> 18 | L7: =VLOOKUP($C7,Sheet2!$A$2:$E$10,5,0) -> Trolley (H) | O7: GJ23Y8525 | P7: AN0250008334
A8: G/I/25-26/01101 | B8: 06Y586605305AC5 | C8: 55311M58U00 | D8: =VLOOKUP($C8,Sheet2!$A$2:$B$10,2,0) -> 141185-74670 | E8: DISC,FRONT BRAKE | F8: 45967 | G8: 0.35416667 | H8: CA-07 | I8: AC5 | J8: 40 | K8: =VLOOKUP($C8,Sheet2!$A$2:$D$10,4,0) -> 40 | L8: =VLOOKUP($C8,Sheet2!$A$2:$E$10,5,0) -> Trolley | N8: =J8/K8 -> 1 | O8: GJ23Y8525 | P8: 910102103
A9: G/I/25-26/01101 | B9: 06Y586605321AC5 | C9: 55401M58U00 | D9: =VLOOKUP($C9,Sheet2!$A$2:$B$10,2,0) -> 141140-91211 | E9: CALIPER ASSY,REAR BRAKE,R | F9: 45967 | G9: 0.35416667 | H9: CA-21 | I9: AC5 | J9: 14 | K9: =VLOOKUP($C9,Sheet2!$A$2:$D$10,4,0) -> 2 | L9: =VLOOKUP($C9,Sheet2!$A$2:$E$10,5,0) -> Bin | M9: =J9/K9 -> 7 | O9: GJ23Y8525 | P9: 12508Q100183
A10: G/I/25-26/01101 | B10: 06Y586747703AC5 | C10: 55401M58U00 | D10: =VLOOKUP($C10,Sheet2!$A$2:$B$10,2,0) -> 141140-91211 | E10: CALIPER ASSY,REAR BRAKE,R | F10: 45967 | G10: 0.35416667 | H10: CA-21 | I10: AC5 | J10: 18 | K10: =VLOOKUP($C10,Sheet2!$A$2:$D$10,4,0) -> 2 | L10: =VLOOKUP($C10,Sheet2!$A$2:$E$10,5,0) -> Bin | M10: =J10/K10 -> 9 | O10: GJ23Y8525 | P10: 12508Q100183
A11: G/I/25-26/01101 | B11: 06Y586605364AC5 | C11: 55402M58U00 | D11: =VLOOKUP($C11,Sheet2!$A$2:$B$10,2,0) -> 141150-91211 | E11: CALIPER ASSY,REAR BRAKE,L | F11: 45967 | G11: 0.35416667 | H11: CA-21 | I11: AC5 | J11: 14 | K11: =VLOOKUP($C11,Sheet2!$A$2:$D$10,4,0) -> 2 | L11: =VLOOKUP($C11,Sheet2!$A$2:$E$10,5,0) -> Bin | M11: =J11/K11 -> 7 | O11: GJ23Y8525 | P11: 12508Q100183
A12: G/I/25-26/01101 | B12: 06Y586752901AC5 | C12: 55402M58U00 | D12: =VLOOKUP($C12,Sheet2!$A$2:$B$10,2,0) -> 141150-91211 | E12: CALIPER ASSY,REAR BRAKE,L | F12: 45967 | G12: 0.35416667 | H12: CA-21 | I12: AC5 | J12: 18 | K12: =VLOOKUP($C12,Sheet2!$A$2:$D$10,4,0) -> 2 | L12: =VLOOKUP($C12,Sheet2!$A$2:$E$10,5,0) -> Bin | M12: =J12/K12 -> 9 | O12: GJ23Y8525 | P12: 12508Q100183
A13: G/I/25-26/01101 | B13: 06Y586605402AC5 | C13: 55611M58U00 | D13: =VLOOKUP($C13,Sheet2!$A$2:$B$10,2,0) -> 141186-74360 | E13: DISC,REAR BRAKE | F13: 45967 | G13: 0.35416667 | H13: CA-21 | I13: AC5 | J13: 40 | K13: =VLOOKUP($C13,Sheet2!$A$2:$D$10,4,0) -> 40 | L13: =VLOOKUP($C13,Sheet2!$A$2:$E$10,5,0) -> Trolley | N13: =J13/K13 -> 1 | O13: GJ23Y8525 | P13: 910101143
A14: G/I/25-26/01102 | B14: 06Y586605429AC5 | C14: 56110M58UA1 | D14: =VLOOKUP($C14,Sheet2!$A$2:$B$10,2,0) -> 116040-92240 | E14: ACTUATOR ASSY,NO VARIANT ESP | F14: 45967 | G14: 0.35416667 | H14: CA-01 | I14: AC5 | J14: 12 | K14: =VLOOKUP($C14,Sheet2!$A$2:$D$10,4,0) -> 6 | L14: =VLOOKUP($C14,Sheet2!$A$2:$E$10,5,0) -> Bin | M14: =J14/K14 -> 2 | O14: GJ23Y8525 | P14: NA
A15: G/I/25-26/01102 | B15: 06Y586752324AC5 | C15: 56110M58UA1 | D15: =VLOOKUP($C15,Sheet2!$A$2:$B$10,2,0) -> 116040-92240 | E15: ACTUATOR ASSY,NO VARIANT ESP | F15: 45967 | G15: 0.35416667 | H15: CA-01 | I15: AC5 | J15: 18 | K15: =VLOOKUP($C15,Sheet2!$A$2:$D$10,4,0) -> 6 | L15: =VLOOKUP($C15,Sheet2!$A$2:$E$10,5,0) -> Bin | M15: =J15/K15 -> 3 | O15: GJ23Y8525 | P15: NA
A16: G/I/25-26/01102 | B16: 06Y586605461AC5 | C16: 5A120M58U01 | D16: =VLOOKUP($C16,Sheet2!$A$2:$B$10,2,0) -> 114010-50820 | E16: CYLINDER ASSY,BK MASTER W/ECU | F16: 45967 | G16: 0.35416667 | H16: CA-01 | I16: AC5 | J16: 3 | K16: =VLOOKUP($C16,Sheet2!$A$2:$D$10,4,0) -> 1 | L16: =VLOOKUP($C16,Sheet2!$A$2:$E$10,5,0) -> Bin | M16: =J16/K16 -> 3 | O16: GJ23Y8525 | P16: NA
A17: G/I/25-26/01102 | B17: 06Y586758705AC5 | C17: 5A120M58U01 | D17: =VLOOKUP($C17,Sheet2!$A$2:$B$10,2,0) -> 114010-50820 | E17: CYLINDER ASSY,BK MASTER W/ECU | F17: 45967 | G17: 0.35416667 | H17: CA-01 | I17: AC5 | J17: 10 | K17: =VLOOKUP($C17,Sheet2!$A$2:$D$10,4,0) -> 1 | L17: =VLOOKUP($C17,Sheet2!$A$2:$E$10,5,0) -> Bin | M17: =J17/K17 -> 10 | O17: GJ23Y8525 | P17: NA
A18: G/I/25-26/01102 | B18: 06Y586605500AC5 | C18: 5A120M58U50 | D18: =VLOOKUP($C18,Sheet2!$A$2:$B$10,2,0) -> 114010-50830 | E18: CYLINDER ASSY,BK MASTER W/ECU | F18: 45967 | G18: 0.35416667 | H18: CA-01 | I18: AC5 | J18: 11 | K18: =VLOOKUP($C18,Sheet2!$A$2:$D$10,4,0) -> 1 | L18: =VLOOKUP($C18,Sheet2!$A$2:$E$10,5,0) -> Bin | M18: =J18/K18 -> 11 | O18: GJ23Y8525 | P18: NA
A19: G/I/25-26/01102 | B19: 06Y586749846AC5 | C19: 5A120M58U50 | D19: =VLOOKUP($C19,Sheet2!$A$2:$B$10,2,0) -> 114010-50830 | E19: CYLINDER ASSY,BK MASTER W/ECU | F19: 45967 | G19: 0.35416667 | H19: CA-01 | I19: AC5 | J19: 7 | K19: =VLOOKUP($C19,Sheet2!$A$2:$D$10,4,0) -> 1 | L19: =VLOOKUP($C19,Sheet2!$A$2:$E$10,5,0) -> Bin | M19: =J19/K19 -> 7 | O19: GJ23Y8525 | P19: 12504Q100241
M20: 68 | N20: 4
A21: G/I/25-26/01103 | B21: 06Y586605267AC5 | C21: 55101M58U10 | D21: =VLOOKUP($C21,Sheet2!$A$2:$B$10,2,0) -> 141110-14600 | E21: CALIPER ASSY,FRONT BRAKE,R | F21: 45967 | G21: 0.60416667 | H21: CA-07 | I21: AC5 | J21: 18 | K21: =VLOOKUP($C21,Sheet2!$A$2:$D$10,4,0) -> 18 | L21: =VLOOKUP($C21,Sheet2!$A$2:$E$10,5,0) -> Trolley (H) | N21: 1 | O21: GJ02ZZ7144 | P21: AN0250008334
A22: G/I/25-26/01103 | B22: 06Y586605283AC5 | C22: 55102M58U10 | D22: =VLOOKUP($C22,Sheet2!$A$2:$B$10,2,0) -> 141120-14600 | E22: CALIPER ASSY,FRONT BRAKE,L | F22: 45967 | G22: 0.60416667 | H22: CA-07 | I22: AC5 | J22: 18 | K22: =VLOOKUP($C22,Sheet2!$A$2:$D$10,4,0) -> 18 | L22: =VLOOKUP($C22,Sheet2!$A$2:$E$10,5,0) -> Trolley (H) | O22: GJ02ZZ7144 | P22: AN0250008334
A23: G/I/25-26/01103 | B23: 06Y586605330AC5 | C23: 55401M58U00 | D23: =VLOOKUP($C23,Sheet2!$A$2:$B$10,2,0) -> 141140-91211 | E23: CALIPER ASSY,REAR BRAKE,R | F23: 45967 | G23: 0.60416667 | H23: CA-21 | I23: AC5 | J23: 10 | K23: =VLOOKUP($C23,Sheet2!$A$2:$D$10,4,0) -> 2 | L23: =VLOOKUP($C23,Sheet2!$A$2:$E$10,5,0) -> Bin | M23: =J23/K23 -> 5 | O23: GJ02ZZ7144 | P23: 12508Q100183
A24: G/I/25-26/01103 | B24: 06Y586605348AC5 | C24: 55401M58U00 | D24: =VLOOKUP($C24,Sheet2!$A$2:$B$10,2,0) -> 141140-91211 | E24: CALIPER ASSY,REAR BRAKE,R | F24: 45967 | G24: 0.60416667 | H24: CA-21 | I24: AC5 | J24: 10 | K24: =VLOOKUP($C24,Sheet2!$A$2:$D$10,4,0) -> 2 | L24: =VLOOKUP($C24,Sheet2!$A$2:$E$10,5,0) -> Bin | M24: =J24/K24 -> 5 | O24: GJ02ZZ7144 | P24: 12508Q100183
A25: G/I/25-26/01103 | B25: 06Y586605372AC5 | C25: 55402M58U00 | D25: =VLOOKUP($C25,Sheet2!$A$2:$B$10,2,0) -> 141150-91211 | E25: CALIPER ASSY,REAR BRAKE,L | F25: 45967 | G25: 0.60416667 | H25: CA-21 | I25: AC5 | J25: 10 | K25: =VLOOKUP($C25,Sheet2!$A$2:$D$10,4,0) -> 2 | L25: =VLOOKUP($C25,Sheet2!$A$2:$E$10,5,0) -> Bin | M25: =J25/K25 -> 5 | O25: GJ02ZZ7144 | P25: 12508Q100183
