Workbook

Sheet Sheet1
A1: PART NUMBER | B1: Mat Code | C1: PART NAME | D1: Packing Standard | E1: Packed In
A2: 55101M58U10 | B2: 141110-14600 | C2: CALIPER RR | D2: 18 | E2: Trolley (H)
A3: 55102M58U10 | B3: 141120-14600 | C3: CALIPER LH | D3: 18 | E3: Trolley (H)
A4: 55311M58U00 | B4: 141185-74670 | C4: DISC FR | D4: 40 | E4: Trolley
A5: 55401M58U00 | B5: 141140-91211 | C5: MOC RH | D5: 2 | E5: Bin
A6: 55402M58U00 | B6: 141150-91211 | C6: MOC LH | D6: 2 | E6: Bin
A7: 55611M58U00 | B7: 141186-74360 | C7: DISC RR | D7: 40 | E7: Trolley
A8: 56110M58UA1 | B8: 116040-92240 | C8: ESC | D8: 6 | E8: Bin
A9: 5A120M58U50 | B9: 114010-50830 | C9: AHB LH | D9: 1 | E9: Bin
A10: 5A120M58U01 | B10: 114010-50820 | C10: AHB RH | D10: 1 | E10: Bin

Sheet 01-12-2025
A1: Dailly SMG Pick List | J1: 24AACCN5739J1ZA
A2: Supply Month | B2: 45992 | L2: Vehicle No
A3: INVOICE NO | B3: KANBAN NO | C3: PART NUMBER | D3: Material Code | E3: PART NAME | F3: SUPPLY DATE | G3: SUPPLY TIME | H3: UNLOADING LOC | I3: Line | J3: Qty Req | K3: Packing Standerd | L3: Packed in | M3: TTL Bin | N3: TORLLY | O3: Vehicle No | P3: INV NO
A4: G/I/25-26/01294 | B4: 01Z599626144AC5 | C4: 55101M58U10 | D4: =VLOOKUP($C4,Sheet1!$A$2:$B$10,2,0) -> 141110-14600 | E4: CALIPER ASSY,FRONT BRAKE,R | F4: 45992 | G4: 0.47916667 | H4: CA-07 | I4: AC5 | J4: 18 | K4: =VLOOKUP($C4,Sheet1!$A$2:$D$10,4,0) -> 18 | L4: =VLOOKUP($C4,Sheet1!$A$2:$E$10,5,0) -> Trolley (H) | N4: 1 | O4: GJ02ZZ7144 | P4: Barode sticker
A5: G/I/25-26/01294 | B5: 01Z599626179AC5 | C5: 55102M58U10 | D5: =VLOOKUP($C5,Sheet1!$A$2:$B$10,2,0) -> 141120-14600 | E5: CALIPER ASSY,FRONT BRAKE,L | F5: 45992 | G5: 0.47916667 | H5: CA-07 | I5: AC5 | J5: 18 | K5: =VLOOKUP($C5,Sheet1!$A$2:$D$10,4,0) -> 18 | L5: =VLOOKUP($C5,Sheet1!$A$2:$E$10,5,0) -> Trolley (H) | O5: GJ02ZZ7144 | P5: Barode sticker
A6: G/I/25-26/01294 | B6: 01Z599798425AC5 | C6: 55101M58U10 | D6: =VLOOKUP($C6,Sheet1!$A$2:$B$10,2,0) -> 141110-14600 | E6: CALIPER ASSY,FRONT BRAKE,R | F6: 45992 | G6: 0.47916667 | H6: CA-07 | I6: AC5 | J6: 18 | K6: =VLOOKUP($C6,Sheet1!$A$2:$D$10,4,0) -> 18 | L6: =VLOOKUP($C6,Sheet1!$A$2:$E$10,5,0) -> Trolley (H) | N6: 1 | O6: GJ02ZZ7144 | P6: Barode sticker
A7: G/I/25-26/01294 | B7: 01Z599798050AC5 | C7: 55102M58U10 | D7: =VLOOKUP($C7,Sheet1!$A$2:$B$10,2,0) -> 141120-14600 | E7: CALIPER ASSY,FRONT BRAKE,L | F7: 45992 | G7: 0.47916667 | H7: CA-07 | I7: AC5 | J7: 18 | K7: =VLOOKUP($C7,Sheet1!$A$2:$D$10,4,0) -> 18 | L7: =VLOOKUP($C7,Sheet1!$A$2:$E$10,5,0) -> Trolley (H) | O7: GJ02ZZ7144 | P7: Barode sticker
A8: G/I/25-26/01294 | B8: 01Z599626209AC5 | C8: 55311M58U00 | D8: =VLOOKUP($C8,Sheet1!$A$2:$B$10,2,0) -> 141185-74670 | E8: DISC,FRONT BRAKE | F8: 45992 | G8: 0.47916667 | H8: CA-07 | I8: AC5 | J8: 40 | K8: =VLOOKUP($C8,Sheet1!$A$2:$D$10,4,0) -> 40 | L8: =VLOOKUP($C8,Sheet1!$A$2:$E$10,5,0) -> Trolley | N8: =J8/K8 -> 1 | O8: GJ02ZZ7144 | P8: 910102507
A9: G/I/25-26/01294 | B9: 01Z599804298AC5 | C9: 55311M58U00 | D9: =VLOOKUP($C9,Sheet1!$A$2:$B$10,2,0) -> 141185-74670 | E9: DISC,FRONT BRAKE | F9: 45992 | G9: 0.47916667 | H9: CA-07 | I9: AC5 | J9: 40 | K9: =VLOOKUP($C9,Sheet1!$A$2:$D$10,4,0) -> 40 | L9: =VLOOKUP($C9,Sheet1!$A$2:$E$10,5,0) -> Trolley | N9: =J9/K9 -> 1 | O9: GJ02ZZ7144 | P9: 910102507
A10: G/I/25-26/01294 | B10: 01Z599626241AC5 | C10: 55401M58U00 | D10: =VLOOKUP($C10,Sheet1!$A$2:$B$10,2,0) -> 141140-91211 | E10: CALIPER ASSY,REAR BRAKE,R | F10: 45992 | G10: 0.47916667 | H10: CA-21 | I10: AC5 | J10: 20 | K10: =VLOOKUP($C10,Sheet1!$A$2:$D$10,4,0) -> 2 | L10: =VLOOKUP($C10,Sheet1!$A$2:$E$10,5,0) -> Bin | M10: =J10/K10 -> 10 | O10: GJ02ZZ7144 | P10: 12509Q100239
A11: G/I/25-26/01294 | B11: 01Z599802309AC5 | C11: 55401M58U00 | D11: =VLOOKUP($C11,Sheet1!$A$2:$B$10,2,0) -> 141140-91211 | E11: CALIPER ASSY,REAR BRAKE,R | F11: 45992 | G11: 0.47916667 | H11: CA-21 | I11: AC5 | J11: 26 | K11: =VLOOKUP($C11,Sheet1!$A$2:$D$10,4,0) -> 2 | L11: =VLOOKUP($C11,Sheet1!$A$2:$E$10,5,0) -> Bin | M11: =J11/K11 -> 13 | O11: GJ02ZZ7144 | P11: 12509Q100239
A12: G/I/25-26/01294 | B12: 01Z599626284AC5 | C12: 55402M58U00 | D12: =VLOOKUP($C12,Sheet1!$A$2:$B$10,2,0) -> 141150-91211 | E12: CALIPER ASSY,REAR BRAKE,L | F12: 45992 | G12: 0.47916667 | H12: CA-21 | I12: AC5 | J12: 20 | K12: =VLOOKUP($C12,Sheet1!$A$2:$D$10,4,0) -> 2 | L12: =VLOOKUP($C12,Sheet1!$A$2:$E$10,5,0) -> Bin | M12: =J12/K12 -> 10 | O12: GJ02ZZ7144 | P12: 12509Q100239
A13: G/I/25-26/01294 | B13: 01Z599804573AC5 | C13: 55402M58U00 | D13: =VLOOKUP($C13,Sheet1!$A$2:$B$10,2,0) -> 141150-91211 | E13: CALIPER ASSY,REAR BRAKE,L | F13: 45992 | G13: 0.47916667 | H13: CA-21 | I13: AC5 | J13: 26 | K13: =VLOOKUP($C13,Sheet1!$A$2:$D$10,4,0) -> 2 | L13: =VLOOKUP($C13,Sheet1!$A$2:$E$10,5,0) -> Bin | M13: =J13/K13 -> 13 | O13: GJ02ZZ7144 | P13: 12509Q100239
A14: G/I/25-26/01294 | B14: 01Z599626314AC5 | C14: 55611M58U00 | D14: =VLOOKUP($C14,Sheet1!$A$2:$B$10,2,0) -> 141186-74360 | E14: DISC,REAR BRAKE | F14: 45992 | G14: 0.47916667 | H14: CA-21 | I14: AC5 | J14: 40 | K14: =VLOOKUP($C14,Sheet1!$A$2:$D$10,4,0) -> 40 | L14: =VLOOKUP($C14,Sheet1!$A$2:$E$10,5,0) -> Trolley | N14: =J14/K14 -> 1 | O14: GJ02ZZ7144 | P14: 910101143
A15: G/I/25-26/01294 | B15: 01Z599805189AC5 | C15: 55611M58U00 | D15: =VLOOKUP($C15,Sheet1!$A$2:$B$10,2,0) -> 141186-74360 | E15: DISC,REAR BRAKE | F15: 45992 | G15: 0.47916667 | H15: CA-21 | I15: AC5 | J15: 40 | K15: =VLOOKUP($C15,Sheet1!$A$2:$D$10,4,0) -> 40 | L15: =VLOOKUP($C15,Sheet1!$A$2:$E$10,5,0) -> Trolley | N15: =J15/K15 -> 1 | O15: GJ02ZZ7144 | P15: 910101143
A16: G/I/25-26/01295 | B16: 01Z599626357AC5 | C16: 56110M58UA1 | D16: =VLOOKUP($C16,Sheet1!$A$2:$B$10,2,0) -> 116040-92240 | E16: ACTUATOR ASSY,NO VARIANT ESP | F16: 45992 | G16: 0.47916667 | H16: CA-01 | I16: AC5 | J16: 24 | K16: =VLOOKUP($C16,Sheet1!$A$2:$D$10,4,0) -> 6 | L16: =VLOOKUP($C16,Sheet1!$A$2:$E$10,5,0) -> Bin | M16: =J16/K16 -> 4 | O16: GJ02ZZ7144 | P16: 12505Q100031
A17: G/I/25-26/01295 | B17: 01Z599803712AC5 | C17: 56110M58UA1 | D17: =VLOOKUP($C17,Sheet1!$A$2:$B$10,2,0) -> 116040-92240 | E17: ACTUATOR ASSY,NO VARIANT ESP | F17: 45992 | G17: 0.47916667 | H17: CA-01 | I17: AC5 | J17: 30 | K17: =VLOOKUP($C17,Sheet1!$A$2:$D$10,4,0) -> 6 | L17: =VLOOKUP($C17,Sheet1!$A$2:$E$10,5,0) -> Bin | M17: =J17/K17 -> 5 | O17: GJ02ZZ7144 | P17: 12505Q100031
A18: G/I/25-26/01295 | B18: 01Z599626390AC5 | C18: 5A120M58U01 | D18: =VLOOKUP($C18,Sheet1!$A$2:$B$10,2,0) -> 114010-50820 | E18: CYLINDER ASSY,BK MASTER W/ECU | F18: 45992 | G18: 0.47916667 | H18: CA-01 | I18: AC5 | J18: 5 | K18: =VLOOKUP($C18,Sheet1!$A$2:$D$10,4,0) -> 1 | L18: =VLOOKUP($C18,Sheet1!$A$2:$E$10,5,0) -> Bin | M18: =J18/K18 -> 5 | O18: GJ02ZZ7144 | P18: 12504Q100266
A19: G/I/25-26/01295 | B19: 01Z599796090AC5 | C19: 5A120M58U01 | D19: =VLOOKUP($C19,Sheet1!$A$2:$B$10,2,0) -> 114010-50820 | E19: CYLINDER ASSY,BK MASTER W/ECU | F19: 45992 | G19: 0.47916667 | H19: CA-01 | I19: AC5 | J19: 1 | K19: =VLOOKUP($C19,Sheet1!$A$2:$D$10,4,0) -> 1 | L19: =VLOOKUP($C19,Sheet1!$A$2:$E$10,5,0) -> Bin | M19: =J19/K19 -> 1 | O19: GJ02ZZ7144 | P19: 12504Q100256
A20: G/I/25-26/01295 | B20: 01Z599626438AC5 | C20: 5A120M58U50 | D20: =VLOOKUP($C20,Sheet1!$A$2:$B$10,2,0) -> 114010-50830 | E20: CYLINDER ASSY,BK MASTER W/ECU | F20: 45992 | G20: 0.47916667 | H20: CA-01 | I20: AC5 | J20: 15 | K20: =VLOOKUP($C20,Sheet1!$A$2:$D$10,4,0) -> 1 | L20: =VLOOKUP($C20,Sheet1!$A$2:$E$10,5,0) -> Bin | M20: =J20/K20 -> 15 | O20: GJ02ZZ7144 | P20: 12504Q100256
A21: G/I/25-26/01295 | B21: 01Z599803186AC5 | C21: 5A120M58U50 | D21: =VLOOKUP($C21,Sheet1!$A$2:$B$10,2,0) -> 114010-50830 | E21: CYLINDER ASSY,BK MASTER W/ECU | F21: 45992 | G21: 0.47916667 | H21: CA-01 | I21: AC5 | J21: 25 | K21: =VLOOKUP($C21,Sheet1!$A$2:$D$10,4,0) -> 1 | L21: =VLOOKUP($C21,Sheet1!$A$2:$E$10,5,0) -> Bin | M21: =J21/K21 -> 25 | O21: GJ02ZZ7144 | P21: 12504Q100256
M22: 101 | N22: 6
A23: G/I/25-26/01296 | B23: 01Z599626152AC5 | C23: 55101M58U10 | D23: =VLOOKUP($C23,Sheet1!$A$2:$B$10,2,0) -> 141110-14600 | E23: CALIPER ASSY,FRONT BRAKE,R | F23: 45992 | G23: 0.52083333 | H23: CA-07 | I23: AC5 | J23: 18 | K23: =VLOOKUP($C23,Sheet1!$A$2:$D$10,4,0) -> 18 | L23: =VLOOKUP($C23,Sheet1!$A$2:$E$10,5,0) -> Trolley (H) | N23: 1 | O23: GJ23Y8525 | P23: Barode sticker
A24: G/I/25-26/01296 | B24: 01Z599626187AC5 | C24: 55102M58U10 | D24: =VLOOKUP($C24,Sheet1!$A$2:$B$10,2,0) -> 141120-14600 | E24: CALIPER ASSY,FRONT BRAKE,L | F24: 45992 | G24: 0.52083333 | H24: CA-07 | I24: AC5 | J24: 18 | K24: =VLOOKUP($C24,Sheet1!$A$2:$D$10,4,0) -> 18 | L24: =VLOOKUP($C24,Sheet1!$A$2:$E$10,5,0) -> Trolley (H) | O24: GJ23Y8525 | P24: Barode sticker
A25: G/I/25-26/01296 | B25: 01Z599626217AC5 | C25: 55311M58U00 | D25: =VLOOKUP($C25,Sheet1!$A$2:$B$10,2,0) -> 141185-74670 | E25: DISC,FRONT BRAKE | F25: 45992 | G25: 0.52083333 | H25: CA-07 | I25: AC5 | J25: 40 | K25: =VLOOKUP($C25,Sheet1!$A$2:$D$10,4,0) -> 40 | L25: =VLOOKUP($C25,Sheet1!$A$2:$E$10,5,0) -> Trolley | N25: =J25/K25 -> 1 | O25: GJ23Y8525 | P25: 910102507
A26: G/I/25-26/01296 | B26: 01Z599626250AC5 | C26: 55401M58U00 | D26: =VLOOKUP($C26,Sheet1!$A$2:$B$10,2,0) -> 141140-91211 | E26: CALIPER ASSY,REAR BRAKE,R | F26: 45992 | G26: 0.52083333 | H26: CA-21 | I26: AC5 | J26: 20 | K26: =VLOOKUP($C26,Sheet1!$A$2:$D$10,4,0) -> 2 | L26: =VLOOKUP($C26,Sheet1!$A$2:$E$10,5,0) -> Bin | M26: =J26/K26 -> 10 | O26: GJ23Y8525 | P26: 12509Q100239
A27: G/I/25-26/01296 | B27: 01Z599626292AC5 | C27: 55402M58U00 | D27: =VLOOKUP($C27,Sheet1!$A$2:$B$10,2,0) -> 141150-91211 | E27: CALIPER ASSY,REAR BRAKE,L | F27: 45992 | G27: 0.52083333 | H27: CA-21 | I27: AC5 | J27: 20 | K27: =VLOOKUP($C27,Sheet1!$A$2:$D$10,4,0) -> 2 | L27: =VLOOKUP($C27,Sheet1!$A$2:$E$10,5,0) -> Bin | M27: =J27/K27 -> 10 | O27: GJ23Y8525 | P27: 12509Q100239
A28: G/I/25-26/01296 | B28: 01Z599626322AC5 | C28: 55611M58U00 | D28: =VLOOKUP($C28,Sheet1!$A$2:$B$10,2,0) -> 141186-74360 | E28: DISC,REAR BRAKE | F28: 45992 | G28: 0.52083333 | H28: CA-21 | I28: AC5 | J28: 40 | K28: =VLOOKUP($C28,Sheet1!$A$2:$D$10,4,0) -> 40 | L28: =VLOOKUP($C28,Sheet1!$A$2:$E$10,5,0) -> Trolley | N28: =J28/K28 -> 1 | O28: GJ23Y8525 | P28: 910101143
A29: G/I/25-26/01297 | B29: 01Z599626365AC5 | C29: 56110M58UA1 | D29: =VLOOKUP($C29,Sheet1!$A$2:$B$10,2,0) -> 116040-92240 | E29: ACTUATOR ASSY,NO VARIANT ESP | F29: 45992 | G29: 0.52083333 | H29: CA-01 | I29: AC5 | J29: 18 | K29: =VLOOKUP($C29,Sheet1!$A$2:$D$10,4,0) -> 6 | L29: =VLOOKUP($C29,Sheet1!$A$2:$E$10,5,0) -> Bin | M29: =J29/K29 -> 3 | O29: GJ23Y8525 | P29: 12505Q100031
A30: G/I/25-26/01297 | B30: 01Z599626403AC5 | C30: 5A120M58U01 | D30: =VLOOKUP($C30,Sheet1!$A$2:$B$10,2,0) -> 114010-50820 | E30: CYLINDER ASSY,BK MASTER W/ECU | F30: 45992 | G30: 0.52083333 | H30: CA-01 | I30: AC5 | J30: 12 | K30: =VLOOKUP($C30,Sheet1!$A$2:$D$10,4,0) -> 1 | L30: =VLOOKUP($C30,Sheet1!$A$2:$E$10,5,0) -> Bin | M30: =J30/K30 -> 12 | O30: GJ23Y8525 | P30: 12504Q100266
A31: G/I/25-26/01297 | B31: 01Z599626446AC5 | C31: 5A120M58U50 | D31: =VLOOKUP($C31,Sheet1!$A$2:$B$10,2,0) -> 114010-50830 | E31: CYLINDER ASSY,BK MASTER W/ECU | F31: 45992 | G31: 0.52083333 | H31: CA-01 | I31: AC5 | J31: 8 | K31: =VLOOKUP($C31,Sheet1!$A$2:$D$10,4,0) -> 1 | L31: =VLOOKUP($C31,Sheet1!$A$2:$E$10,5,0) -> Bin | M31: =J31/K31 -> 8 | O31: GJ23Y8525 | P31: 12504Q100256
M32: 43 | N32: 3
A33: G/I/25-26/01298 | B33: 01Z599626160AC5 | C33: 55101M58U10 | D33: =VLOOKUP($C33,Sheet1!$A$2:$B$10,2,0) -> 141110-14600 | E33: CALIPER ASSY,FRONT BRAKE,R | F33: 45992 | G33: 0.60416667 | H33: CA-07 | I33: AC5 | J33: 18 | K33: =VLOOKUP($C33,Sheet1!$A$2:$D$10,4,0) -> 18 | L33: =VLOOKUP($C33,Sheet1!$A$2:$E$10,5,0) -> Trolley (H) | N33: 1 | O33: HR47G9416 | P33: Barode sticker
A34: G/I/25-26/01298 | B34: 01Z599626195AC5 | C34: 55102M58U10 | D34: =VLOOKUP($C34,Sheet1!$A$2:$B$10,2,0) -> 141120-14600 | E34: CALIPER ASSY,FRONT BRAKE,L | F34: 45992 | G34: 0.60416667 | H34: CA-07 | I34: AC5 | J34: 18 | K34: =VLOOKUP($C34,Sheet1!$A$2:$D$10,4,0) -> 18 | L34: =VLOOKUP($C34,Sheet1!$A$2:$E$10,5,0) -> Trolley (H) | O34: HR47G9416 | P34: Barode sticker
A35: G/I/25-26/01298 | B35: 01Z599626225AC5 | C35: 55311M58U00 | D35: =VLOOKUP($C35,Sheet1!$A$2:$B$10,2,0) -> 141185-74670 | E35: DISC,FRONT BRAKE | F35: 45992 | G35: 0.60416667 | H35: CA-07 | I35: AC5 | J35: 40 | K35: =VLOOKUP($C35,Sheet1!$A$2:$D$10,4,0) -> 40 | L35: =VLOOKUP($C35,Sheet1!$A$2:$E$10,5,0) -> Trolley | N35: =J35/K35 -> 1 | O35: HR47G9416 | P35: 910102649
A36: G/I/25-26/01298 | B36: 01Z599626268AC5 | C36: 55401M58U00 | D36: =VLOOKUP($C36,Sheet1!$A$2:$B$10,2,0) -> 141140-91211 | E36: CALIPER ASSY,REAR BRAKE,R | F36: 45992 | G36: 0.60416667 | H36: CA-21 | I36: AC5 | J36: 12 | K36: =VLOOKUP($C36,Sheet1!$A$2:$D$10,4,0) -> 2 | L36: =VLOOKUP($C36,Sheet1!$A$2:$E$10,5,0) -> Bin | M36: =J36/K36 -> 6 | O36: HR47G9416 | P36: 12509Q100239
A37: G/I/25-26/01298 | B37: 01Z599626306AC5 | C37: 55402M58U00 | D37: =VLOOKUP($C37,Sheet1!$A$2:$B$10,2,0) -> 141150-91211 | E37: CALIPER ASSY,REAR BRAKE,L | F37: 45992 | G37: 0.60416667 | H37: CA-21 | I37: AC5 | J37: 12 | K37: =VLOOKUP($C37,Sheet1!$A$2:$D$10,4,0) -> 2 | L37: =VLOOKUP($C37,Sheet1!$A$2:$E$10,5,0) -> Bin | M37: =J37/K37 -> 6 | O37: HR47G9416 | P37: 12509Q100239
A38: G/I/25-26/01298 | B38: 01Z599626330AC5 | C38: 55611M58U00 | D38: =VLOOKUP($C38,Sheet1!$A$2:$B$10,2,0) -> 141186-74360 | E38: DISC,REAR BRAKE | F38: 45992 | G38: 0.60416667 | H38: CA-21 | I38: AC5 | J38: 40 | K38: =VLOOKUP($C38,Sheet1!$A$2:$D$10,4,0) -> 40 | L38: =VLOOKUP($C38,Sheet1!$A$2:$E$10,5,0) -> Trolley | N38: =J38/K38 -> 1 | O38: HR47G9416 | P38: 910101143
A39: G/I/25-26/01299 | B39: 01Z599626373AC5 | C39: 56110M58UA1 | D39: =VLOOKUP($C39,Sheet1!$A$2:$B$10,2,0) -> 116040-92240 | E39: ACTUATOR ASSY,NO VARIANT ESP | F39: 45992 | G39: 0.60416667 | H39: CA-01 | I39: AC5 | J39: 12 | K39: =VLOOKUP($C39,Sheet1!$A$2:$D$10,4,0) -> 6 | L39: =VLOOKUP($C39,Sheet1!$A$2:$E$10,5,0) -> Bin | M39: =J39/K39 -> 2 | O39: HR47G9416 | P39: 12505Q100031
A40: G/I/25-26/01299 | B40: 01Z599626411AC5 | C40: 5A120M58U01 | D40: =VLOOKUP($C40,Sheet1!$A$2:$B$10,2,0) -> 114010-50820 | E40: CYLINDER ASSY,BK MASTER W/ECU | F40: 45992 | G40: 0.60416667 | H40: CA-01 | I40: AC5 | J40: 7 | K40: =VLOOKUP($C40,Sheet1!$A$2:$D$10,4,0) -> 1 | L40: =VLOOKUP($C40,Sheet1!$A$2:$E$10,5,0) -> Bin | M40: =J40/K40 -> 7 | O40: HR47G9416 | P40: 12504Q100266
...

Sheet 02-12-2025
A1: Dailly SMG Pick List | J1: 24AACCN5739J1ZA
A2: Supply Month | B2: 45993 | L2: Vehicle No
A3: INVOICE NO | B3: KANBAN NO | C3: PART NUMBER | D3: Material Code | E3: PART NAME | F3: SUPPLY DATE | G3: SUPPLY TIME | H3: UNLOADING LOC | I3: Line | J3: Qty Req | K3: Packing Standerd | L3: Packed in | M3: TTL Bin | N3: TORLLY | O3: Vehicle No | P3: INV NO
A4: G/I/25-26/01302 | B4: 02Z500460281AC5 | C4: 55101M58U10 | D4: =VLOOKUP($C4,Sheet1!$A$2:$B$10,2,0) -> 141110-14600 | E4: CALIPER ASSY,FRONT BRAKE,R | F4: 45993 | G4: 0.35416667 | H4: CA-07 | I4: AC5 | J4: 36 | K4: =VLOOKUP($C4,Sheet1!$A$2:$D$10,4,0) -> 18 | L4: =VLOOKUP($C4,Sheet1!$A$2:$E$10,5,0) -> Trolley (H) | N4: 2 | O4: GJ01KT7585 | P4: Barode sticker
A5: G/I/25-26/01302 | B5: 02Z500461059AC5 | C5: 55102M58U10 | D5: =VLOOKUP($C5,Sheet1!$A$2:$B$10,2,0) -> 141120-14600 | E5: CALIPER ASSY,FRONT BRAKE,L | F5: 45993 | G5: 0.35416667 | H5: CA-07 | I5: AC5 | J5: 36 | K5: =VLOOKUP($C5,Sheet1!$A$2:$D$10,4,0) -> 18 | L5: =VLOOKUP($C5,Sheet1!$A$2:$E$10,5,0) -> Trolley (H) | O5: GJ01KT7585 | P5: Barode sticker
A6: G/I/25-26/01302 | B6: 02Z500327590AC5 | C6: 55311M58U00 | D6: =VLOOKUP($C6,Sheet1!$A$2:$B$10,2,0) -> 141185-74670 | E6: DISC,FRONT BRAKE | F6: 45993 | G6: 0.35416667 | H6: CA-07 | I6: AC5 | J6: 40 | K6: =VLOOKUP($C6,Sheet1!$A$2:$D$10,4,0) -> 40 | L6: =VLOOKUP($C6,Sheet1!$A$2:$E$10,5,0) -> Trolley | N6: =J6/K6 -> 1 | O6: GJ01KT7585 | P6: 910102649
A7: G/I/25-26/01302 | B7: 02Z500457973AC5 | C7: 55311M58U00 | D7: =VLOOKUP($C7,Sheet1!$A$2:$B$10,2,0) -> 141185-74670 | E7: DISC,FRONT BRAKE | F7: 45993 | G7: 0.35416667 | H7: CA-07 | I7: AC5 | J7: 40 | K7: =VLOOKUP($C7,Sheet1!$A$2:$D$10,4,0) -> 40 | L7: =VLOOKUP($C7,Sheet1!$A$2:$E$10,5,0) -> Trolley | N7: =J7/K7 -> 1 | O7: GJ01KT7585 | P7: 910102394
A8: G/I/25-26/01302 | B8: 02Z500327620AC5 | C8: 55401M58U00 | D8: =VLOOKUP($C8,Sheet1!$A$2:$B$10,2,0) -> 141140-91211 | E8: CALIPER ASSY,REAR BRAKE,R | F8: 45993 | G8: 0.35416667 | H8: CA-21 | I8: AC5 | J8: 20 | K8: =VLOOKUP($C8,Sheet1!$A$2:$D$10,4,0) -> 2 | L8: =VLOOKUP($C8,Sheet1!$A$2:$E$10,5,0) -> Bin | M8: =J8/K8 -> 10 | O8: GJ01KT7585 | P8: 12509Q100239
A9: G/I/25-26/01302 | B9: 02Z500455156AC5 | C9: 55401M58U00 | D9: =VLOOKUP($C9,Sheet1!$A$2:$B$10,2,0) -> 141140-91211 | E9: CALIPER ASSY,REAR BRAKE,R | F9: 45993 | G9: 0.35416667 | H9: CA-21 | I9: AC5 | J9: 22 | K9: =VLOOKUP($C9,Sheet1!$A$2:$D$10,4,0) -> 2 | L9: =VLOOKUP($C9,Sheet1!$A$2:$E$10,5,0) -> Bin | M9: =J9/K9 -> 11 | O9: GJ01KT7585 | P9: 12509Q100239
A10: G/I/25-26/01302 | B10: 02Z500327662AC5 | C10: 55402M58U00 | D10: =VLOOKUP($C10,Sheet1!$A$2:$B$10,2,0) -> 141150-91211 | E10: CALIPER ASSY,REAR BRAKE,L | F10: 45993 | G10: 0.35416667 | H10: CA-21 | I10: AC5 | J10: 20 | K10: =VLOOKUP($C10,Sheet1!$A$2:$D$10,4,0) -> 2 | L10: =VLOOKUP($C10,Sheet1!$A$2:$E$10,5,0) -> Bin | M10: =J10/K10 -> 10 | O10: GJ01KT7585 | P10: 12509Q100239
A11: G/I/25-26/01302 | B11: 02Z500465461AC5 | C11: 55402M58U00 | D11: =VLOOKUP($C11,Sheet1!$A$2:$B$10,2,0) -> 141150-91211 | E11: CALIPER ASSY,REAR BRAKE,L | F11: 45993 | G11: 0.35416667 | H11: CA-21 | I11: AC5 | J11: 22 | K11: =VLOOKUP($C11,Sheet1!$A$2:$D$10,4,0) -> 2 | L11: =VLOOKUP($C11,Sheet1!$A$2:$E$10,5,0) -> Bin | M11: =J11/K11 -> 11 | O11: GJ01KT7585 | P11: 12509Q100239
A12: G/I/25-26/01303 | B12: 02Z500327530AC5 | C12: 55101M58U10 | D12: =VLOOKUP($C12,Sheet1!$A$2:$B$10,2,0) -> 141110-14600 | E12: CALIPER ASSY,FRONT BRAKE,R | F12: 45993 | G12: 0.35416667 | H12: CA-07 | I12: AC5 | J12: 18 | K12: =VLOOKUP($C12,Sheet1!$A$2:$D$10,4,0) -> 18 | L12: =VLOOKUP($C12,Sheet1!$A$2:$E$10,5,0) -> Trolley (H) | N12: 1 | O12: GJ01KT7585 | P12: Barode sticker
A13: G/I/25-26/01303 | B13: 02Z500327565AC5 | C13: 55102M58U10 | D13: =VLOOKUP($C13,Sheet1!$A$2:$B$10,2,0) -> 141120-14600 | E13: CALIPER ASSY,FRONT BRAKE,L | F13: 45993 | G13: 0.35416667 | H13: CA-07 | I13: AC5 | J13: 18 | K13: =VLOOKUP($C13,Sheet1!$A$2:$D$10,4,0) -> 18 | L13: =VLOOKUP($C13,Sheet1!$A$2:$E$10,5,0) -> Trolley (H) | O13: GJ01KT7585 | P13: Barode sticker
A14: G/I/25-26/01303 | B14: 02Z500327697AC5 | C14: 55611M58U00 | D14: =VLOOKUP($C14,Sheet1!$A$2:$B$10,2,0) -> 141186-74360 | E14: DISC,REAR BRAKE | F14: 45993 | G14: 0.35416667 | H14: CA-21 | I14: AC5 | J14: 40 | K14: =VLOOKUP($C14,Sheet1!$A$2:$D$10,4,0) -> 40 | L14: =VLOOKUP($C14,Sheet1!$A$2:$E$10,5,0) -> Trolley | N14: =J14/K14 -> 1 | O14: GJ01KT7585 | P14: 910101985-36PCS / 910101603-04 PCS
A15: G/I/25-26/01303 | B15: 02Z500455113AC5 | C15: 55611M58U00 | D15: =VLOOKUP($C15,Sheet1!$A$2:$B$10,2,0) -> 141186-74360 | E15: DISC,REAR BRAKE | F15: 45993 | G15: 0.35416667 | H15: CA-21 | I15: AC5 | J15: 80 | K15: =VLOOKUP($C15,Sheet1!$A$2:$D$10,4,0) -> 40 | L15: =VLOOKUP($C15,Sheet1!$A$2:$E$10,5,0) -> Trolley | N15: =J15/K15 -> 2 | O15: GJ01KT7585 | P15: 910101603-40 PCS / 910101143-40 PCS
A16: G/I/25-26/01304 | B16: 02Z500327727AC5 | C16: 56110M58UA1 | D16: =VLOOKUP($C16,Sheet1!$A$2:$B$10,2,0) -> 116040-92240 | E16: ACTUATOR ASSY,NO VARIANT ESP | F16: 45993 | G16: 0.35416667 | H16: CA-01 | I16: AC5 | J16: 18 | K16: =VLOOKUP($C16,Sheet1!$A$2:$D$10,4,0) -> 6 | L16: =VLOOKUP($C16,Sheet1!$A$2:$E$10,5,0) -> Bin | M16: =J16/K16 -> 3 | O16: GJ01KT7585 | P16: 12505Q100031
A17: G/I/25-26/01304 | B17: 02Z500460508AC5 | C17: 56110M58UA1 | D17: =VLOOKUP($C17,Sheet1!$A$2:$B$10,2,0) -> 116040-92240 | E17: ACTUATOR ASSY,NO VARIANT ESP | F17: 45993 | G17: 0.35416667 | H17: CA-01 | I17: AC5 | J17: 24 | K17: =VLOOKUP($C17,Sheet1!$A$2:$D$10,4,0) -> 6 | L17: =VLOOKUP($C17,Sheet1!$A$2:$E$10,5,0) -> Bin | M17: =J17/K17 -> 4 | O17: GJ01KT7585 | P17: 12505Q100031
A18: G/I/25-26/01304 | B18: 02Z500327751AC5 | C18: 5A120M58U01 | D18: =VLOOKUP($C18,Sheet1!$A$2:$B$10,2,0) -> 114010-50820 | E18: CYLINDER ASSY,BK MASTER W/ECU | F18: 45993 | G18: 0.35416667 | H18: CA-01 | I18: AC5 | J18: 5 | K18: =VLOOKUP($C18,Sheet1!$A$2:$D$10,4,0) -> 1 | L18: =VLOOKUP($C18,Sheet1!$A$2:$E$10,5,0) -> Bin | M18: =J18/K18 -> 5 | O18: GJ01KT7585 | P18: 12504Q100266
A19: G/I/25-26/01304 | B19: 02Z500457523AC5 | C19: 5A120M58U01 | D19: =VLOOKUP($C19,Sheet1!$A$2:$B$10,2,0) -> 114010-50820 | E19: CYLINDER ASSY,BK MASTER W/ECU | F19: 45993 | G19: 0.35416667 | H19: CA-01 | I19: AC5 | J19: 7 | K19: =VLOOKUP($C19,Sheet1!$A$2:$D$10,4,0) -> 1 | L19: =VLOOKUP($C19,Sheet1!$A$2:$E$10,5,0) -> Bin | M19: =J19/K19 -> 7 | O19: GJ01KT7585 | P19: 12504Q100266
A20: G/I/25-26/01304 | B20: 02Z500327794AC5 | C20: 5A120M58U50 | D20: =VLOOKUP($C20,Sheet1!$A$2:$B$10,2,0) -> 114010-50830 | E20: CYLINDER ASSY,BK MASTER W/ECU | F20: 45993 | G20: 0.35416667 | H20: CA-01 | I20: AC5 | J20: 15 | K20: =VLOOKUP($C20,Sheet1!$A$2:$D$10,4,0) -> 1 | L20: =VLOOKUP($C20,Sheet1!$A$2:$E$10,5,0) -> Bin | M20: =J20/K20 -> 15 | O20: GJ01KT7585 | P20: 12504Q100256
A21: G/I/25-26/01304 | B21: 02Z500455660AC5 | C21: 5A120M58U50 | D21: =VLOOKUP($C21,Sheet1!$A$2:$B$10,2,0) -> 114010-50830 | E21: CYLINDER ASSY,BK MASTER W/ECU | F21: 45993 | G21: 0.35416667 | H21: CA-01 | I21: AC5 | J21: 16 | K21: =VLOOKUP($C21,Sheet1!$A$2:$D$10,4,0) -> 1 | L21: =VLOOKUP($C21,Sheet1!$A$2:$E$10,5,0) -> Bin | M21: =J21/K21 -> 16 | O21: GJ01KT7585 | P21: 12504Q100256
M22: 92 | N22: 8
A23: G/I/25-26/01305 | B23: 02Z500327549AC5 | C23: 55101M58U10 | D23: =VLOOKUP($C23,Sheet1!$A$2:$B$10,2,0) -> 141110-14600 | E23: CALIPER ASSY,FRONT BRAKE,R | F23: 45993 | G23: 0.5625 | H23: CA-07 | I23: AC5 | J23: 18 | K23: =VLOOKUP($C23,Sheet1!$A$2:$D$10,4,0) -> 18 | L23: =VLOOKUP($C23,Sheet1!$A$2:$E$10,5,0) -> Trolley (H) | N23: 1 | O23: GJ02ZZ7144 | P23: Barode sticker
A24: G/I/25-26/01305 | B24: 02Z500327573AC5 | C24: 55102M58U10 | D24: =VLOOKUP($C24,Sheet1!$A$2:$B$10,2,0) -> 141120-14600 | E24: CALIPER ASSY,FRONT BRAKE,L | F24: 45993 | G24: 0.5625 | H24: CA-07 | I24: AC5 | J24: 18 | K24: =VLOOKUP($C24,Sheet1!$A$2:$D$10,4,0) -> 18 | L24: =VLOOKUP($C24,Sheet1!$A$2:$E$10,5,0) -> Trolley (H) | O24: GJ02ZZ7144 | P24: Barode sticker
A25: G/I/25-26/01305 | B25: 02Z500327603AC5 | C25: 55311M58U00 | D25: =VLOOKUP($C25,Sheet1!$A$2:$B$10,2,0) -> 141185-74670 | E25: DISC,FRONT BRAKE | F25: 45993 | G25: 0.5625 | H25: CA-07 | I25: AC5 | J25: 40 | K25: =VLOOKUP($C25,Sheet1!$A$2:$D$10,4,0) -> 40 | L25: =VLOOKUP($C25,Sheet1!$A$2:$E$10,5,0) -> Trolley | N25: =J25/K25 -> 1 | O25: GJ02ZZ7144 | P25: 910102507
A26: G/I/25-26/01305 | B26: 02Z500327638AC5 | C26: 55401M58U00 | D26: =VLOOKUP($C26,Sheet1!$A$2:$B$10,2,0) -> 141140-91211 | E26: CALIPER ASSY,REAR BRAKE,R | F26: 45993 | G26: 0.5625 | H26: CA-21 | I26: AC5 | J26: 20 | K26: =VLOOKUP($C26,Sheet1!$A$2:$D$10,4,0) -> 2 | L26: =VLOOKUP($C26,Sheet1!$A$2:$E$10,5,0) -> Bin | M26: =J26/K26 -> 10 | O26: GJ02ZZ7144 | P26: 12509Q100239
A27: G/I/25-26/01305 | B27: 02Z500327670AC5 | C27: 55402M58U00 | D27: =VLOOKUP($C27,Sheet1!$A$2:$B$10,2,0) -> 141150-91211 | E27: CALIPER ASSY,REAR BRAKE,L | F27: 45993 | G27: 0.5625 | H27: CA-21 | I27: AC5 | J27: 20 | K27: =VLOOKUP($C27,Sheet1!$A$2:$D$10,4,0) -> 2 | L27: =VLOOKUP($C27,Sheet1!$A$2:$E$10,5,0) -> Bin | M27: =J27/K27 -> 10 | O27: GJ02ZZ7144 | P27: 12509Q100239
A28: G/I/25-26/01305 | B28: 02Z500327700AC5 | C28: 55611M58U00 | D28: =VLOOKUP($C28,Sheet1!$A$2:$B$10,2,0) -> 141186-74360 | E28: DISC,REAR BRAKE | F28: 45993 | G28: 0.5625 | H28: CA-21 | I28: AC5 | J28: 40 | K28: =VLOOKUP($C28,Sheet1!$A$2:$D$10,4,0) -> 40 | L28: =VLOOKUP($C28,Sheet1!$A$2:$E$10,5,0) -> Trolley | N28: =J28/K28 -> 1 | O28: GJ02ZZ7144 | P28: 910101985
A29: G/I/25-26/01306 | B29: 02Z500327735AC5 | C29: 56110M58UA1 | D29: =VLOOKUP($C29,Sheet1!$A$2:$B$10,2,0) -> 116040-92240 | E29: ACTUATOR ASSY,NO VARIANT ESP | F29: 45993 | G29: 0.5625 | H29: CA-01 | I29: AC5 | J29: 24 | K29: =VLOOKUP($C29,Sheet1!$A$2:$D$10,4,0) -> 6 | L29: =VLOOKUP($C29,Sheet1!$A$2:$E$10,5,0) -> Bin | M29: =J29/K29 -> 4 | O29: GJ02ZZ7144 | P29: 12505Q100031
A30: G/I/25-26/01306 | B30: 02Z500327760AC5 | C30: 5A120M58U01 | D30: =VLOOKUP($C30,Sheet1!$A$2:$B$10,2,0) -> 114010-50820 | E30: CYLINDER ASSY,BK MASTER W/ECU | F30: 45993 | G30: 0.5625 | H30: CA-01 | I30: AC5 | J30: 12 | K30: =VLOOKUP($C30,Sheet1!$A$2:$D$10,4,0) -> 1 | L30: =VLOOKUP($C30,Sheet1!$A$2:$E$10,5,0) -> Bin | M30: =J30/K30 -> 12 | O30: GJ02ZZ7144 | P30: 12504Q100266
A31: G/I/25-26/01306 | B31: 02Z500327808AC5 | C31: 5A120M58U50 | D31: =VLOOKUP($C31,Sheet1!$A$2:$B$10,2,0) -> 114010-50830 | E31: CYLINDER ASSY,BK MASTER W/ECU | F31: 45993 | G31: 0.5625 | H31: CA-01 | I31: AC5 | J31: 3 | K31: =VLOOKUP($C31,Sheet1!$A$2:$D$10,4,0) -> 1 | L31: =VLOOKUP($C31,Sheet1!$A$2:$E$10,5,0) -> Bin | M31: =J31/K31 -> 3 | O31: GJ02ZZ7144 | P31: 12504Q100256
A32: G/I/25-26/01307 | B32: 02Z500327646AC5 | C32: 55401M58U00 | D32: =VLOOKUP($C32,Sheet1!$A$2:$B$10,2,0) -> 141140-91211 | E32: CALIPER ASSY,REAR BRAKE,R | F32: 45993 | G32: 0.60416667 | H32: CA-21 | I32: AC5 | J32: 4 | K32: =VLOOKUP($C32,Sheet1!$A$2:$D$10,4,0) -> 2 | L32: =VLOOKUP($C32,Sheet1!$A$2:$E$10,5,0) -> Bin | M32: =J32/K32 -> 2 | O32: GJ02ZZ7144 | P32: 12509Q100239
A33: G/I/25-26/01307 | B33: 02Z500327689AC5 | C33: 55402M58U00 | D33: =VLOOKUP($C33,Sheet1!$A$2:$B$10,2,0) -> 141150-91211 | E33: CALIPER ASSY,REAR BRAKE,L | F33: 45993 | G33: 0.60416667 | H33: CA-21 | I33: AC5 | J33: 4 | K33: =VLOOKUP($C33,Sheet1!$A$2:$D$10,4,0) -> 2 | L33: =VLOOKUP($C33,Sheet1!$A$2:$E$10,5,0) -> Bin | M33: =J33/K33 -> 2 | O33: GJ02ZZ7144 | P33: 12509Q100239
A34: G/I/25-26/01308 | B34: 02Z500327778AC5 | C34: 5A120M58U01 | D34: =VLOOKUP($C34,Sheet1!$A$2:$B$10,2,0) -> 114010-50820 | E34: CYLINDER ASSY,BK MASTER W/ECU | F34: 45993 | G34: 0.60416667 | H34: CA-01 | I34: AC5 | J34: 2 | K34: =VLOOKUP($C34,Sheet1!$A$2:$D$10,4,0) -> 1 | L34: =VLOOKUP($C34,Sheet1!$A$2:$E$10,5,0) -> Bin | M34: =J34/K34 -> 2 | O34: GJ02ZZ7144 | P34: 12504Q100266
M35: 45 | N35: 3
A36: G/I/25-26/01309 | B36: 02Z500327522AC5 | C36: 55101M58U10 | D36: =VLOOKUP($C36,Sheet1!$A$2:$B$10,2,0) -> 141110-14600 | E36: CALIPER ASSY,FRONT BRAKE,R | F36: 45993 | G36: 0.64583333 | H36: CA-07 | I36: AC5 | J36: 18 | K36: =VLOOKUP($C36,Sheet1!$A$2:$D$10,4,0) -> 18 | L36: =VLOOKUP($C36,Sheet1!$A$2:$E$10,5,0) -> Trolley (H) | N36: 1 | O36: HR47E8635 | P36: Barode sticker
A37: G/I/25-26/01309 | B37: 02Z500327557AC5 | C37: 55102M58U10 | D37: =VLOOKUP($C37,Sheet1!$A$2:$B$10,2,0) -> 141120-14600 | E37: CALIPER ASSY,FRONT BRAKE,L | F37: 45993 | G37: 0.64583333 | H37: CA-07 | I37: AC5 | J37: 18 | K37: =VLOOKUP($C37,Sheet1!$A$2:$D$10,4,0) -> 18 | L37: =VLOOKUP($C37,Sheet1!$A$2:$E$10,5,0) -> Trolley (H) | O37: HR47E8635 | P37: Barode sticker
A38: G/I/25-26/01309 | B38: 02Z500327581AC5 | C38: 55311M58U00 | D38: =VLOOKUP($C38,Sheet1!$A$2:$B$10,2,0) -> 141185-74670 | E38: DISC,FRONT BRAKE | F38: 45993 | G38: 0.64583333 | H38: CA-07 | I38: AC5 | J38: 40 | K38: =VLOOKUP($C38,Sheet1!$A$2:$D$10,4,0) -> 40 | L38: =VLOOKUP($C38,Sheet1!$A$2:$E$10,5,0) -> Trolley | N38: =J38/K38 -> 1 | O38: HR47E8635 | P38: 910102649
A39: G/I/25-26/01309 | B39: 02Z500327611AC5 | C39: 55401M58U00 | D39: =VLOOKUP($C39,Sheet1!$A$2:$B$10,2,0) -> 141140-91211 | E39: CALIPER ASSY,REAR BRAKE,R | F39: 45993 | G39: 0.64583333 | H39: CA-21 | I39: AC5 | J39: 8 | K39: =VLOOKUP($C39,Sheet1!$A$2:$D$10,4,0) -> 2 | L39: =VLOOKUP($C39,Sheet1!$A$2:$E$10,5,0) -> Bin | M39: =J39/K39 -> 4 | O39: HR47E8635 | P39: 12509Q100239
A40: G/I/25-26/01309 | B40: 02Z500327654AC5 | C40: 55402M58U00 | D40: =VLOOKUP($C40,Sheet1!$A$2:$B$10,2,0) -> 141150-91211 | E40: CALIPER ASSY,REAR BRAKE,L | F40: 45993 | G40: 0.64583333 | H40: CA-21 | I40: AC5 | J40: 8 | K40: =VLOOKUP($C40,Sheet1!$A$2:$D$10,4,0) -> 2 | L40: =VLOOKUP($C40,Sheet1!$A$2:$E$10,5,0) -> Bin | M40: =J40/K40 -> 4 | O40: HR47E8635 | P40: 12509Q100239
...

Sheet 03-12-2025
A1: Dailly SMG Pick List | J1: 24AACCN5739J1ZA
A2: Supply Month | B2: 45994 | L2: Vehicle No
A3: INVOICE NO | B3: KANBAN NO | C3: PART NUMBER | D3: Material Code | E3: PART NAME | F3: SUPPLY DATE | G3: SUPPLY TIME | H3: UNLOADING LOC | I3: Line | J3: Qty Req | K3: Packing Standerd | L3: Packed in | M3: TTL Bin | N3: TORLLY | O3: Vehicle No | P3: INV NO
A4: G/I/25-26/01311 | B4: 03Z501091131AC5 | C4: 55101M58U10 | D4: =VLOOKUP($C4,Sheet1!$A$2:$B$10,2,0) -> 141110-14600 | E4: CALIPER ASSY,FRONT BRAKE,R | F4: 45994 | G4: 0.39583333 | H4: CA-07 | I4: AC5 | J4: 54 | K4: =VLOOKUP($C4,Sheet1!$A$2:$D$10,4,0) -> 18 | L4: =VLOOKUP($C4,Sheet1!$A$2:$E$10,5,0) -> Trolley (H) | N4: 3 | O4: GJ01KT7585 | P4: Barode sticker
A5: G/I/25-26/01311 | B5: 03Z501096001AC5 | C5: 55102M58U10 | D5: =VLOOKUP($C5,Sheet1!$A$2:$B$10,2,0) -> 141120-14600 | E5: CALIPER ASSY,FRONT BRAKE,L | F5: 45994 | G5: 0.39583333 | H5: CA-07 | I5: AC5 | J5: 54 | K5: =VLOOKUP($C5,Sheet1!$A$2:$D$10,4,0) -> 18 | L5: =VLOOKUP($C5,Sheet1!$A$2:$E$10,5,0) -> Trolley (H) | O5: GJ01KT7585 | P5: Barode sticker
A6: G/I/25-26/01311 | B6: 03Z501049909AC5 | C6: 55311M58U00 | D6: =VLOOKUP($C6,Sheet1!$A$2:$B$10,2,0) -> 141185-74670 | E6: DISC,FRONT BRAKE | F6: 45994 | G6: 0.39583333 | H6: CA-07 | I6: AC5 | J6: 40 | K6: =VLOOKUP($C6,Sheet1!$A$2:$D$10,4,0) -> 40 | L6: =VLOOKUP($C6,Sheet1!$A$2:$E$10,5,0) -> Trolley | N6: =J6/K6 -> 1 | O6: GJ01KT7585 | P6: 910102394
A7: G/I/25-26/01311 | B7: 03Z501100670AC5 | C7: 55311M58U00 | D7: =VLOOKUP($C7,Sheet1!$A$2:$B$10,2,0) -> 141185-74670 | E7: DISC,FRONT BRAKE | F7: 45994 | G7: 0.39583333 | H7: CA-07 | I7: AC5 | J7: 120 | K7: =VLOOKUP($C7,Sheet1!$A$2:$D$10,4,0) -> 40 | L7: =VLOOKUP($C7,Sheet1!$A$2:$E$10,5,0) -> Trolley | N7: =J7/K7 -> 3 | O7: GJ01KT7585 | P7: 910102649- 80 Qty/ 910102507-40 Qty
A8: G/I/25-26/01311 | B8: 03Z501049925AC5 | C8: 55401M58U00 | D8: =VLOOKUP($C8,Sheet1!$A$2:$B$10,2,0) -> 141140-91211 | E8: CALIPER ASSY,REAR BRAKE,R | F8: 45994 | G8: 0.39583333 | H8: CA-21 | I8: AC5 | J8: 20 | K8: =VLOOKUP($C8,Sheet1!$A$2:$D$10,4,0) -> 2 | L8: =VLOOKUP($C8,Sheet1!$A$2:$E$10,5,0) -> Bin | M8: =J8/K8 -> 10 | O8: GJ01KT7585 | P8: 12509Q100239
A9: G/I/25-26/01311 | B9: 03Z501102567AC5 | C9: 55401M58U00 | D9: =VLOOKUP($C9,Sheet1!$A$2:$B$10,2,0) -> 141140-91211 | E9: CALIPER ASSY,REAR BRAKE,R | F9: 45994 | G9: 0.39583333 | H9: CA-21 | I9: AC5 | J9: 54 | K9: =VLOOKUP($C9,Sheet1!$A$2:$D$10,4,0) -> 2 | L9: =VLOOKUP($C9,Sheet1!$A$2:$E$10,5,0) -> Bin | M9: =J9/K9 -> 27 | O9: GJ01KT7585 | P9: 12509Q100239
A10: G/I/25-26/01311 | B10: 03Z501049950AC5 | C10: 55402M58U00 | D10: =VLOOKUP($C10,Sheet1!$A$2:$B$10,2,0) -> 141150-91211 | E10: CALIPER ASSY,REAR BRAKE,L | F10: 45994 | G10: 0.39583333 | H10: CA-21 | I10: AC5 | J10: 20 | K10: =VLOOKUP($C10,Sheet1!$A$2:$D$10,4,0) -> 2 | L10: =VLOOKUP($C10,Sheet1!$A$2:$E$10,5,0) -> Bin | M10: =J10/K10 -> 10 | O10: GJ01KT7585 | P10: 12509Q100239
A11: G/I/25-26/01311 | B11: 03Z501102486AC5 | C11: 55402M58U00 | D11: =VLOOKUP($C11,Sheet1!$A$2:$B$10,2,0) -> 141150-91211 | E11: CALIPER ASSY,REAR BRAKE,L | F11: 45994 | G11: 0.39583333 | H11: CA-21 | I11: AC5 | J11: 54 | K11: =VLOOKUP($C11,Sheet1!$A$2:$D$10,4,0) -> 2 | L11: =VLOOKUP($C11,Sheet1!$A$2:$E$10,5,0) -> Bin | M11: =J11/K11 -> 27 | O11: GJ01KT7585 | P11: 12509Q100239
M12: 74 | N12: 7
A13: G/I/25-26/01314 | B13: 03Z501049852AC5 | C13: 55101M58U10 | D13: =VLOOKUP($C13,Sheet1!$A$2:$B$10,2,0) -> 141110-14600 | E13: CALIPER ASSY,FRONT BRAKE,R | F13: 45994 | G13: 0.39583333 | H13: CA-07 | I13: AC5 | J13: 18 | K13: =VLOOKUP($C13,Sheet1!$A$2:$D$10,4,0) -> 18 | L13: =VLOOKUP($C13,Sheet1!$A$2:$E$10,5,0) -> Trolley (H) | N13: 1 | O13: GJ23Y8525 | P13: Barode sticker
A14: G/I/25-26/01314 | B14: 03Z501049879AC5 | C14: 55102M58U10 | D14: =VLOOKUP($C14,Sheet1!$A$2:$B$10,2,0) -> 141120-14600 | E14: CALIPER ASSY,FRONT BRAKE,L | F14: 45994 | G14: 0.39583333 | H14: CA-07 | I14: AC5 | J14: 18 | K14: =VLOOKUP($C14,Sheet1!$A$2:$D$10,4,0) -> 18 | L14: =VLOOKUP($C14,Sheet1!$A$2:$E$10,5,0) -> Trolley (H) | O14: GJ23Y8525 | P14: Barode sticker
A15: G/I/25-26/01312 | B15: 03Z501049976AC5 | C15: 55611M58U00 | D15: =VLOOKUP($C15,Sheet1!$A$2:$B$10,2,0) -> 141186-74360 | E15: DISC,REAR BRAKE | F15: 45994 | G15: 0.39583333 | H15: CA-21 | I15: AC5 | J15: 40 | K15: =VLOOKUP($C15,Sheet1!$A$2:$D$10,4,0) -> 40 | L15: =VLOOKUP($C15,Sheet1!$A$2:$E$10,5,0) -> Trolley | N15: =J15/K15 -> 1 | O15: GJ23Y8525 | P15: 910101603
A16: G/I/25-26/01312 | B16: 03Z501098403AC5 | C16: 55611M58U00 | D16: =VLOOKUP($C16,Sheet1!$A$2:$B$10,2,0) -> 141186-74360 | E16: DISC,REAR BRAKE | F16: 45994 | G16: 0.39583333 | H16: CA-21 | I16: AC5 | J16: 120 | K16: =VLOOKUP($C16,Sheet1!$A$2:$D$10,4,0) -> 40 | L16: =VLOOKUP($C16,Sheet1!$A$2:$E$10,5,0) -> Trolley | N16: =J16/K16 -> 3 | O16: GJ23Y8525 | P16: 910101143-02 Qty. / 910101603- 80 Qty. / 910101985-38 Qty.
A17: G/I/25-26/01313 | B17: 03Z501097423AC5 | C17: 56110M58UA1 | D17: =VLOOKUP($C17,Sheet1!$A$2:$B$10,2,0) -> 116040-92240 | E17: ACTUATOR ASSY,NO VARIANT ESP | F17: 45994 | G17: 0.39583333 | H17: CA-01 | I17: AC5 | J17: 36 | K17: =VLOOKUP($C17,Sheet1!$A$2:$D$10,4,0) -> 6 | L17: =VLOOKUP($C17,Sheet1!$A$2:$E$10,5,0) -> Bin | M17: =J17/K17 -> 6 | O17: GJ23Y8525 | P17: 12505Q100031
A18: G/I/25-26/01313 | B18: 03Z501049992AC5 | C18: 5A120M58U01 | D18: =VLOOKUP($C18,Sheet1!$A$2:$B$10,2,0) -> 114010-50820 | E18: CYLINDER ASSY,BK MASTER W/ECU | F18: 45994 | G18: 0.39583333 | H18: CA-01 | I18: AC5 | J18: 11 | K18: =VLOOKUP($C18,Sheet1!$A$2:$D$10,4,0) -> 1 | L18: =VLOOKUP($C18,Sheet1!$A$2:$E$10,5,0) -> Bin | M18: =J18/K18 -> 11 | O18: GJ23Y8525 | P18: 12504Q100266
A19: G/I/25-26/01313 | B19: 03Z501101676AC5 | C19: 5A120M58U01 | D19: =VLOOKUP($C19,Sheet1!$A$2:$B$10,2,0) -> 114010-50820 | E19: CYLINDER ASSY,BK MASTER W/ECU | F19: 45994 | G19: 0.39583333 | H19: CA-01 | I19: AC5 | J19: 22 | K19: =VLOOKUP($C19,Sheet1!$A$2:$D$10,4,0) -> 1 | L19: =VLOOKUP($C19,Sheet1!$A$2:$E$10,5,0) -> Bin | M19: =J19/K19 -> 22 | O19: GJ23Y8525 | P19: 12504Q100256
A20: G/I/25-26/01313 | B20: 03Z501050028AC5 | C20: 5A120M58U50 | D20: =VLOOKUP($C20,Sheet1!$A$2:$B$10,2,0) -> 114010-50830 | E20: CYLINDER ASSY,BK MASTER W/ECU | F20: 45994 | G20: 0.39583333 | H20: CA-01 | I20: AC5 | J20: 9 | K20: =VLOOKUP($C20,Sheet1!$A$2:$D$10,4,0) -> 1 | L20: =VLOOKUP($C20,Sheet1!$A$2:$E$10,5,0) -> Bin | M20: =J20/K20 -> 9 | O20: GJ23Y8525 | P20: 12504Q100256
A21: G/I/25-26/01313 | B21: 03Z501088700AC5 | C21: 5A120M58U50 | D21: =VLOOKUP($C21,Sheet1!$A$2:$B$10,2,0) -> 114010-50830 | E21: CYLINDER ASSY,BK MASTER W/ECU | F21: 45994 | G21: 0.39583333 | H21: CA-01 | I21: AC5 | J21: 32 | K21: =VLOOKUP($C21,Sheet1!$A$2:$D$10,4,0) -> 1 | L21: =VLOOKUP($C21,Sheet1!$A$2:$E$10,5,0) -> Bin | M21: =J21/K21 -> 32 | O21: GJ23Y8525 | P21: 12504Q100256
M22: 80 | N22: 5
A23: G/I/25-26/01315 | B23: 03Z501049860AC5 | C23: 55101M58U10 | D23: =VLOOKUP($C23,Sheet1!$A$2:$B$10,2,0) -> 141110-14600 | E23: CALIPER ASSY,FRONT BRAKE,R | F23: 45994 | G23: 0.52083333 | H23: CA-07 | I23: AC5 | J23: 18 | K23: =VLOOKUP($C23,Sheet1!$A$2:$D$10,4,0) -> 18 | L23: =VLOOKUP($C23,Sheet1!$A$2:$E$10,5,0) -> Trolley (H) | N23: 1 | O23: HR47G9416 | P23: old invoice
A24: G/I/25-26/01315 | B24: 03Z501049887AC5 | C24: 55102M58U10 | D24: =VLOOKUP($C24,Sheet1!$A$2:$B$10,2,0) -> 141120-14600 | E24: CALIPER ASSY,FRONT BRAKE,L | F24: 45994 | G24: 0.52083333 | H24: CA-07 | I24: AC5 | J24: 18 | K24: =VLOOKUP($C24,Sheet1!$A$2:$D$10,4,0) -> 18 | L24: =VLOOKUP($C24,Sheet1!$A$2:$E$10,5,0) -> Trolley (H) | O24: HR47G9416 | P24: old invoice
A25: G/I/25-26/01315 | B25: 03Z501049933AC5 | C25: 55401M58U00 | D25: =VLOOKUP($C25,Sheet1!$A$2:$B$10,2,0) -> 141140-91211 | E25: CALIPER ASSY,REAR BRAKE,R | F25: 45994 | G25: 0.52083333 | H25: CA-21 | I25: AC5 | J25: 4 | K25: =VLOOKUP($C25,Sheet1!$A$2:$D$10,4,0) -> 2 | L25: =VLOOKUP($C25,Sheet1!$A$2:$E$10,5,0) -> Bin | M25: =J25/K25 -> 2 | O25: HR47G9416 | P25: 12509Q100239
A26: G/I/25-26/01315 | B26: 03Z501049968AC5 | C26: 55402M58U00 | D26: =VLOOKUP($C26,Sheet1!$A$2:$B$10,2,0) -> 141150-91211 | E26: CALIPER ASSY,REAR BRAKE,L | F26: 45994 | G26: 0.52083333 | H26: CA-21 | I26: AC5 | J26: 4 | K26: =VLOOKUP($C26,Sheet1!$A$2:$D$10,4,0) -> 2 | L26: =VLOOKUP($C26,Sheet1!$A$2:$E$10,5,0) -> Bin | M26: =J26/K26 -> 2 | O26: HR47G9416 | P26: 12509Q100239
A27: G/I/25-26/01316 | B27: 03Z501050001AC5 | C27: 5A120M58U01 | D27: =VLOOKUP($C27,Sheet1!$A$2:$B$10,2,0) -> 114010-50820 | E27: CYLINDER ASSY,BK MASTER W/ECU | F27: 45994 | G27: 0.52083333 | H27: CA-01 | I27: AC5 | J27: 2 | K27: =VLOOKUP($C27,Sheet1!$A$2:$D$10,4,0) -> 1 | L27: =VLOOKUP($C27,Sheet1!$A$2:$E$10,5,0) -> Bin | M27: =J27/K27 -> 2 | O27: HR47G9416 | P27: 12504Q100256
A28: G/I/25-26/01316 | B28: 03Z501050036AC5 | C28: 5A120M58U50 | D28: =VLOOKUP($C28,Sheet1!$A$2:$B$10,2,0) -> 114010-50830 | E28: CYLINDER ASSY,BK MASTER W/ECU | F28: 45994 | G28: 0.52083333 | H28: CA-01 | I28: AC5 | J28: 1 | K28: =VLOOKUP($C28,Sheet1!$A$2:$D$10,4,0) -> 1 | L28: =VLOOKUP($C28,Sheet1!$A$2:$E$10,5,0) -> Bin | M28: =J28/K28 -> 1 | O28: HR47G9416 | P28: 12504Q100256
M29: 7 | N29: 1
A30: G/I/25-26/01317 | B30: 03Z501049895AC5 | C30: 55311M58U00 | D30: =VLOOKUP($C30,Sheet1!$A$2:$B$10,2,0) -> 141185-74670 | E30: DISC,FRONT BRAKE | F30: 45994 | G30: 0.97916667 | H30: CA-07 | I30: AC5 | J30: 40 | K30: =VLOOKUP($C30,Sheet1!$A$2:$D$10,4,0) -> 40 | L30: =VLOOKUP($C30,Sheet1!$A$2:$E$10,5,0) -> Trolley | N30: =J30/K30 -> 1 | O30: HR47E8635 | P30: 910102507
A31: G/I/25-26/01317 | B31: 03Z501049917AC5 | C31: 55401M58U00 | D31: =VLOOKUP($C31,Sheet1!$A$2:$B$10,2,0) -> 141140-91211 | E31: CALIPER ASSY,REAR BRAKE,R | F31: 45994 | G31: 0.97916667 | H31: CA-21 | I31: AC5 | J31: 12 | K31: =VLOOKUP($C31,Sheet1!$A$2:$D$10,4,0) -> 2 | L31: =VLOOKUP($C31,Sheet1!$A$2:$E$10,5,0) -> Bin | M31: =J31/K31 -> 6 | O31: HR47E8635 | P31: 12509Q100239
A32: G/I/25-26/01317 | B32: 03Z501049941AC5 | C32: 55402M58U00 | D32: =VLOOKUP($C32,Sheet1!$A$2:$B$10,2,0) -> 141150-91211 | E32: CALIPER ASSY,REAR BRAKE,L | F32: 45994 | G32: 0.97916667 | H32: CA-21 | I32: AC5 | J32: 12 | K32: =VLOOKUP($C32,Sheet1!$A$2:$D$10,4,0) -> 2 | L32: =VLOOKUP($C32,Sheet1!$A$2:$E$10,5,0) -> Bin | M32: =J32/K32 -> 6 | O32: HR47E8635 | P32: 12509Q100239
A33: G/I/25-26/01318 | B33: 03Z501049984AC5 | C33: 5A120M58U01 | D33: =VLOOKUP($C33,Sheet1!$A$2:$B$10,2,0) -> 114010-50820 | E33: CYLINDER ASSY,BK MASTER W/ECU | F33: 45994 | G33: 0.97916667 | H33: CA-01 | I33: AC5 | J33: 2 | K33: =VLOOKUP($C33,Sheet1!$A$2:$D$10,4,0) -> 1 | L33: =VLOOKUP($C33,Sheet1!$A$2:$E$10,5,0) -> Bin | M33: =J33/K33 -> 2 | O33: HR47E8635 | P33: 12504Q100256
A34: G/I/25-26/01318 | B34: 03Z501050010AC5 | C34: 5A120M58U50 | D34: =VLOOKUP($C34,Sheet1!$A$2:$B$10,2,0) -> 114010-50830 | E34: CYLINDER ASSY,BK MASTER W/ECU | F34: 45994 | G34: 0.97916667 | H34: CA-01 | I34: AC5 | J34: 11 | K34: =VLOOKUP($C34,Sheet1!$A$2:$D$10,4,0) -> 1 | L34: =VLOOKUP($C34,Sheet1!$A$2:$E$10,5,0) -> Bin | M34: =J34/K34 -> 11 | O34: HR47E8635 | P34: 12504Q100256
M35: 25 | N35: 1
B36: Download : X539_eNagare_2025122.txt

Sheet 04-12-2025
A1: Dailly SMG Pick List | J1: 24AACCN5739J1ZA
A2: Supply Month | B2: 45995 | L2: Vehicle No
A3: INVOICE NO | B3: KANBAN NO | C3: PART NUMBER | D3: Material Code | E3: PART NAME | F3: SUPPLY DATE | G3: SUPPLY TIME | H3: UNLOADING LOC | I3: Line | J3: Qty Req | K3: Packing Standerd | L3: Packed in | M3: TTL Bin | N3: TORLLY | O3: Vehicle No | P3: INV NO
A4: G/I/25-26/01319 | B4: 04Z501700855AC5 | C4: 55101M58U10 | D4: =VLOOKUP($C4,Sheet1!$A$2:$B$10,2,0) -> 141110-14600 | E4: CALIPER ASSY,FRONT BRAKE,R | F4: 45995 | G4: 0.27083333 | H4: CA-07 | I4: AC5 | J4: 18 | K4: =VLOOKUP($C4,Sheet1!$A$2:$D$10,4,0) -> 18 | L4: =VLOOKUP($C4,Sheet1!$A$2:$E$10,5,0) -> Trolley (H) | N4: 1 | O4: GJ02ZZ7144 | P4: Barode sticker | Q4: old
A5: G/I/25-26/01319 | B5: 04Z501700898AC5 | C5: 55102M58U10 | D5: =VLOOKUP($C5,Sheet1!$A$2:$B$10,2,0) -> 141120-14600 | E5: CALIPER ASSY,FRONT BRAKE,L | F5: 45995 | G5: 0.27083333 | H5: CA-07 | I5: AC5 | J5: 18 | K5: =VLOOKUP($C5,Sheet1!$A$2:$D$10,4,0) -> 18 | L5: =VLOOKUP($C5,Sheet1!$A$2:$E$10,5,0) -> Trolley (H) | O5: GJ02ZZ7144 | P5: Barode sticker | Q5: old
A6: G/I/25-26/01319 | B6: 04Z501742914AC5 | C6: 55101M58U10 | D6: =VLOOKUP($C6,Sheet1!$A$2:$B$10,2,0) -> 141110-14600 | E6: CALIPER ASSY,FRONT BRAKE,R | F6: 45995 | G6: 0.27083333 | H6: CA-07 | I6: AC5 | J6: 36 | K6: =VLOOKUP($C6,Sheet1!$A$2:$D$10,4,0) -> 18 | L6: =VLOOKUP($C6,Sheet1!$A$2:$E$10,5,0) -> Trolley (H) | N6: 2 | O6: GJ02ZZ7144 | P6: Barode sticker | Q6: old
A7: G/I/25-26/01319 | B7: 04Z501753444AC5 | C7: 55102M58U10 | D7: =VLOOKUP($C7,Sheet1!$A$2:$B$10,2,0) -> 141120-14600 | E7: CALIPER ASSY,FRONT BRAKE,L | F7: 45995 | G7: 0.27083333 | H7: CA-07 | I7: AC5 | J7: 36 | K7: =VLOOKUP($C7,Sheet1!$A$2:$D$10,4,0) -> 18 | L7: =VLOOKUP($C7,Sheet1!$A$2:$E$10,5,0) -> Trolley (H) | O7: GJ02ZZ7144 | P7: Barode sticker | Q7: old
A8: G/I/25-26/01319 | B8: 04Z501700936AC5 | C8: 55311M58U00 | D8: =VLOOKUP($C8,Sheet1!$A$2:$B$10,2,0) -> 141185-74670 | E8: DISC,FRONT BRAKE | F8: 45995 | G8: 0.27083333 | H8: CA-07 | I8: AC5 | J8: 40 | K8: =VLOOKUP($C8,Sheet1!$A$2:$D$10,4,0) -> 40 | L8: =VLOOKUP($C8,Sheet1!$A$2:$E$10,5,0) -> Trolley | N8: =J8/K8 -> 1 | O8: GJ02ZZ7144 | P8: 910102807
A9: G/I/25-26/01319 | B9: 04Z501749951AC5 | C9: 55311M58U00 | D9: =VLOOKUP($C9,Sheet1!$A$2:$B$10,2,0) -> 141185-74670 | E9: DISC,FRONT BRAKE | F9: 45995 | G9: 0.27083333 | H9: CA-07 | I9: AC5 | J9: 40 | K9: =VLOOKUP($C9,Sheet1!$A$2:$D$10,4,0) -> 40 | L9: =VLOOKUP($C9,Sheet1!$A$2:$E$10,5,0) -> Trolley | N9: =J9/K9 -> 1 | O9: GJ02ZZ7144 | P9: 910102649
A10: G/I/25-26/01319 | B10: 04Z501700987AC5 | C10: 55401M58U00 | D10: =VLOOKUP($C10,Sheet1!$A$2:$B$10,2,0) -> 141140-91211 | E10: CALIPER ASSY,REAR BRAKE,R | F10: 45995 | G10: 0.27083333 | H10: CA-21 | I10: AC5 | J10: 20 | K10: =VLOOKUP($C10,Sheet1!$A$2:$D$10,4,0) -> 2 | L10: =VLOOKUP($C10,Sheet1!$A$2:$E$10,5,0) -> Bin | M10: =J10/K10 -> 10 | O10: GJ02ZZ7144 | P10: 12509Q100239
A11: G/I/25-26/01319 | B11: 04Z501743252AC5 | C11: 55401M58U00 | D11: =VLOOKUP($C11,Sheet1!$A$2:$B$10,2,0) -> 141140-91211 | E11: CALIPER ASSY,REAR BRAKE,R | F11: 45995 | G11: 0.27083333 | H11: CA-21 | I11: AC5 | J11: 22 | K11: =VLOOKUP($C11,Sheet1!$A$2:$D$10,4,0) -> 2 | L11: =VLOOKUP($C11,Sheet1!$A$2:$E$10,5,0) -> Bin | M11: =J11/K11 -> 11 | O11: GJ02ZZ7144 | P11: 12509Q100239
A12: G/I/25-26/01319 | B12: 04Z501701029AC5 | C12: 55402M58U00 | D12: =VLOOKUP($C12,Sheet1!$A$2:$B$10,2,0) -> 141150-91211 | E12: CALIPER ASSY,REAR BRAKE,L | F12: 45995 | G12: 0.27083333 | H12: CA-21 | I12: AC5 | J12: 20 | K12: =VLOOKUP($C12,Sheet1!$A$2:$D$10,4,0) -> 2 | L12: =VLOOKUP($C12,Sheet1!$A$2:$E$10,5,0) -> Bin | M12: =J12/K12 -> 10 | O12: GJ02ZZ7144 | P12: 12509Q100239
A13: G/I/25-26/01319 | B13: 04Z501758764AC5 | C13: 55402M58U00 | D13: =VLOOKUP($C13,Sheet1!$A$2:$B$10,2,0) -> 141150-91211 | E13: CALIPER ASSY,REAR BRAKE,L | F13: 45995 | G13: 0.27083333 | H13: CA-21 | I13: AC5 | J13: 22 | K13: =VLOOKUP($C13,Sheet1!$A$2:$D$10,4,0) -> 2 | L13: =VLOOKUP($C13,Sheet1!$A$2:$E$10,5,0) -> Bin | M13: =J13/K13 -> 11 | O13: GJ02ZZ7144 | P13: 12509Q100239
A14: G/I/25-26/01319 | B14: 04Z501701061AC5 | C14: 55611M58U00 | D14: =VLOOKUP($C14,Sheet1!$A$2:$B$10,2,0) -> 141186-74360 | E14: DISC,REAR BRAKE | F14: 45995 | G14: 0.27083333 | H14: CA-21 | I14: AC5 | J14: 40 | K14: =VLOOKUP($C14,Sheet1!$A$2:$D$10,4,0) -> 40 | L14: =VLOOKUP($C14,Sheet1!$A$2:$E$10,5,0) -> Trolley | N14: =J14/K14 -> 1 | O14: GJ02ZZ7144 | P14: 910101603 | Q14: old
A15: G/I/25-26/01319 | B15: 04Z501753207AC5 | C15: 55611M58U00 | D15: =VLOOKUP($C15,Sheet1!$A$2:$B$10,2,0) -> 141186-74360 | E15: DISC,REAR BRAKE | F15: 45995 | G15: 0.27083333 | H15: CA-21 | I15: AC5 | J15: 80 | K15: =VLOOKUP($C15,Sheet1!$A$2:$D$10,4,0) -> 40 | L15: =VLOOKUP($C15,Sheet1!$A$2:$E$10,5,0) -> Trolley | N15: =J15/K15 -> 2 | O15: GJ02ZZ7144 | P15: 910101603/ 910100578 | Q15: old
A16: G/I/25-26/01320 | B16: 04Z501701100AC5 | C16: 56110M58UA1 | D16: =VLOOKUP($C16,Sheet1!$A$2:$B$10,2,0) -> 116040-92240 | E16: ACTUATOR ASSY,NO VARIANT ESP | F16: 45995 | G16: 0.27083333 | H16: CA-01 | I16: AC5 | J16: 24 | K16: =VLOOKUP($C16,Sheet1!$A$2:$D$10,4,0) -> 6 | L16: =VLOOKUP($C16,Sheet1!$A$2:$E$10,5,0) -> Bin | M16: =J16/K16 -> 4 | O16: GJ02ZZ7144 | P16: 12505Q100031
A17: G/I/25-26/01320 | B17: 04Z501746081AC5 | C17: 56110M58UA1 | D17: =VLOOKUP($C17,Sheet1!$A$2:$B$10,2,0) -> 116040-92240 | E17: ACTUATOR ASSY,NO VARIANT ESP | F17: 45995 | G17: 0.27083333 | H17: CA-01 | I17: AC5 | J17: 18 | K17: =VLOOKUP($C17,Sheet1!$A$2:$D$10,4,0) -> 6 | L17: =VLOOKUP($C17,Sheet1!$A$2:$E$10,5,0) -> Bin | M17: =J17/K17 -> 3 | O17: GJ02ZZ7144 | P17: 12505Q100031
A18: G/I/25-26/01320 | B18: 04Z501701142AC5 | C18: 5A120M58U01 | D18: =VLOOKUP($C18,Sheet1!$A$2:$B$10,2,0) -> 114010-50820 | E18: CYLINDER ASSY,BK MASTER W/ECU | F18: 45995 | G18: 0.27083333 | H18: CA-01 | I18: AC5 | J18: 9 | K18: =VLOOKUP($C18,Sheet1!$A$2:$D$10,4,0) -> 1 | L18: =VLOOKUP($C18,Sheet1!$A$2:$E$10,5,0) -> Bin | M18: =J18/K18 -> 9 | O18: GJ02ZZ7144 | P18: 12504Q100266
A19: G/I/25-26/01320 | B19: 04Z501741993AC5 | C19: 5A120M58U01 | D19: =VLOOKUP($C19,Sheet1!$A$2:$B$10,2,0) -> 114010-50820 | E19: CYLINDER ASSY,BK MASTER W/ECU | F19: 45995 | G19: 0.27083333 | H19: CA-01 | I19: AC5 | J19: 13 | K19: =VLOOKUP($C19,Sheet1!$A$2:$D$10,4,0) -> 1 | L19: =VLOOKUP($C19,Sheet1!$A$2:$E$10,5,0) -> Bin | M19: =J19/K19 -> 13 | O19: GJ02ZZ7144 | P19: 12504Q100266
A20: G/I/25-26/01320 | B20: 04Z501701185AC5 | C20: 5A120M58U50 | D20: =VLOOKUP($C20,Sheet1!$A$2:$B$10,2,0) -> 114010-50830 | E20: CYLINDER ASSY,BK MASTER W/ECU | F20: 45995 | G20: 0.27083333 | H20: CA-01 | I20: AC5 | J20: 11 | K20: =VLOOKUP($C20,Sheet1!$A$2:$D$10,4,0) -> 1 | L20: =VLOOKUP($C20,Sheet1!$A$2:$E$10,5,0) -> Bin | M20: =J20/K20 -> 11 | O20: GJ02ZZ7144 | P20: 12504Q100256
A21: G/I/25-26/01320 | B21: 04Z501754130AC5 | C21: 5A120M58U50 | D21: =VLOOKUP($C21,Sheet1!$A$2:$B$10,2,0) -> 114010-50830 | E21: CYLINDER ASSY,BK MASTER W/ECU | F21: 45995 | G21: 0.27083333 | H21: CA-01 | I21: AC5 | J21: 10 | K21: =VLOOKUP($C21,Sheet1!$A$2:$D$10,4,0) -> 1 | L21: =VLOOKUP($C21,Sheet1!$A$2:$E$10,5,0) -> Bin | M21: =J21/K21 -> 10 | O21: GJ02ZZ7144 | P21: 12504Q100256
M22: 92 | N22: 8
A23: G/I/25-26/01321 | B23: 04Z501700863AC5 | C23: 55101M58U10 | D23: =VLOOKUP($C23,Sheet1!$A$2:$B$10,2,0) -> 141110-14600 | E23: CALIPER ASSY,FRONT BRAKE,R | F23: 45995 | G23: 0.52083333 | H23: CA-07 | I23: AC5 | J23: 18 | K23: =VLOOKUP($C23,Sheet1!$A$2:$D$10,4,0) -> 18 | L23: =VLOOKUP($C23,Sheet1!$A$2:$E$10,5,0) -> Trolley (H) | N23: 1 | O23: GJ23Y8525 | P23: Barode sticker
A24: G/I/25-26/01321 | B24: 04Z501700901AC5 | C24: 55102M58U10 | D24: =VLOOKUP($C24,Sheet1!$A$2:$B$10,2,0) -> 141120-14600 | E24: CALIPER ASSY,FRONT BRAKE,L | F24: 45995 | G24: 0.52083333 | H24: CA-07 | I24: AC5 | J24: 18 | K24: =VLOOKUP($C24,Sheet1!$A$2:$D$10,4,0) -> 18 | L24: =VLOOKUP($C24,Sheet1!$A$2:$E$10,5,0) -> Trolley (H) | O24: GJ23Y8525 | P24: Barode sticker
A25: G/I/25-26/01321 | B25: 04Z501700944AC5 | C25: 55311M58U00 | D25: =VLOOKUP($C25,Sheet1!$A$2:$B$10,2,0) -> 141185-74670 | E25: DISC,FRONT BRAKE | F25: 45995 | G25: 0.52083333 | H25: CA-07 | I25: AC5 | J25: 40 | K25: =VLOOKUP($C25,Sheet1!$A$2:$D$10,4,0) -> 40 | L25: =VLOOKUP($C25,Sheet1!$A$2:$E$10,5,0) -> Trolley | N25: =J25/K25 -> 1 | O25: GJ23Y8525 | P25: 910102786
A26: G/I/25-26/01321 | B26: 04Z501700995AC5 | C26: 55401M58U00 | D26: =VLOOKUP($C26,Sheet1!$A$2:$B$10,2,0) -> 141140-91211 | E26: CALIPER ASSY,REAR BRAKE,R | F26: 45995 | G26: 0.52083333 | H26: CA-21 | I26: AC5 | J26: 20 | K26: =VLOOKUP($C26,Sheet1!$A$2:$D$10,4,0) -> 2 | L26: =VLOOKUP($C26,Sheet1!$A$2:$E$10,5,0) -> Bin | M26: =J26/K26 -> 10 | O26: GJ23Y8525 | P26: 12509Q100239
A27: G/I/25-26/01321 | B27: 04Z501701037AC5 | C27: 55402M58U00 | D27: =VLOOKUP($C27,Sheet1!$A$2:$B$10,2,0) -> 141150-91211 | E27: CALIPER ASSY,REAR BRAKE,L | F27: 45995 | G27: 0.52083333 | H27: CA-21 | I27: AC5 | J27: 20 | K27: =VLOOKUP($C27,Sheet1!$A$2:$D$10,4,0) -> 2 | L27: =VLOOKUP($C27,Sheet1!$A$2:$E$10,5,0) -> Bin | M27: =J27/K27 -> 10 | O27: GJ23Y8525 | P27: 12509Q100239
A28: G/I/25-26/01321 | B28: 04Z501701070AC5 | C28: 55611M58U00 | D28: =VLOOKUP($C28,Sheet1!$A$2:$B$10,2,0) -> 141186-74360 | E28: DISC,REAR BRAKE | F28: 45995 | G28: 0.52083333 | H28: CA-21 | I28: AC5 | J28: 40 | K28: =VLOOKUP($C28,Sheet1!$A$2:$D$10,4,0) -> 40 | L28: =VLOOKUP($C28,Sheet1!$A$2:$E$10,5,0) -> Trolley | N28: =J28/K28 -> 1 | O28: GJ23Y8525 | P28: 910100578
A29: G/I/25-26/01322 | B29: 04Z501701118AC5 | C29: 56110M58UA1 | D29: =VLOOKUP($C29,Sheet1!$A$2:$B$10,2,0) -> 116040-92240 | E29: ACTUATOR ASSY,NO VARIANT ESP | F29: 45995 | G29: 0.52083333 | H29: CA-01 | I29: AC5 | J29: 18 | K29: =VLOOKUP($C29,Sheet1!$A$2:$D$10,4,0) -> 6 | L29: =VLOOKUP($C29,Sheet1!$A$2:$E$10,5,0) -> Bin | M29: =J29/K29 -> 3 | O29: GJ23Y8525 | P29: 12505Q100031
A30: G/I/25-26/01322 | B30: 04Z501701150AC5 | C30: 5A120M58U01 | D30: =VLOOKUP($C30,Sheet1!$A$2:$B$10,2,0) -> 114010-50820 | E30: CYLINDER ASSY,BK MASTER W/ECU | F30: 45995 | G30: 0.52083333 | H30: CA-01 | I30: AC5 | J30: 11 | K30: =VLOOKUP($C30,Sheet1!$A$2:$D$10,4,0) -> 1 | L30: =VLOOKUP($C30,Sheet1!$A$2:$E$10,5,0) -> Bin | M30: =J30/K30 -> 11 | O30: GJ23Y8525 | P30: 12504Q100266
A31: G/I/25-26/01322 | B31: 04Z501701193AC5 | C31: 5A120M58U50 | D31: =VLOOKUP($C31,Sheet1!$A$2:$B$10,2,0) -> 114010-50830 | E31: CYLINDER ASSY,BK MASTER W/ECU | F31: 45995 | G31: 0.52083333 | H31: CA-01 | I31: AC5 | J31: 9 | K31: =VLOOKUP($C31,Sheet1!$A$2:$D$10,4,0) -> 1 | L31: =VLOOKUP($C31,Sheet1!$A$2:$E$10,5,0) -> Bin | M31: =J31/K31 -> 9 | O31: GJ23Y8525 | P31: 12504Q100256
M32: 43 | N32: 3
A33: G/I/25-26/01323 | B33: 04Z501700871AC5 | C33: 55101M58U10 | D33: =VLOOKUP($C33,Sheet1!$A$2:$B$10,2,0) -> 141110-14600 | E33: CALIPER ASSY,FRONT BRAKE,R | F33: 45995 | G33: 0.60416667 | H33: CA-07 | I33: AC5 | J33: 18 | K33: =VLOOKUP($C33,Sheet1!$A$2:$D$10,4,0) -> 18 | L33: =VLOOKUP($C33,Sheet1!$A$2:$E$10,5,0) -> Trolley (H) | N33: 1 | O33: HR47G9416 | P33: Barode sticker
A34: G/I/25-26/01323 | B34: 04Z501700910AC5 | C34: 55102M58U10 | D34: =VLOOKUP($C34,Sheet1!$A$2:$B$10,2,0) -> 141120-14600 | E34: CALIPER ASSY,FRONT BRAKE,L | F34: 45995 | G34: 0.60416667 | H34: CA-07 | I34: AC5 | J34: 18 | K34: =VLOOKUP($C34,Sheet1!$A$2:$D$10,4,0) -> 18 | L34: =VLOOKUP($C34,Sheet1!$A$2:$E$10,5,0) -> Trolley (H) | O34: HR47G9416 | P34: Barode sticker
A35: G/I/25-26/01323 | B35: 04Z501700952AC5 | C35: 55311M58U00 | D35: =VLOOKUP($C35,Sheet1!$A$2:$B$10,2,0) -> 141185-74670 | E35: DISC,FRONT BRAKE | F35: 45995 | G35: 0.60416667 | H35: CA-07 | I35: AC5 | J35: 40 | K35: =VLOOKUP($C35,Sheet1!$A$2:$D$10,4,0) -> 40 | L35: =VLOOKUP($C35,Sheet1!$A$2:$E$10,5,0) -> Trolley | N35: =J35/K35 -> 1 | O35: HR47G9416 | P35: 910102786
A36: G/I/25-26/01323 | B36: 04Z501701002AC5 | C36: 55401M58U00 | D36: =VLOOKUP($C36,Sheet1!$A$2:$B$10,2,0) -> 141140-91211 | E36: CALIPER ASSY,REAR BRAKE,R | F36: 45995 | G36: 0.60416667 | H36: CA-21 | I36: AC5 | J36: 20 | K36: =VLOOKUP($C36,Sheet1!$A$2:$D$10,4,0) -> 2 | L36: =VLOOKUP($C36,Sheet1!$A$2:$E$10,5,0) -> Bin | M36: =J36/K36 -> 10 | O36: HR47G9416 | P36: 12509Q100239
A37: G/I/25-26/01323 | B37: 04Z501701045AC5 | C37: 55402M58U00 | D37: =VLOOKUP($C37,Sheet1!$A$2:$B$10,2,0) -> 141150-91211 | E37: CALIPER ASSY,REAR BRAKE,L | F37: 45995 | G37: 0.60416667 | H37: CA-21 | I37: AC5 | J37: 20 | K37: =VLOOKUP($C37,Sheet1!$A$2:$D$10,4,0) -> 2 | L37: =VLOOKUP($C37,Sheet1!$A$2:$E$10,5,0) -> Bin | M37: =J37/K37 -> 10 | O37: HR47G9416 | P37: 12509Q100239
A38: G/I/25-26/01323 | B38: 04Z501701088AC5 | C38: 55611M58U00 | D38: =VLOOKUP($C38,Sheet1!$A$2:$B$10,2,0) -> 141186-74360 | E38: DISC,REAR BRAKE | F38: 45995 | G38: 0.60416667 | H38: CA-21 | I38: AC5 | J38: 40 | K38: =VLOOKUP($C38,Sheet1!$A$2:$D$10,4,0) -> 40 | L38: =VLOOKUP($C38,Sheet1!$A$2:$E$10,5,0) -> Trolley | N38: =J38/K38 -> 1 | O38: HR47G9416 | P38: 910100578
A39: G/I/25-26/01324 | B39: 04Z501701126AC5 | C39: 56110M58UA1 | D39: =VLOOKUP($C39,Sheet1!$A$2:$B$10,2,0) -> 116040-92240 | E39: ACTUATOR ASSY,NO VARIANT ESP | F39: 45995 | G39: 0.60416667 | H39: CA-01 | I39: AC5 | J39: 18 | K39: =VLOOKUP($C39,Sheet1!$A$2:$D$10,4,0) -> 6 | L39: =VLOOKUP($C39,Sheet1!$A$2:$E$10,5,0) -> Bin | M39: =J39/K39 -> 3 | O39: HR47G9416 | P39: 12505Q100031
A40: G/I/25-26/01324 | B40: 04Z501701169AC5 | C40: 5A120M58U01 | D40: =VLOOKUP($C40,Sheet1!$A$2:$B$10,2,0) -> 114010-50820 | E40: CYLINDER ASSY,BK MASTER W/ECU | F40: 45995 | G40: 0.60416667 | H40: CA-01 | I40: AC5 | J40: 5 | K40: =VLOOKUP($C40,Sheet1!$A$2:$D$10,4,0) -> 1 | L40: =VLOOKUP($C40,Sheet1!$A$2:$E$10,5,0) -> Bin | M40: =J40/K40 -> 5 | O40: HR47G9416 | P40: 12504Q100266
...

Sheet 05-12-2025
A1: Dailly SMG Pick List | J1: 24AACCN5739J1ZA
A2: Supply Month | B2: 45996 | L2: Vehicle No
A3: INVOICE NO | B3: KANBAN NO | C3: PART NUMBER | D3: Material Code | E3: PART NAME | F3: SUPPLY DATE | G3: SUPPLY TIME | H3: UNLOADING LOC | I3: Line | J3: Qty Req | K3: Packing Standerd | L3: Packed in | M3: TTL Bin | N3: TORLLY | O3: Vehicle No | P3: INV NO
A4: G/I/25-26/01329 | B4: 05Z502400480AC5 | C4: 55101M58U10 | D4: =VLOOKUP($C4,Sheet1!$A$2:$B$10,2,0) -> 141110-14600 | E4: CALIPER ASSY,FRONT BRAKE,R | F4: 45996 | G4: 0.27083333 | H4: CA-07 | I4: AC5 | J4: 18 | K4: =VLOOKUP($C4,Sheet1!$A$2:$D$10,4,0) -> 18 | L4: =VLOOKUP($C4,Sheet1!$A$2:$E$10,5,0) -> Trolley (H) | N4: 1 | O4: GJ23Y8525 | P4: Barode sticker
A5: G/I/25-26/01329 | B5: 05Z502400510AC5 | C5: 55102M58U10 | D5: =VLOOKUP($C5,Sheet1!$A$2:$B$10,2,0) -> 141120-14600 | E5: CALIPER ASSY,FRONT BRAKE,L | F5: 45996 | G5: 0.27083333 | H5: CA-07 | I5: AC5 | J5: 18 | K5: =VLOOKUP($C5,Sheet1!$A$2:$D$10,4,0) -> 18 | L5: =VLOOKUP($C5,Sheet1!$A$2:$E$10,5,0) -> Trolley (H) | O5: GJ23Y8525 | P5: Barode sticker
A6: G/I/25-26/01329 | B6: 05Z502400553AC5 | C6: 55311M58U00 | D6: =VLOOKUP($C6,Sheet1!$A$2:$B$10,2,0) -> 141185-74670 | E6: DISC,FRONT BRAKE | F6: 45996 | G6: 0.27083333 | H6: CA-07 | I6: AC5 | J6: 40 | K6: =VLOOKUP($C6,Sheet1!$A$2:$D$10,4,0) -> 40 | L6: =VLOOKUP($C6,Sheet1!$A$2:$E$10,5,0) -> Trolley | N6: =J6/K6 -> 1 | O6: GJ23Y8525 | P6: 910102786
A7: G/I/25-26/01329 | B7: 05Z502400596AC5 | C7: 55401M58U00 | D7: =VLOOKUP($C7,Sheet1!$A$2:$B$10,2,0) -> 141140-91211 | E7: CALIPER ASSY,REAR BRAKE,R | F7: 45996 | G7: 0.27083333 | H7: CA-21 | I7: AC5 | J7: 24 | K7: =VLOOKUP($C7,Sheet1!$A$2:$D$10,4,0) -> 2 | L7: =VLOOKUP($C7,Sheet1!$A$2:$E$10,5,0) -> Bin | M7: =J7/K7 -> 12 | O7: GJ23Y8525 | P7: 12509Q100239
A8: G/I/25-26/01329 | B8: 05Z502431238AC5 | C8: 55401M58U00 | D8: =VLOOKUP($C8,Sheet1!$A$2:$B$10,2,0) -> 141140-91211 | E8: CALIPER ASSY,REAR BRAKE,R | F8: 45996 | G8: 0.27083333 | H8: CA-21 | I8: AC5 | J8: 12 | K8: =VLOOKUP($C8,Sheet1!$A$2:$D$10,4,0) -> 2 | L8: =VLOOKUP($C8,Sheet1!$A$2:$E$10,5,0) -> Bin | M8: =J8/K8 -> 6 | O8: GJ23Y8525 | P8: 12509Q100239
A9: G/I/25-26/01329 | B9: 05Z502400634AC5 | C9: 55402M58U00 | D9: =VLOOKUP($C9,Sheet1!$A$2:$B$10,2,0) -> 141150-91211 | E9: CALIPER ASSY,REAR BRAKE,L | F9: 45996 | G9: 0.27083333 | H9: CA-21 | I9: AC5 | J9: 24 | K9: =VLOOKUP($C9,Sheet1!$A$2:$D$10,4,0) -> 2 | L9: =VLOOKUP($C9,Sheet1!$A$2:$E$10,5,0) -> Bin | M9: =J9/K9 -> 12 | O9: GJ23Y8525 | P9: 12509Q100239
A10: G/I/25-26/01329 | B10: 05Z502437937AC5 | C10: 55402M58U00 | D10: =VLOOKUP($C10,Sheet1!$A$2:$B$10,2,0) -> 141150-91211 | E10: CALIPER ASSY,REAR BRAKE,L | F10: 45996 | G10: 0.27083333 | H10: CA-21 | I10: AC5 | J10: 12 | K10: =VLOOKUP($C10,Sheet1!$A$2:$D$10,4,0) -> 2 | L10: =VLOOKUP($C10,Sheet1!$A$2:$E$10,5,0) -> Bin | M10: =J10/K10 -> 6 | O10: GJ23Y8525 | P10: 12509Q100239
A11: G/I/25-26/01329 | B11: 05Z502400669AC5 | C11: 55611M58U00 | D11: =VLOOKUP($C11,Sheet1!$A$2:$B$10,2,0) -> 141186-74360 | E11: DISC,REAR BRAKE | F11: 45996 | G11: 0.27083333 | H11: CA-21 | I11: AC5 | J11: 40 | K11: =VLOOKUP($C11,Sheet1!$A$2:$D$10,4,0) -> 40 | L11: =VLOOKUP($C11,Sheet1!$A$2:$E$10,5,0) -> Trolley | N11: =J11/K11 -> 1 | O11: GJ23Y8525 | P11: 910100578
A12: G/I/25-26/01329 | B12: 05Z502438089AC5 | C12: 55611M58U00 | D12: =VLOOKUP($C12,Sheet1!$A$2:$B$10,2,0) -> 141186-74360 | E12: DISC,REAR BRAKE | F12: 45996 | G12: 0.27083333 | H12: CA-21 | I12: AC5 | J12: 40 | K12: =VLOOKUP($C12,Sheet1!$A$2:$D$10,4,0) -> 40 | L12: =VLOOKUP($C12,Sheet1!$A$2:$E$10,5,0) -> Trolley | N12: =J12/K12 -> 1 | O12: GJ23Y8525 | P12: 910100578-25 Qty. / 910101143-15 Qty.
A13: G/I/25-26/01330 | B13: 05Z502400715AC5 | C13: 56110M58UA1 | D13: =VLOOKUP($C13,Sheet1!$A$2:$B$10,2,0) -> 116040-92240 | E13: ACTUATOR ASSY,NO VARIANT ESP | F13: 45996 | G13: 0.27083333 | H13: CA-01 | I13: AC5 | J13: 24 | K13: =VLOOKUP($C13,Sheet1!$A$2:$D$10,4,0) -> 6 | L13: =VLOOKUP($C13,Sheet1!$A$2:$E$10,5,0) -> Bin | M13: =J13/K13 -> 4 | O13: GJ23Y8525 | P13: 12505Q100031
A14: G/I/25-26/01330 | B14: 05Z502430088AC5 | C14: 56110M58UA1 | D14: =VLOOKUP($C14,Sheet1!$A$2:$B$10,2,0) -> 116040-92240 | E14: ACTUATOR ASSY,NO VARIANT ESP | F14: 45996 | G14: 0.27083333 | H14: CA-01 | I14: AC5 | J14: 12 | K14: =VLOOKUP($C14,Sheet1!$A$2:$D$10,4,0) -> 6 | L14: =VLOOKUP($C14,Sheet1!$A$2:$E$10,5,0) -> Bin | M14: =J14/K14 -> 2 | O14: GJ23Y8525 | P14: 12505Q100031
A15: G/I/25-26/01330 | B15: 05Z502400758AC5 | C15: 5A120M58U01 | D15: =VLOOKUP($C15,Sheet1!$A$2:$B$10,2,0) -> 114010-50820 | E15: CYLINDER ASSY,BK MASTER W/ECU | F15: 45996 | G15: 0.27083333 | H15: CA-01 | I15: AC5 | J15: 14 | K15: =VLOOKUP($C15,Sheet1!$A$2:$D$10,4,0) -> 1 | L15: =VLOOKUP($C15,Sheet1!$A$2:$E$10,5,0) -> Bin | M15: =J15/K15 -> 14 | O15: GJ23Y8525 | P15: 12504Q100266
A16: G/I/25-26/01330 | B16: 05Z502439905AC5 | C16: 5A120M58U01 | D16: =VLOOKUP($C16,Sheet1!$A$2:$B$10,2,0) -> 114010-50820 | E16: CYLINDER ASSY,BK MASTER W/ECU | F16: 45996 | G16: 0.27083333 | H16: CA-01 | I16: AC5 | J16: 1 | K16: =VLOOKUP($C16,Sheet1!$A$2:$D$10,4,0) -> 1 | L16: =VLOOKUP($C16,Sheet1!$A$2:$E$10,5,0) -> Bin | M16: =J16/K16 -> 1 | O16: GJ23Y8525 | P16: 12504Q100266
A17: G/I/25-26/01330 | B17: 05Z502400790AC5 | C17: 5A120M58U50 | D17: =VLOOKUP($C17,Sheet1!$A$2:$B$10,2,0) -> 114010-50830 | E17: CYLINDER ASSY,BK MASTER W/ECU | F17: 45996 | G17: 0.27083333 | H17: CA-01 | I17: AC5 | J17: 9 | K17: =VLOOKUP($C17,Sheet1!$A$2:$D$10,4,0) -> 1 | L17: =VLOOKUP($C17,Sheet1!$A$2:$E$10,5,0) -> Bin | M17: =J17/K17 -> 9 | O17: GJ23Y8525 | P17: 12504Q100256
A18: G/I/25-26/01330 | B18: 05Z502427664AC5 | C18: 5A120M58U50 | D18: =VLOOKUP($C18,Sheet1!$A$2:$B$10,2,0) -> 114010-50830 | E18: CYLINDER ASSY,BK MASTER W/ECU | F18: 45996 | G18: 0.27083333 | H18: CA-01 | I18: AC5 | J18: 11 | K18: =VLOOKUP($C18,Sheet1!$A$2:$D$10,4,0) -> 1 | L18: =VLOOKUP($C18,Sheet1!$A$2:$E$10,5,0) -> Bin | M18: =J18/K18 -> 11 | O18: GJ23Y8525 | P18: 12504Q100256
M19: 77 | N19: 4
A20: G/I/25-26/01331 | B20: 05Z502400499AC5 | C20: 55101M58U10 | D20: =VLOOKUP($C20,Sheet1!$A$2:$B$10,2,0) -> 141110-14600 | E20: CALIPER ASSY,FRONT BRAKE,R | F20: 45996 | G20: 0.47916667 | H20: CA-07 | I20: AC5 | J20: 36 | K20: =VLOOKUP($C20,Sheet1!$A$2:$D$10,4,0) -> 18 | L20: =VLOOKUP($C20,Sheet1!$A$2:$E$10,5,0) -> Trolley (H) | N20: 2 | O20: GJ01KT7585 | P20: Barode sticker
A21: G/I/25-26/01331 | B21: 05Z502400529AC5 | C21: 55102M58U10 | D21: =VLOOKUP($C21,Sheet1!$A$2:$B$10,2,0) -> 141120-14600 | E21: CALIPER ASSY,FRONT BRAKE,L | F21: 45996 | G21: 0.47916667 | H21: CA-07 | I21: AC5 | J21: 36 | K21: =VLOOKUP($C21,Sheet1!$A$2:$D$10,4,0) -> 18 | L21: =VLOOKUP($C21,Sheet1!$A$2:$E$10,5,0) -> Trolley (H) | O21: GJ01KT7585 | P21: Barode sticker
A22: G/I/25-26/01331 | B22: 05Z502400561AC5 | C22: 55311M58U00 | D22: =VLOOKUP($C22,Sheet1!$A$2:$B$10,2,0) -> 141185-74670 | E22: DISC,FRONT BRAKE | F22: 45996 | G22: 0.47916667 | H22: CA-07 | I22: AC5 | J22: 40 | K22: =VLOOKUP($C22,Sheet1!$A$2:$D$10,4,0) -> 40 | L22: =VLOOKUP($C22,Sheet1!$A$2:$E$10,5,0) -> Trolley | N22: =J22/K22 -> 1 | O22: GJ01KT7585 | P22: 910102786
A23: G/I/25-26/01331 | B23: 05Z502400600AC5 | C23: 55401M58U00 | D23: =VLOOKUP($C23,Sheet1!$A$2:$B$10,2,0) -> 141140-91211 | E23: CALIPER ASSY,REAR BRAKE,R | F23: 45996 | G23: 0.47916667 | H23: CA-21 | I23: AC5 | J23: 20 | K23: =VLOOKUP($C23,Sheet1!$A$2:$D$10,4,0) -> 2 | L23: =VLOOKUP($C23,Sheet1!$A$2:$E$10,5,0) -> Bin | M23: =J23/K23 -> 10 | O23: GJ01KT7585 | P23: 12509Q100239
