Workbook

Sheet Sheet1
A1: PART NUMBER | B1: Mat Code | C1: PART NAME | D1: Packing Standard | E1: Packed In
A2: 55101M58U10 | B2: 141110-14600 | C2: CALIPER RR | D2: 18 | E2: Trolley (H)
A3: 55102M58U10 | B3: 141120-14600 | C3: CALIPER LH | D3: 18 | E3: Trolley (H)
A4: 55311M58U00 | B4: 141185-74670 | C4: DISC FR | D4: 40 | E4: Trolley
A5: 55401M58U00 | B5: 141140-91211 | C5: MOC RH | D5: 2 | E5: Bin
A6: 55402M58U00 | B6: 141150-91211 | C6: MOC LH | D6: 2 | E6: Bin
A7: 55611M58U00 | B7: 141186-74360 | C7: DISC RR | D7: 40 | E7: Trolley
A8: 56110M58UA1 | B8: 116040-92240 | C8: ESC | D8: 6 | E8: Bin
A9: 5A120M58U50 | B9: 114010-50830 | C9: AHB LH | D9: 1 | E9: Bin
A10: 5A120M58U01 | B10: 114010-50820 | C10: AHB RH | D10: 1 | E10: Bin

Sheet 05-01-2026
J1: 24AACCN5739J1ZA
A2: Supply Month | B2: 46027 | L2: Vehicle No
A3: INVOICE NO | B3: KANBAN NO | C3: PART NUMBER | D3: Material Code | E3: PART NAME | F3: SUPPLY DATE | G3: SUPPLY TIME | H3: UNLOADING LOC | I3: Line | J3: Qty Req | K3: Packing Standerd | L3: Packed in | M3: TTL Bin | N3: TORLLY | O3: Vehicle No | P3: INV NO
A4: G/I/25-26/01524 | B4: 05N616094239AC5 | C4: 55101M58U10 | D4: =VLOOKUP($C4,Sheet1!$A$2:$D$10,2,0) -> 141110-14600 | E4: CALIPER ASSY,FRONT BRAKE,R | F4: 46027 | G4: 0.27083333 | H4: CA-07 | I4: AC5 | J4: 36 | K4: =VLOOKUP($C4,Sheet1!$A$2:$D$10,4,0) -> 18 | L4: =VLOOKUP($C4,Sheet1!$A$2:$E$10,5,0) -> Trolley (H) | N4: 2 | O4: HR47E8635 | P4: AN0250010835
A5: G/I/25-26/01524 | B5: 05N616094271AC5 | C5: 55102M58U10 | D5: =VLOOKUP($C5,Sheet1!$A$2:$D$10,2,0) -> 141120-14600 | E5: CALIPER ASSY,FRONT BRAKE,L | F5: 46027 | G5: 0.27083333 | H5: CA-07 | I5: AC5 | J5: 36 | K5: =VLOOKUP($C5,Sheet1!$A$2:$D$10,4,0) -> 18 | L5: =VLOOKUP($C5,Sheet1!$A$2:$E$10,5,0) -> Trolley (H) | O5: HR47E8635 | P5: AN0250010835
A6: G/I/25-26/01524 | B6: 05N616241630AC5 | C6: 55101M58U10 | D6: =VLOOKUP($C6,Sheet1!$A$2:$D$10,2,0) -> 141110-14600 | E6: CALIPER ASSY,FRONT BRAKE,R | F6: 46027 | G6: 0.27083333 | H6: CA-07 | I6: AC5 | J6: 18 | K6: =VLOOKUP($C6,Sheet1!$A$2:$D$10,4,0) -> 18 | L6: =VLOOKUP($C6,Sheet1!$A$2:$E$10,5,0) -> Trolley (H) | N6: 1 | O6: HR47E8635 | P6: AN0250010835
A7: G/I/25-26/01524 | B7: 05N616240650AC5 | C7: 55102M58U10 | D7: =VLOOKUP($C7,Sheet1!$A$2:$D$10,2,0) -> 141120-14600 | E7: CALIPER ASSY,FRONT BRAKE,L | F7: 46027 | G7: 0.27083333 | H7: CA-07 | I7: AC5 | J7: 18 | K7: =VLOOKUP($C7,Sheet1!$A$2:$D$10,4,0) -> 18 | L7: =VLOOKUP($C7,Sheet1!$A$2:$E$10,5,0) -> Trolley (H) | O7: HR47E8635 | P7: AN0250010835
A8: G/I/25-26/01524 | B8: 05N616094298AC5 | C8: 55311M58U00 | D8: =VLOOKUP($C8,Sheet1!$A$2:$D$10,2,0) -> 141185-74670 | E8: DISC,FRONT BRAKE | F8: 46027 | G8: 0.27083333 | H8: CA-07 | I8: AC5 | J8: 80 | K8: =VLOOKUP($C8,Sheet1!$A$2:$D$10,4,0) -> 40 | L8: =VLOOKUP($C8,Sheet1!$A$2:$E$10,5,0) -> Trolley | N8: =J8/K8 -> 2 | O8: HR47E8635 | P8: 910104284
A9: G/I/25-26/01524 | B9: 05N616094336AC5 | C9: 55401M58U00 | D9: =VLOOKUP($C9,Sheet1!$A$2:$D$10,2,0) -> 141140-91211 | E9: CALIPER ASSY,REAR BRAKE,R | F9: 46027 | G9: 0.27083333 | H9: CA-21 | I9: AC5 | J9: 30 | K9: =VLOOKUP($C9,Sheet1!$A$2:$D$10,4,0) -> 2 | L9: =VLOOKUP($C9,Sheet1!$A$2:$E$10,5,0) -> Bin | M9: =J9/K9 -> 15 | O9: HR47E8635 | P9: 12505Q100043
A10: G/I/25-26/01524 | B10: 05N616212525AC5 | C10: 55401M58U00 | D10: =VLOOKUP($C10,Sheet1!$A$2:$D$10,2,0) -> 141140-91211 | E10: CALIPER ASSY,REAR BRAKE,R | F10: 46027 | G10: 0.27083333 | H10: CA-21 | I10: AC5 | J10: 14 | K10: =VLOOKUP($C10,Sheet1!$A$2:$D$10,4,0) -> 2 | L10: =VLOOKUP($C10,Sheet1!$A$2:$E$10,5,0) -> Bin | M10: =J10/K10 -> 7 | O10: HR47E8635 | P10: 12505Q100064
A11: G/I/25-26/01524 | B11: 05N616246195AC5 | C11: 55401M58U00 | D11: =VLOOKUP($C11,Sheet1!$A$2:$D$10,2,0) -> 141140-91211 | E11: CALIPER ASSY,REAR BRAKE,R | F11: 46027 | G11: 0.27083333 | H11: CA-21 | I11: AC5 | J11: 4 | K11: =VLOOKUP($C11,Sheet1!$A$2:$D$10,4,0) -> 2 | L11: =VLOOKUP($C11,Sheet1!$A$2:$E$10,5,0) -> Bin | M11: =J11/K11 -> 2 | O11: HR47E8635 | P11: 12505Q100043
A12: G/I/25-26/01524 | B12: 05N616094379AC5 | C12: 55402M58U00 | D12: =VLOOKUP($C12,Sheet1!$A$2:$D$10,2,0) -> 141150-91211 | E12: CALIPER ASSY,REAR BRAKE,L | F12: 46027 | G12: 0.27083333 | H12: CA-21 | I12: AC5 | J12: 30 | K12: =VLOOKUP($C12,Sheet1!$A$2:$D$10,4,0) -> 2 | L12: =VLOOKUP($C12,Sheet1!$A$2:$E$10,5,0) -> Bin | M12: =J12/K12 -> 15 | O12: HR47E8635 | P12: 12505Q100043
A13: G/I/25-26/01524 | B13: 05N616212274AC5 | C13: 55402M58U00 | D13: =VLOOKUP($C13,Sheet1!$A$2:$D$10,2,0) -> 141150-91211 | E13: CALIPER ASSY,REAR BRAKE,L | F13: 46027 | G13: 0.27083333 | H13: CA-21 | I13: AC5 | J13: 14 | K13: =VLOOKUP($C13,Sheet1!$A$2:$D$10,4,0) -> 2 | L13: =VLOOKUP($C13,Sheet1!$A$2:$E$10,5,0) -> Bin | M13: =J13/K13 -> 7 | O13: HR47E8635 | P13: 12505Q100043
A14: G/I/25-26/01524 | B14: 05N616242297AC5 | C14: 55402M58U00 | D14: =VLOOKUP($C14,Sheet1!$A$2:$D$10,2,0) -> 141150-91211 | E14: CALIPER ASSY,REAR BRAKE,L | F14: 46027 | G14: 0.27083333 | H14: CA-21 | I14: AC5 | J14: 4 | K14: =VLOOKUP($C14,Sheet1!$A$2:$D$10,4,0) -> 2 | L14: =VLOOKUP($C14,Sheet1!$A$2:$E$10,5,0) -> Bin | M14: =J14/K14 -> 2 | O14: HR47E8635 | P14: 12505Q100043
A15: G/I/25-26/01524 | B15: 05N616094417AC5 | C15: 55611M58U00 | D15: =VLOOKUP($C15,Sheet1!$A$2:$D$10,2,0) -> 141186-74360 | E15: DISC,REAR BRAKE | F15: 46027 | G15: 0.27083333 | H15: CA-21 | I15: AC5 | J15: 80 | K15: =VLOOKUP($C15,Sheet1!$A$2:$D$10,4,0) -> 40 | L15: =VLOOKUP($C15,Sheet1!$A$2:$E$10,5,0) -> Trolley | N15: =J15/K15 -> 2 | O15: HR47E8635 | P15: 910104269
A16: G/I/25-26/01524 | B16: 05N616218345AC5 | C16: 55611M58U00 | D16: =VLOOKUP($C16,Sheet1!$A$2:$D$10,2,0) -> 141186-74360 | E16: DISC,REAR BRAKE | F16: 46027 | G16: 0.27083333 | H16: CA-21 | I16: AC5 | J16: 40 | K16: =VLOOKUP($C16,Sheet1!$A$2:$D$10,4,0) -> 40 | L16: =VLOOKUP($C16,Sheet1!$A$2:$E$10,5,0) -> Trolley | N16: =J16/K16 -> 1 | O16: HR47E8635 | P16: 910104269
A17: G/I/25-26/01525 | B17: 05N616094441AC5 | C17: 56110M58UA1 | D17: =VLOOKUP($C17,Sheet1!$A$2:$D$10,2,0) -> 116040-92240 | E17: ACTUATOR ASSY,NO VARIANT ESP | F17: 46027 | G17: 0.27083333 | H17: CA-01 | I17: AC5 | J17: 30 | K17: =VLOOKUP($C17,Sheet1!$A$2:$D$10,4,0) -> 6 | L17: =VLOOKUP($C17,Sheet1!$A$2:$E$10,5,0) -> Bin | M17: =J17/K17 -> 5 | O17: HR47E8635 | P17: 12505Q100152
A18: G/I/25-26/01525 | B18: 05N616220617AC5 | C18: 56110M58UA1 | D18: =VLOOKUP($C18,Sheet1!$A$2:$D$10,2,0) -> 116040-92240 | E18: ACTUATOR ASSY,NO VARIANT ESP | F18: 46027 | G18: 0.27083333 | H18: CA-01 | I18: AC5 | J18: 12 | K18: =VLOOKUP($C18,Sheet1!$A$2:$D$10,4,0) -> 6 | L18: =VLOOKUP($C18,Sheet1!$A$2:$E$10,5,0) -> Bin | M18: =J18/K18 -> 2 | O18: HR47E8635 | P18: 12505Q100152
A19: G/I/25-26/01525 | B19: 05N616241720AC5 | C19: 56110M58UA1 | D19: =VLOOKUP($C19,Sheet1!$A$2:$D$10,2,0) -> 116040-92240 | E19: ACTUATOR ASSY,NO VARIANT ESP | F19: 46027 | G19: 0.27083333 | H19: CA-01 | I19: AC5 | J19: 6 | K19: =VLOOKUP($C19,Sheet1!$A$2:$D$10,4,0) -> 6 | L19: =VLOOKUP($C19,Sheet1!$A$2:$E$10,5,0) -> Bin | M19: =J19/K19 -> 1 | O19: HR47E8635 | P19: 12505Q100152
A20: G/I/25-26/01525 | B20: 05N616094484AC5 | C20: 5A120M58U01 | D20: =VLOOKUP($C20,Sheet1!$A$2:$D$10,2,0) -> 114010-50820 | E20: CYLINDER ASSY,BK MASTER W/ECU | F20: 46027 | G20: 0.27083333 | H20: CA-01 | I20: AC5 | J20: 12 | K20: =VLOOKUP($C20,Sheet1!$A$2:$D$10,4,0) -> 1 | L20: =VLOOKUP($C20,Sheet1!$A$2:$E$10,5,0) -> Bin | M20: =J20/K20 -> 12 | O20: HR47E8635 | P20: 12505Q100051
A21: G/I/25-26/01525 | B21: 05N616215184AC5 | C21: 5A120M58U01 | D21: =VLOOKUP($C21,Sheet1!$A$2:$D$10,2,0) -> 114010-50820 | E21: CYLINDER ASSY,BK MASTER W/ECU | F21: 46027 | G21: 0.27083333 | H21: CA-01 | I21: AC5 | J21: 10 | K21: =VLOOKUP($C21,Sheet1!$A$2:$D$10,4,0) -> 1 | L21: =VLOOKUP($C21,Sheet1!$A$2:$E$10,5,0) -> Bin | M21: =J21/K21 -> 10 | O21: HR47E8635 | P21: 12505Q100051
A22: G/I/25-26/01525 | B22: 05N616247094AC5 | C22: 5A120M58U01 | D22: =VLOOKUP($C22,Sheet1!$A$2:$D$10,2,0) -> 114010-50820 | E22: CYLINDER ASSY,BK MASTER W/ECU | F22: 46027 | G22: 0.27083333 | H22: CA-01 | I22: AC5 | J22: 1 | K22: =VLOOKUP($C22,Sheet1!$A$2:$D$10,4,0) -> 1 | L22: =VLOOKUP($C22,Sheet1!$A$2:$E$10,5,0) -> Bin | M22: =J22/K22 -> 1 | O22: HR47E8635 | P22: 12505Q100051
A23: G/I/25-26/01525 | B23: 05N616094530AC5 | C23: 5A120M58U50 | D23: =VLOOKUP($C23,Sheet1!$A$2:$D$10,2,0) -> 114010-50830 | E23: CYLINDER ASSY,BK MASTER W/ECU | F23: 46027 | G23: 0.27083333 | H23: CA-01 | I23: AC5 | J23: 19 | K23: =VLOOKUP($C23,Sheet1!$A$2:$D$10,4,0) -> 1 | L23: =VLOOKUP($C23,Sheet1!$A$2:$E$10,5,0) -> Bin | M23: =J23/K23 -> 19 | O23: HR47E8635 | P23: 12505Q100043
A24: G/I/25-26/01525 | B24: 05N616229231AC5 | C24: 5A120M58U50 | D24: =VLOOKUP($C24,Sheet1!$A$2:$D$10,2,0) -> 114010-50830 | E24: CYLINDER ASSY,BK MASTER W/ECU | F24: 46027 | G24: 0.27083333 | H24: CA-01 | I24: AC5 | J24: 4 | K24: =VLOOKUP($C24,Sheet1!$A$2:$D$10,4,0) -> 1 | L24: =VLOOKUP($C24,Sheet1!$A$2:$E$10,5,0) -> Bin | M24: =J24/K24 -> 4 | O24: HR47E8635 | P24: 12505Q100043
A25: G/I/25-26/01525 | B25: 05N616246390AC5 | C25: 5A120M58U50 | D25: =VLOOKUP($C25,Sheet1!$A$2:$D$10,2,0) -> 114010-50830 | E25: CYLINDER ASSY,BK MASTER W/ECU | F25: 46027 | G25: 0.27083333 | H25: CA-01 | I25: AC5 | J25: 3 | K25: =VLOOKUP($C25,Sheet1!$A$2:$D$10,4,0) -> 1 | L25: =VLOOKUP($C25,Sheet1!$A$2:$E$10,5,0) -> Bin | M25: =J25/K25 -> 3 | O25: HR47E8635 | P25: 12505Q100043
M26: 105 | N26: 8
A27: G/I/25-26/01526 | B27: 05N616094220AC5 | C27: 55101M58U10 | D27: =VLOOKUP($C27,Sheet1!$A$2:$D$10,2,0) -> 141110-14600 | E27: CALIPER ASSY,FRONT BRAKE,R | F27: 46027 | G27: 0.47916667 | H27: CA-07 | I27: AC5 | J27: 18 | K27: =VLOOKUP($C27,Sheet1!$A$2:$D$10,4,0) -> 18 | L27: =VLOOKUP($C27,Sheet1!$A$2:$E$10,5,0) -> Trolley (H) | N27: 1 | O27: HR47G9416 | P27: AN0250010835
A28: G/I/25-26/01526 | B28: 05N616094263AC5 | C28: 55102M58U10 | D28: =VLOOKUP($C28,Sheet1!$A$2:$D$10,2,0) -> 141120-14600 | E28: CALIPER ASSY,FRONT BRAKE,L | F28: 46027 | G28: 0.47916667 | H28: CA-07 | I28: AC5 | J28: 18 | K28: =VLOOKUP($C28,Sheet1!$A$2:$D$10,4,0) -> 18 | L28: =VLOOKUP($C28,Sheet1!$A$2:$E$10,5,0) -> Trolley (H) | O28: HR47G9416 | P28: AN0250010835
A29: G/I/25-26/01526 | B29: 05N616094301AC5 | C29: 55311M58U00 | D29: =VLOOKUP($C29,Sheet1!$A$2:$D$10,2,0) -> 141185-74670 | E29: DISC,FRONT BRAKE | F29: 46027 | G29: 0.47916667 | H29: CA-07 | I29: AC5 | J29: 40 | K29: =VLOOKUP($C29,Sheet1!$A$2:$D$10,4,0) -> 40 | L29: =VLOOKUP($C29,Sheet1!$A$2:$E$10,5,0) -> Trolley | N29: =J29/K29 -> 1 | O29: HR47G9416 | P29: 910104284
A30: G/I/25-26/01526 | B30: 05N616094344AC5 | C30: 55401M58U00 | D30: =VLOOKUP($C30,Sheet1!$A$2:$D$10,2,0) -> 141140-91211 | E30: CALIPER ASSY,REAR BRAKE,R | F30: 46027 | G30: 0.47916667 | H30: CA-21 | I30: AC5 | J30: 26 | K30: =VLOOKUP($C30,Sheet1!$A$2:$D$10,4,0) -> 2 | L30: =VLOOKUP($C30,Sheet1!$A$2:$E$10,5,0) -> Bin | M30: =J30/K30 -> 13 | O30: HR47G9416 | P30: 12505Q100043
A31: G/I/25-26/01526 | B31: 05N616094387AC5 | C31: 55402M58U00 | D31: =VLOOKUP($C31,Sheet1!$A$2:$D$10,2,0) -> 141150-91211 | E31: CALIPER ASSY,REAR BRAKE,L | F31: 46027 | G31: 0.47916667 | H31: CA-21 | I31: AC5 | J31: 24 | K31: =VLOOKUP($C31,Sheet1!$A$2:$D$10,4,0) -> 2 | L31: =VLOOKUP($C31,Sheet1!$A$2:$E$10,5,0) -> Bin | M31: =J31/K31 -> 12 | O31: HR47G9416 | P31: 12505Q100043
A32: G/I/25-26/01526 | B32: 05N616094425AC5 | C32: 55611M58U00 | D32: =VLOOKUP($C32,Sheet1!$A$2:$D$10,2,0) -> 141186-74360 | E32: DISC,REAR BRAKE | F32: 46027 | G32: 0.47916667 | H32: CA-21 | I32: AC5 | J32: 40 | K32: =VLOOKUP($C32,Sheet1!$A$2:$D$10,4,0) -> 40 | L32: =VLOOKUP($C32,Sheet1!$A$2:$E$10,5,0) -> Trolley | N32: =J32/K32 -> 1 | O32: HR47G9416 | P32: 910104269
A33: G/I/25-26/01527 | B33: 05N616094450AC5 | C33: 56110M58UA1 | D33: =VLOOKUP($C33,Sheet1!$A$2:$D$10,2,0) -> 116040-92240 | E33: ACTUATOR ASSY,NO VARIANT ESP | F33: 46027 | G33: 0.47916667 | H33: CA-01 | I33: AC5 | J33: 24 | K33: =VLOOKUP($C33,Sheet1!$A$2:$D$10,4,0) -> 6 | L33: =VLOOKUP($C33,Sheet1!$A$2:$E$10,5,0) -> Bin | M33: =J33/K33 -> 4 | O33: HR47G9416 | P33: 12505Q100152
A34: G/I/25-26/01527 | B34: 05N616094492AC5 | C34: 5A120M58U01 | D34: =VLOOKUP($C34,Sheet1!$A$2:$D$10,2,0) -> 114010-50820 | E34: CYLINDER ASSY,BK MASTER W/ECU | F34: 46027 | G34: 0.47916667 | H34: CA-01 | I34: AC5 | J34: 6 | K34: =VLOOKUP($C34,Sheet1!$A$2:$D$10,4,0) -> 1 | L34: =VLOOKUP($C34,Sheet1!$A$2:$E$10,5,0) -> Bin | M34: =J34/K34 -> 6 | O34: HR47G9416 | P34: 12505Q100051
A35: G/I/25-26/01527 | B35: 05N616094522AC5 | C35: 5A120M58U50 | D35: =VLOOKUP($C35,Sheet1!$A$2:$D$10,2,0) -> 114010-50830 | E35: CYLINDER ASSY,BK MASTER W/ECU | F35: 46027 | G35: 0.47916667 | H35: CA-01 | I35: AC5 | J35: 18 | K35: =VLOOKUP($C35,Sheet1!$A$2:$D$10,4,0) -> 1 | L35: =VLOOKUP($C35,Sheet1!$A$2:$E$10,5,0) -> Bin | M35: =J35/K35 -> 18 | O35: HR47G9416 | P35: 12505Q100043
M36: 53 | N36: 3
A37: G/I/25-26/01528 | B37: 05N616094247AC5 | C37: 55101M58U10 | D37: =VLOOKUP($C37,Sheet1!$A$2:$D$10,2,0) -> 141110-14600 | E37: CALIPER ASSY,FRONT BRAKE,R | F37: 46027 | G37: 0.60416667 | H37: CA-07 | I37: AC5 | J37: 18 | K37: =VLOOKUP($C37,Sheet1!$A$2:$D$10,4,0) -> 18 | L37: =VLOOKUP($C37,Sheet1!$A$2:$E$10,5,0) -> Trolley (H) | N37: 1 | O37: HR47H5465 | P37: AN0250010835
A38: G/I/25-26/01528 | B38: 05N616094280AC5 | C38: 55102M58U10 | D38: =VLOOKUP($C38,Sheet1!$A$2:$D$10,2,0) -> 141120-14600 | E38: CALIPER ASSY,FRONT BRAKE,L | F38: 46027 | G38: 0.60416667 | H38: CA-07 | I38: AC5 | J38: 18 | K38: =VLOOKUP($C38,Sheet1!$A$2:$D$10,4,0) -> 18 | L38: =VLOOKUP($C38,Sheet1!$A$2:$E$10,5,0) -> Trolley (H) | O38: HR47H5465 | P38: AN0250010835
A39: G/I/25-26/01528 | B39: 05N616094310AC5 | C39: 55311M58U00 | D39: =VLOOKUP($C39,Sheet1!$A$2:$D$10,2,0) -> 141185-74670 | E39: DISC,FRONT BRAKE | F39: 46027 | G39: 0.60416667 | H39: CA-07 | I39: AC5 | J39: 40 | K39: =VLOOKUP($C39,Sheet1!$A$2:$D$10,4,0) -> 40 | L39: =VLOOKUP($C39,Sheet1!$A$2:$E$10,5,0) -> Trolley | N39: =J39/K39 -> 1 | O39: HR47H5465 | P39: 910104284
A40: G/I/25-26/01528 | B40: 05N616094352AC5 | C40: 55401M58U00 | D40: =VLOOKUP($C40,Sheet1!$A$2:$D$10,2,0) -> 141140-91211 | E40: CALIPER ASSY,REAR BRAKE,R | F40: 46027 | G40: 0.60416667 | H40: CA-21 | I40: AC5 | J40: 20 | K40: =VLOOKUP($C40,Sheet1!$A$2:$D$10,4,0) -> 2 | L40: =VLOOKUP($C40,Sheet1!$A$2:$E$10,5,0) -> Bin | M40: =J40/K40 -> 10 | O40: HR47H5465 | P40: 12505Q100043
...

Sheet 06-01-2026
J1: 24AACCN5739J1ZA
A2: Supply Month | B2: 46028 | L2: Vehicle No
A3: INVOICE NO | B3: KANBAN NO | C3: PART NUMBER | D3: Material Code | E3: PART NAME | F3: SUPPLY DATE | G3: SUPPLY TIME | H3: UNLOADING LOC | I3: Line | J3: Qty Req | K3: Packing Standerd | L3: Packed in | M3: TTL Bin | N3: TORLLY | O3: Vehicle No | P3: INV NO
A4: G/I/25-26/01532 | B4: 06N617269768AC5 | C4: 55101M58U10 | D4: =VLOOKUP($C4,Sheet1!$A$2:$D$10,2,0) -> 141110-14600 | E4: CALIPER ASSY,FRONT BRAKE,R | F4: 46028 | G4: 0.35416667 | H4: CA-07 | I4: AC5 | J4: 54 | K4: =VLOOKUP($C4,Sheet1!$A$2:$D$10,4,0) -> 18 | L4: =VLOOKUP($C4,Sheet1!$A$2:$E$10,5,0) -> Trolley (H) | N4: 3 | O4: HR47E7907 | P4: AN0250010835
A5: G/I/25-26/01532 | B5: 06N617269806AC5 | C5: 55102M58U10 | D5: =VLOOKUP($C5,Sheet1!$A$2:$D$10,2,0) -> 141120-14600 | E5: CALIPER ASSY,FRONT BRAKE,L | F5: 46028 | G5: 0.35416667 | H5: CA-07 | I5: AC5 | J5: 54 | K5: =VLOOKUP($C5,Sheet1!$A$2:$D$10,4,0) -> 18 | L5: =VLOOKUP($C5,Sheet1!$A$2:$E$10,5,0) -> Trolley (H) | O5: HR47E7907 | P5: AN0250010835
A6: G/I/25-26/01532 | B6: 06N617269849AC5 | C6: 55311M58U00 | D6: =VLOOKUP($C6,Sheet1!$A$2:$D$10,2,0) -> 141185-74670 | E6: DISC,FRONT BRAKE | F6: 46028 | G6: 0.35416667 | H6: CA-07 | I6: AC5 | J6: 80 | K6: =VLOOKUP($C6,Sheet1!$A$2:$D$10,4,0) -> 40 | L6: =VLOOKUP($C6,Sheet1!$A$2:$E$10,5,0) -> Trolley | N6: =J6/K6 -> 2 | O6: HR47E7907 | P6: 910104284
A7: G/I/25-26/01532 | B7: 06N617269881AC5 | C7: 55401M58U00 | D7: =VLOOKUP($C7,Sheet1!$A$2:$D$10,2,0) -> 141140-91211 | E7: CALIPER ASSY,REAR BRAKE,R | F7: 46028 | G7: 0.35416667 | H7: CA-21 | I7: AC5 | J7: 56 | K7: =VLOOKUP($C7,Sheet1!$A$2:$D$10,4,0) -> 2 | L7: =VLOOKUP($C7,Sheet1!$A$2:$E$10,5,0) -> Bin | M7: =J7/K7 -> 28 | O7: HR47E7907 | P7: 12505Q100043
A8: G/I/25-26/01532 | B8: 06N617397030AC5 | C8: 55401M58U00 | D8: =VLOOKUP($C8,Sheet1!$A$2:$D$10,2,0) -> 141140-91211 | E8: CALIPER ASSY,REAR BRAKE,R | F8: 46028 | G8: 0.35416667 | H8: CA-21 | I8: AC5 | J8: 6 | K8: =VLOOKUP($C8,Sheet1!$A$2:$D$10,4,0) -> 2 | L8: =VLOOKUP($C8,Sheet1!$A$2:$E$10,5,0) -> Bin | M8: =J8/K8 -> 3 | O8: HR47E7907 | P8: 12505Q100043
A9: G/I/25-26/01532 | B9: 06N617269920AC5 | C9: 55402M58U00 | D9: =VLOOKUP($C9,Sheet1!$A$2:$D$10,2,0) -> 141150-91211 | E9: CALIPER ASSY,REAR BRAKE,L | F9: 46028 | G9: 0.35416667 | H9: CA-21 | I9: AC5 | J9: 56 | K9: =VLOOKUP($C9,Sheet1!$A$2:$D$10,4,0) -> 2 | L9: =VLOOKUP($C9,Sheet1!$A$2:$E$10,5,0) -> Bin | M9: =J9/K9 -> 28 | O9: HR47E7907 | P9: 12505Q100043
A10: G/I/25-26/01532 | B10: 06N617400333AC5 | C10: 55402M58U00 | D10: =VLOOKUP($C10,Sheet1!$A$2:$D$10,2,0) -> 141150-91211 | E10: CALIPER ASSY,REAR BRAKE,L | F10: 46028 | G10: 0.35416667 | H10: CA-21 | I10: AC5 | J10: 6 | K10: =VLOOKUP($C10,Sheet1!$A$2:$D$10,4,0) -> 2 | L10: =VLOOKUP($C10,Sheet1!$A$2:$E$10,5,0) -> Bin | M10: =J10/K10 -> 3 | O10: HR47E7907 | P10: 12505Q100043
A11: G/I/25-26/01532 | B11: 06N617269962AC5 | C11: 55611M58U00 | D11: =VLOOKUP($C11,Sheet1!$A$2:$D$10,2,0) -> 141186-74360 | E11: DISC,REAR BRAKE | F11: 46028 | G11: 0.35416667 | H11: CA-21 | I11: AC5 | J11: 80 | K11: =VLOOKUP($C11,Sheet1!$A$2:$D$10,4,0) -> 40 | L11: =VLOOKUP($C11,Sheet1!$A$2:$E$10,5,0) -> Trolley | N11: =J11/K11 -> 2 | O11: HR47E7907 | P11: 910104269
A12: G/I/25-26/01533 | B12: 06N617270006AC5 | C12: 56110M58UA1 | D12: =VLOOKUP($C12,Sheet1!$A$2:$D$10,2,0) -> 116040-92240 | E12: ACTUATOR ASSY,NO VARIANT ESP | F12: 46028 | G12: 0.35416667 | H12: CA-01 | I12: AC5 | J12: 54 | K12: =VLOOKUP($C12,Sheet1!$A$2:$D$10,4,0) -> 6 | L12: =VLOOKUP($C12,Sheet1!$A$2:$E$10,5,0) -> Bin | M12: =J12/K12 -> 9 | O12: HR47E7907 | P12: 12505Q100152
A13: G/I/25-26/01533 | B13: 06N617401143AC5 | C13: 56110M58UA1 | D13: =VLOOKUP($C13,Sheet1!$A$2:$D$10,2,0) -> 116040-92240 | E13: ACTUATOR ASSY,NO VARIANT ESP | F13: 46028 | G13: 0.35416667 | H13: CA-01 | I13: AC5 | J13: 6 | K13: =VLOOKUP($C13,Sheet1!$A$2:$D$10,4,0) -> 6 | L13: =VLOOKUP($C13,Sheet1!$A$2:$E$10,5,0) -> Bin | M13: =J13/K13 -> 1 | O13: HR47E7907 | P13: 12505Q100152
A14: G/I/25-26/01533 | B14: 06N617270049AC5 | C14: 5A120M58U01 | D14: =VLOOKUP($C14,Sheet1!$A$2:$D$10,2,0) -> 114010-50820 | E14: CYLINDER ASSY,BK MASTER W/ECU | F14: 46028 | G14: 0.35416667 | H14: CA-01 | I14: AC5 | J14: 29 | K14: =VLOOKUP($C14,Sheet1!$A$2:$D$10,4,0) -> 1 | L14: =VLOOKUP($C14,Sheet1!$A$2:$E$10,5,0) -> Bin | M14: =J14/K14 -> 29 | O14: HR47E7907 | P14: 12505Q100051
A15: G/I/25-26/01533 | B15: 06N617398320AC5 | C15: 5A120M58U01 | D15: =VLOOKUP($C15,Sheet1!$A$2:$D$10,2,0) -> 114010-50820 | E15: CYLINDER ASSY,BK MASTER W/ECU | F15: 46028 | G15: 0.35416667 | H15: CA-01 | I15: AC5 | J15: 4 | K15: =VLOOKUP($C15,Sheet1!$A$2:$D$10,4,0) -> 1 | L15: =VLOOKUP($C15,Sheet1!$A$2:$E$10,5,0) -> Bin | M15: =J15/K15 -> 4 | O15: HR47E7907 | P15: 12505Q100051
A16: G/I/25-26/01533 | B16: 06N617270073AC5 | C16: 5A120M58U50 | D16: =VLOOKUP($C16,Sheet1!$A$2:$D$10,2,0) -> 114010-50830 | E16: CYLINDER ASSY,BK MASTER W/ECU | F16: 46028 | G16: 0.35416667 | H16: CA-01 | I16: AC5 | J16: 31 | K16: =VLOOKUP($C16,Sheet1!$A$2:$D$10,4,0) -> 1 | L16: =VLOOKUP($C16,Sheet1!$A$2:$E$10,5,0) -> Bin | M16: =J16/K16 -> 31 | O16: HR47E7907 | P16: 12505Q100043
A17: G/I/25-26/01533 | B17: 06N617401496AC5 | C17: 5A120M58U50 | D17: =VLOOKUP($C17,Sheet1!$A$2:$D$10,2,0) -> 114010-50830 | E17: CYLINDER ASSY,BK MASTER W/ECU | F17: 46028 | G17: 0.35416667 | H17: CA-01 | I17: AC5 | J17: 1 | K17: =VLOOKUP($C17,Sheet1!$A$2:$D$10,4,0) -> 1 | L17: =VLOOKUP($C17,Sheet1!$A$2:$E$10,5,0) -> Bin | M17: =J17/K17 -> 1 | O17: HR47E7907 | P17: 12505Q100043
M18: 137 | N18: 7
A19: G/I/25-26/01534 | B19: 06N617269849AC5 | C19: 55311M58U00 | D19: =VLOOKUP($C19,Sheet1!$A$2:$D$10,2,0) -> 141185-74670 | E19: DISC,FRONT BRAKE | F19: 46028 | G19: 0.35416667 | H19: CA-07 | I19: AC5 | J19: 40 | K19: =VLOOKUP($C19,Sheet1!$A$2:$D$10,4,0) -> 40 | L19: =VLOOKUP($C19,Sheet1!$A$2:$E$10,5,0) -> Trolley | N19: =J19/K19 -> 1 | O19: HR47E8635 | P19: 910104284
A20: G/I/25-26/01534 | B20: 06N617269962AC5 | C20: 55611M58U00 | D20: =VLOOKUP($C20,Sheet1!$A$2:$D$10,2,0) -> 141186-74360 | E20: DISC,REAR BRAKE | F20: 46028 | G20: 0.35416667 | H20: CA-21 | I20: AC5 | J20: 40 | K20: =VLOOKUP($C20,Sheet1!$A$2:$D$10,4,0) -> 40 | L20: =VLOOKUP($C20,Sheet1!$A$2:$E$10,5,0) -> Trolley | N20: =J20/K20 -> 1 | O20: HR47E8635 | P20: 910104269
A21: G/I/25-26/01543 | B21: AR451719207AC5 | C21: 55101M58U10 | D21: =VLOOKUP($C21,Sheet1!$A$2:$D$10,2,0) -> 141110-14600 | E21: CALIPER ASSY,FRONT BRAKE,R | F21: 46028 | G21: DI | H21: CA-07 | J21: 5 | K21: =VLOOKUP($C21,Sheet1!$A$2:$D$10,4,0) -> 18 | L21: =VLOOKUP($C21,Sheet1!$A$2:$E$10,5,0) -> Trolley (H) | N21: 1 | O21: HR47E8635 | P21: AN0250010383 | Q21: SMG DI
A22: G/I/25-26/01543 | B22: AR451719346AC5 | C22: 55102M58U10 | D22: =VLOOKUP($C22,Sheet1!$A$2:$D$10,2,0) -> 141120-14600 | E22: CALIPER ASSY,FRONT BRAKE,L | F22: 46028 | G22: DI | H22: CA-07 | J22: 5 | K22: =VLOOKUP($C22,Sheet1!$A$2:$D$10,4,0) -> 18 | L22: =VLOOKUP($C22,Sheet1!$A$2:$E$10,5,0) -> Trolley (H) | O22: HR47E8635 | P22: AN0250010383 | Q22: SMG DI
M23: 1
A24: G/I/25-26/01535 | B24: 06N617269776AC5 | C24: 55101M58U10 | D24: =VLOOKUP($C24,Sheet1!$A$2:$D$10,2,0) -> 141110-14600 | E24: CALIPER ASSY,FRONT BRAKE,R | F24: 46028 | G24: 0.5625 | H24: CA-07 | I24: AC5 | J24: 36 | K24: =VLOOKUP($C24,Sheet1!$A$2:$D$10,4,0) -> 18 | L24: =VLOOKUP($C24,Sheet1!$A$2:$E$10,5,0) -> Trolley (H) | N24: 2 | O24: HR47E8635 | P24: AN0250010835
A25: G/I/25-26/01535 | B25: 06N617269814AC5 | C25: 55102M58U10 | D25: =VLOOKUP($C25,Sheet1!$A$2:$D$10,2,0) -> 141120-14600 | E25: CALIPER ASSY,FRONT BRAKE,L | F25: 46028 | G25: 0.5625 | H25: CA-07 | I25: AC5 | J25: 36 | K25: =VLOOKUP($C25,Sheet1!$A$2:$D$10,4,0) -> 18 | L25: =VLOOKUP($C25,Sheet1!$A$2:$E$10,5,0) -> Trolley (H) | O25: HR47E8635 | P25: AN0250010835
A26: G/I/25-26/01535 | B26: 06N617269857AC5 | C26: 55311M58U00 | D26: =VLOOKUP($C26,Sheet1!$A$2:$D$10,2,0) -> 141185-74670 | E26: DISC,FRONT BRAKE | F26: 46028 | G26: 0.5625 | H26: CA-07 | I26: AC5 | J26: 80 | K26: =VLOOKUP($C26,Sheet1!$A$2:$D$10,4,0) -> 40 | L26: =VLOOKUP($C26,Sheet1!$A$2:$E$10,5,0) -> Trolley | N26: =J26/K26 -> 2 | O26: HR47E8635 | P26: 910104284
A27: G/I/25-26/01535 | B27: 06N617269890AC5 | C27: 55401M58U00 | D27: =VLOOKUP($C27,Sheet1!$A$2:$D$10,2,0) -> 141140-91211 | E27: CALIPER ASSY,REAR BRAKE,R | F27: 46028 | G27: 0.5625 | H27: CA-21 | I27: AC5 | J27: 38 | K27: =VLOOKUP($C27,Sheet1!$A$2:$D$10,4,0) -> 2 | L27: =VLOOKUP($C27,Sheet1!$A$2:$E$10,5,0) -> Bin | M27: =J27/K27 -> 19 | O27: HR47E8635 | P27: 12505Q100043
A28: G/I/25-26/01535 | B28: 06N617269938AC5 | C28: 55402M58U00 | D28: =VLOOKUP($C28,Sheet1!$A$2:$D$10,2,0) -> 141150-91211 | E28: CALIPER ASSY,REAR BRAKE,L | F28: 46028 | G28: 0.5625 | H28: CA-21 | I28: AC5 | J28: 38 | K28: =VLOOKUP($C28,Sheet1!$A$2:$D$10,4,0) -> 2 | L28: =VLOOKUP($C28,Sheet1!$A$2:$E$10,5,0) -> Bin | M28: =J28/K28 -> 19 | O28: HR47E8635 | P28: 12505Q100043
A29: G/I/25-26/01535 | B29: 06N617269970AC5 | C29: 55611M58U00 | D29: =VLOOKUP($C29,Sheet1!$A$2:$D$10,2,0) -> 141186-74360 | E29: DISC,REAR BRAKE | F29: 46028 | G29: 0.5625 | H29: CA-21 | I29: AC5 | J29: 80 | K29: =VLOOKUP($C29,Sheet1!$A$2:$D$10,4,0) -> 40 | L29: =VLOOKUP($C29,Sheet1!$A$2:$E$10,5,0) -> Trolley | N29: =J29/K29 -> 2 | O29: HR47E8635 | P29: 910104269-39 Qty / 910104658-41 Qty.
A30: G/I/25-26/01536 | B30: 06N617270014AC5 | C30: 56110M58UA1 | D30: =VLOOKUP($C30,Sheet1!$A$2:$D$10,2,0) -> 116040-92240 | E30: ACTUATOR ASSY,NO VARIANT ESP | F30: 46028 | G30: 0.5625 | H30: CA-01 | I30: AC5 | J30: 36 | K30: =VLOOKUP($C30,Sheet1!$A$2:$D$10,4,0) -> 6 | L30: =VLOOKUP($C30,Sheet1!$A$2:$E$10,5,0) -> Bin | M30: =J30/K30 -> 6 | O30: HR47E8635 | P30: 12505Q100152
A31: G/I/25-26/01536 | B31: 06N617270057AC5 | C31: 5A120M58U01 | D31: =VLOOKUP($C31,Sheet1!$A$2:$D$10,2,0) -> 114010-50820 | E31: CYLINDER ASSY,BK MASTER W/ECU | F31: 46028 | G31: 0.5625 | H31: CA-01 | I31: AC5 | J31: 16 | K31: =VLOOKUP($C31,Sheet1!$A$2:$D$10,4,0) -> 1 | L31: =VLOOKUP($C31,Sheet1!$A$2:$E$10,5,0) -> Bin | M31: =J31/K31 -> 16 | O31: HR47E8635 | P31: 12505Q100051
A32: G/I/25-26/01536 | B32: 06N617270081AC5 | C32: 5A120M58U50 | D32: =VLOOKUP($C32,Sheet1!$A$2:$D$10,2,0) -> 114010-50830 | E32: CYLINDER ASSY,BK MASTER W/ECU | F32: 46028 | G32: 0.5625 | H32: CA-01 | I32: AC5 | J32: 23 | K32: =VLOOKUP($C32,Sheet1!$A$2:$D$10,4,0) -> 1 | L32: =VLOOKUP($C32,Sheet1!$A$2:$E$10,5,0) -> Bin | M32: =J32/K32 -> 23 | O32: HR47E8635 | P32: 12505Q100043
M33: 83 | N33: 6
A34: G/I/25-26/01537 | B34: 06N617269784AC5 | C34: 55101M58U10 | D34: =VLOOKUP($C34,Sheet1!$A$2:$D$10,2,0) -> 141110-14600 | E34: CALIPER ASSY,FRONT BRAKE,R | F34: 46028 | G34: 0.77083333 | H34: CA-07 | I34: AC5 | J34: 36 | K34: =VLOOKUP($C34,Sheet1!$A$2:$D$10,4,0) -> 18 | L34: =VLOOKUP($C34,Sheet1!$A$2:$E$10,5,0) -> Trolley (H) | N34: 2 | O34: HR47G9416 | P34: AN0250010835
A35: G/I/25-26/01537 | B35: 06N617269822AC5 | C35: 55102M58U10 | D35: =VLOOKUP($C35,Sheet1!$A$2:$D$10,2,0) -> 141120-14600 | E35: CALIPER ASSY,FRONT BRAKE,L | F35: 46028 | G35: 0.77083333 | H35: CA-07 | I35: AC5 | J35: 36 | K35: =VLOOKUP($C35,Sheet1!$A$2:$D$10,4,0) -> 18 | L35: =VLOOKUP($C35,Sheet1!$A$2:$E$10,5,0) -> Trolley (H) | O35: HR47G9416 | P35: AN0250010835
A36: G/I/25-26/01537 | B36: 06N617269865AC5 | C36: 55311M58U00 | D36: =VLOOKUP($C36,Sheet1!$A$2:$D$10,2,0) -> 141185-74670 | E36: DISC,FRONT BRAKE | F36: 46028 | G36: 0.77083333 | H36: CA-07 | I36: AC5 | J36: 80 | K36: =VLOOKUP($C36,Sheet1!$A$2:$D$10,4,0) -> 40 | L36: =VLOOKUP($C36,Sheet1!$A$2:$E$10,5,0) -> Trolley | N36: =J36/K36 -> 2 | O36: HR47G9416 | P36: 910104284
A37: G/I/25-26/01537 | B37: 06N617269903AC5 | C37: 55401M58U00 | D37: =VLOOKUP($C37,Sheet1!$A$2:$D$10,2,0) -> 141140-91211 | E37: CALIPER ASSY,REAR BRAKE,R | F37: 46028 | G37: 0.77083333 | H37: CA-21 | I37: AC5 | J37: 30 | K37: =VLOOKUP($C37,Sheet1!$A$2:$D$10,4,0) -> 2 | L37: =VLOOKUP($C37,Sheet1!$A$2:$E$10,5,0) -> Bin | M37: =J37/K37 -> 15 | O37: HR47G9416 | P37: 12505Q100043
A38: G/I/25-26/01537 | B38: 06N617269946AC5 | C38: 55402M58U00 | D38: =VLOOKUP($C38,Sheet1!$A$2:$D$10,2,0) -> 141150-91211 | E38: CALIPER ASSY,REAR BRAKE,L | F38: 46028 | G38: 0.77083333 | H38: CA-21 | I38: AC5 | J38: 30 | K38: =VLOOKUP($C38,Sheet1!$A$2:$D$10,4,0) -> 2 | L38: =VLOOKUP($C38,Sheet1!$A$2:$E$10,5,0) -> Bin | M38: =J38/K38 -> 15 | O38: HR47G9416 | P38: 12505Q100043
A39: G/I/25-26/01537 | B39: 06N617269989AC5 | C39: 55611M58U00 | D39: =VLOOKUP($C39,Sheet1!$A$2:$D$10,2,0) -> 141186-74360 | E39: DISC,REAR BRAKE | F39: 46028 | G39: 0.77083333 | H39: CA-21 | I39: AC5 | J39: 80 | K39: =VLOOKUP($C39,Sheet1!$A$2:$D$10,4,0) -> 40 | L39: =VLOOKUP($C39,Sheet1!$A$2:$E$10,5,0) -> Trolley | N39: =J39/K39 -> 2 | O39: HR47G9416 | P39: 910104658
A40: G/I/25-26/01538 | B40: 06N617270022AC5 | C40: 56110M58UA1 | D40: =VLOOKUP($C40,Sheet1!$A$2:$D$10,2,0) -> 116040-92240 | E40: ACTUATOR ASSY,NO VARIANT ESP | F40: 46028 | G40: 0.77083333 | H40: CA-01 | I40: AC5 | J40: 30 | K40: =VLOOKUP($C40,Sheet1!$A$2:$D$10,4,0) -> 6 | L40: =VLOOKUP($C40,Sheet1!$A$2:$E$10,5,0) -> Bin | M40: =J40/K40 -> 5 | O40: HR47G9416 | P40: 12505Q100152
...

Sheet 06-01-26 RPDC
A1: Supply For | B1: Original DI Date | C1: Revised DI Date | D1: Vendor Code | E1: DI Number | F1: Part Number | G1: Scheduled Quantity | H1: Packing Standerd | I1: Vehicle No | J1: Rejected Quantity | K1: Location | L1: Attention | M1: Price Change Flag | N1: Latest Batch Code | O1: Price | P1: Sales Id | Q1: Scheduled Quantity | R1: Sales No | S1: Price Revision List
A2: SPARES | B2: 46028 | D2: X539 | E2: A26451717739 | F2: 55311M58U00 | G2: 6 | H2: 1 | I2: HR47G9416 | J2: 1 | K2: WAD | L2: * | M2: N | N2: AA | O2: 4259 | P2: =G2/H2 -> 6 | Q2: 6 | S2: Item Price Revision List
A3: SPARES | B3: 46028 | D3: X539 | E3: A26451717779 | F3: 55311M58U00 | G3: 6 | H3: 1 | I3: HR47G9416 | J3: 1 | K3: WAD | L3: * | M3: N | N3: AA | O3: 4259 | P3: =G3/H3 -> 6 | Q3: 6 | S3: Item Price Revision List
A4: SPARES | B4: 46028 | D4: X539 | E4: A26451715719 | F4: 55311M58U00 | G4: 176 | H4: 1 | I4: HR47G9416 | J4: 1 | K4: WAD | L4: * | M4: N | N4: AA | O4: 4259 | P4: =G4/H4 -> 176 | Q4: 176 | S4: Item Price Revision List
A5: SPARES | B5: 46026 | C5: 46028 | D5: X539 | E5: A26449858003 | F5: 55910M58U10 | G5: 30 | H5: 10 | I5: HR47G9416 | J5: 2 | K5: WAD | L5: * | M5: N | N5: AA | O5: 3917.5 | P5: =G5/H5 -> 3 | Q5: 30 | S5: Item Price Revision List
A6: SPARES | B6: 46028 | D6: X539 | E6: A26449858013 | F6: 55910M58U10 | G6: 10 | H6: 10 | I6: HR47G9416 | J6: 2 | K6: WAD | L6: * | M6: N | N6: AA | O6: 3917.5 | P6: =G6/H6 -> 1 | Q6: 10 | S6: Item Price Revision List
A7: SPARES | B7: 46028 | D7: X539 | E7: A26451717759 | F7: 55611M58U00 | G7: 2 | H7: 1 | I7: HR47G9416 | J7: 3 | K7: WAD | L7: * | M7: N | N7: AA | O7: 3733.5 | P7: =G7/H7 -> 2 | Q7: 2 | S7: Item Price Revision List
A8: SPARES | B8: 46028 | D8: X539 | E8: A26451717789 | F8: 55611M58U00 | G8: 2 | H8: 1 | I8: HR47G9416 | J8: 3 | K8: WAD | L8: * | M8: N | N8: AA | O8: 3733.5 | P8: =G8/H8 -> 2 | Q8: 2 | S8: Item Price Revision List
A9: SPARES | B9: 46028 | D9: X539 | E9: A26451716469 | F9: 55611M58U00 | G9: 147 | H9: 1 | I9: HR47G9416 | J9: 3 | K9: WAD | L9: * | M9: N | N9: AA | O9: 3733.5 | P9: =G9/H9 -> 147 | Q9: 147 | S9: Item Price Revision List
A10: SPARES | B10: 46026 | C10: 46028 | D10: X539 | E10: A26449858173 | F10: 55950M58U00 | G10: 20 | H10: 10 | I10: HR47G9416 | J10: 4 | K10: WAD | L10: * | M10: N | N10: AA | O10: 920.5 | P10: =G10/H10 -> 2 | Q10: 20 | S10: Item Price Revision List
A11: SPARES | B11: 46026 | C11: 46028 | D11: X539 | E11: A26449858113 | F11: 55920M58U00 | G11: 60 | H11: 10 | I11: HR47G9416 | J11: 5 | K11: WAD | L11: * | M11: N | N11: AA | O11: 920.5 | P11: =G11/H11 -> 6 | Q11: 60 | S11: Item Price Revision List
A12: SPARES | B12: 46028 | D12: X539 | E12: A26451717109 | F12: 55830M58U10 | G12: 80 | H12: 10 | I12: HR47G9416 | J12: 6 | K12: WAD | L12: * | M12: N | N12: AA | O12: 843.5 | P12: =G12/H12 -> 8 | Q12: 80 | S12: Item Price Revision List
A13: SPARES | B13: 46028 | D13: X539 | E13: A26451717259 | F13: 55840M58U10 | G13: 140 | H13: 10 | I13: HR47G9416 | J13: 7 | K13: WAD | L13: * | M13: N | N13: AA | O13: 380 | P13: =G13/H13 -> 14 | Q13: 140 | S13: Item Price Revision List
A14: SPARES | B14: 46026 | C14: 46028 | D14: X539 | E14: A26449858143 | F14: 55930M58U00 | G14: 120 | H14: 10 | I14: HR47G9416 | J14: 8 | K14: WAD | L14: * | M14: N | N14: AA | O14: 460 | P14: =G14/H14 -> 12 | Q14: 120 | S14: Item Price Revision List
A15: SPARES | B15: 46027 | C15: 46028 | D15: X539 | E15: A26449858153 | F15: 55930M58U00 | G15: 10 | H15: 10 | I15: HR47G9416 | J15: 8 | K15: WAD | L15: * | M15: N | N15: AA | O15: 460 | P15: =G15/H15 -> 1 | Q15: 10 | S15: Item Price Revision List
A16: SPARES | B16: 46026 | C16: 46028 | D16: X539 | E16: A26449858193 | F16: 55960M58U00 | G16: 120 | H16: 10 | I16: HR47G9416 | J16: 9 | K16: WAD | L16: * | M16: N | N16: AA | O16: 751 | P16: =G16/H16 -> 12 | Q16: 120 | S16: Item Price Revision List
A17: SPARES | B17: 46026 | C17: 46028 | D17: X539 | E17: A26449857483 | F17: 55850M58U10 | G17: 54 | H17: 18 | I17: HR47G9416 | J17: 10 | K17: WAD | L17: * | M17: N | N17: AA | O17: 380 | P17: =G17/H17 -> 3 | Q17: 54 | S17: Item Price Revision List

Sheet 07-01-2026
J1: 24AACCN5739J1ZA
A2: Supply Month | B2: 46029 | L2: Vehicle No
A3: INVOICE NO | B3: KANBAN NO | C3: PART NUMBER | D3: Material Code | E3: PART NAME | F3: SUPPLY DATE | G3: SUPPLY TIME | H3: UNLOADING LOC | I3: Line | J3: Qty Req | K3: Packing Standerd | L3: Packed in | M3: TTL Bin | N3: TORLLY | O3: Vehicle No | P3: INV NO
A4: G/I/25-26/01545 | B4: 07N618082246AC5 | C4: 55101M58U10 | D4: =VLOOKUP($C4,Sheet1!$A$2:$D$10,2,0) -> 141110-14600 | E4: CALIPER ASSY,FRONT BRAKE,R | F4: 46029 | G4: 0.27083333 | H4: CA-07 | I4: AC5 | J4: 18 | K4: =VLOOKUP($C4,Sheet1!$A$2:$D$10,4,0) -> 18 | L4: =VLOOKUP($C4,Sheet1!$A$2:$E$10,5,0) -> Trolley (H) | N4: 1 | O4: HR47H5465 | P4: AN0250010835
A5: G/I/25-26/01545 | B5: 07N618087094AC5 | C5: 55102M58U10 | D5: =VLOOKUP($C5,Sheet1!$A$2:$D$10,2,0) -> 141120-14600 | E5: CALIPER ASSY,FRONT BRAKE,L | F5: 46029 | G5: 0.27083333 | H5: CA-07 | I5: AC5 | J5: 18 | K5: =VLOOKUP($C5,Sheet1!$A$2:$D$10,4,0) -> 18 | L5: =VLOOKUP($C5,Sheet1!$A$2:$E$10,5,0) -> Trolley (H) | O5: HR47H5465 | P5: AN0250010835
A6: G/I/25-26/01545 | B6: 07N618080952AC5 | C6: 55311M58U00 | D6: =VLOOKUP($C6,Sheet1!$A$2:$D$10,2,0) -> 141185-74670 | E6: DISC,FRONT BRAKE | F6: 46029 | G6: 0.27083333 | H6: CA-07 | I6: AC5 | J6: 80 | K6: =VLOOKUP($C6,Sheet1!$A$2:$D$10,4,0) -> 40 | L6: =VLOOKUP($C6,Sheet1!$A$2:$E$10,5,0) -> Trolley | N6: =J6/K6 -> 2 | O6: HR47H5465 | P6: 910104658
A7: G/I/25-26/01545 | B7: 07N618078702AC5 | C7: 55401M58U00 | D7: =VLOOKUP($C7,Sheet1!$A$2:$D$10,2,0) -> 141140-91211 | E7: CALIPER ASSY,REAR BRAKE,R | F7: 46029 | G7: 0.27083333 | H7: CA-21 | I7: AC5 | J7: 30 | K7: =VLOOKUP($C7,Sheet1!$A$2:$D$10,4,0) -> 2 | L7: =VLOOKUP($C7,Sheet1!$A$2:$E$10,5,0) -> Bin | M7: =J7/K7 -> 15 | O7: HR47H5465 | P7: 12505Q100043
A8: G/I/25-26/01545 | B8: 07N618083307AC5 | C8: 55402M58U00 | D8: =VLOOKUP($C8,Sheet1!$A$2:$D$10,2,0) -> 141150-91211 | E8: CALIPER ASSY,REAR BRAKE,L | F8: 46029 | G8: 0.27083333 | H8: CA-21 | I8: AC5 | J8: 30 | K8: =VLOOKUP($C8,Sheet1!$A$2:$D$10,4,0) -> 2 | L8: =VLOOKUP($C8,Sheet1!$A$2:$E$10,5,0) -> Bin | M8: =J8/K8 -> 15 | O8: HR47H5465 | P8: 12505Q100043
A9: G/I/25-26/01545 | B9: 07N618078370AC5 | C9: 55611M58U00 | D9: =VLOOKUP($C9,Sheet1!$A$2:$D$10,2,0) -> 141186-74360 | E9: DISC,REAR BRAKE | F9: 46029 | G9: 0.27083333 | H9: CA-21 | I9: AC5 | J9: 80 | K9: =VLOOKUP($C9,Sheet1!$A$2:$D$10,4,0) -> 40 | L9: =VLOOKUP($C9,Sheet1!$A$2:$E$10,5,0) -> Trolley | N9: =J9/K9 -> 2 | O9: HR47H5465 | P9: 910104658
A10: G/I/25-26/01546 | B10: 07N618079393AC5 | C10: 56110M58UA1 | D10: =VLOOKUP($C10,Sheet1!$A$2:$D$10,2,0) -> 116040-92240 | E10: ACTUATOR ASSY,NO VARIANT ESP | F10: 46029 | G10: 0.27083333 | H10: CA-01 | I10: AC5 | J10: 30 | K10: =VLOOKUP($C10,Sheet1!$A$2:$D$10,4,0) -> 6 | L10: =VLOOKUP($C10,Sheet1!$A$2:$E$10,5,0) -> Bin | M10: =J10/K10 -> 5 | O10: HR47H5465 | P10: 12505Q100152
A11: G/I/25-26/01546 | B11: 07N618081630AC5 | C11: 5A120M58U01 | D11: =VLOOKUP($C11,Sheet1!$A$2:$D$10,2,0) -> 114010-50820 | E11: CYLINDER ASSY,BK MASTER W/ECU | F11: 46029 | G11: 0.27083333 | H11: CA-01 | I11: AC5 | J11: 20 | K11: =VLOOKUP($C11,Sheet1!$A$2:$D$10,4,0) -> 1 | L11: =VLOOKUP($C11,Sheet1!$A$2:$E$10,5,0) -> Bin | M11: =J11/K11 -> 20 | O11: HR47H5465 | P11: 12505Q100051
A12: G/I/25-26/01546 | B12: 07N618077617AC5 | C12: 5A120M58U50 | D12: =VLOOKUP($C12,Sheet1!$A$2:$D$10,2,0) -> 114010-50830 | E12: CYLINDER ASSY,BK MASTER W/ECU | F12: 46029 | G12: 0.27083333 | H12: CA-01 | I12: AC5 | J12: 20 | K12: =VLOOKUP($C12,Sheet1!$A$2:$D$10,4,0) -> 1 | L12: =VLOOKUP($C12,Sheet1!$A$2:$E$10,5,0) -> Bin | M12: =J12/K12 -> 20 | O12: HR47H5465 | P12: 12505Q100043
M13: 75 | N13: 5
A14: G/I/25-26/01547 | B14: 07N618015492AC5 | C14: 55101M58U10 | D14: =VLOOKUP($C14,Sheet1!$A$2:$D$10,2,0) -> 141110-14600 | E14: CALIPER ASSY,FRONT BRAKE,R | F14: 46029 | G14: 0.35416667 | H14: CA-07 | I14: AC5 | J14: 36 | K14: =VLOOKUP($C14,Sheet1!$A$2:$D$10,4,0) -> 18 | L14: =VLOOKUP($C14,Sheet1!$A$2:$E$10,5,0) -> Trolley (H) | N14: 2 | O14: HR47E7907 | P14: AN0250010835
A15: G/I/25-26/01547 | B15: 07N618015530AC5 | C15: 55102M58U10 | D15: =VLOOKUP($C15,Sheet1!$A$2:$D$10,2,0) -> 141120-14600 | E15: CALIPER ASSY,FRONT BRAKE,L | F15: 46029 | G15: 0.35416667 | H15: CA-07 | I15: AC5 | J15: 36 | K15: =VLOOKUP($C15,Sheet1!$A$2:$D$10,4,0) -> 18 | L15: =VLOOKUP($C15,Sheet1!$A$2:$E$10,5,0) -> Trolley (H) | O15: HR47E7907 | P15: AN0250010835
A16: G/I/25-26/01547 | B16: 07N618015573AC5 | C16: 55311M58U00 | D16: =VLOOKUP($C16,Sheet1!$A$2:$D$10,2,0) -> 141185-74670 | E16: DISC,FRONT BRAKE | F16: 46029 | G16: 0.35416667 | H16: CA-07 | I16: AC5 | J16: 80 | K16: =VLOOKUP($C16,Sheet1!$A$2:$D$10,4,0) -> 40 | L16: =VLOOKUP($C16,Sheet1!$A$2:$E$10,5,0) -> Trolley | N16: =J16/K16 -> 2 | O16: HR47E7907 | P16: 910104658
A17: G/I/25-26/01547 | B17: 07N618015603AC5 | C17: 55401M58U00 | D17: =VLOOKUP($C17,Sheet1!$A$2:$D$10,2,0) -> 141140-91211 | E17: CALIPER ASSY,REAR BRAKE,R | F17: 46029 | G17: 0.35416667 | H17: CA-21 | I17: AC5 | J17: 42 | K17: =VLOOKUP($C17,Sheet1!$A$2:$D$10,4,0) -> 2 | L17: =VLOOKUP($C17,Sheet1!$A$2:$E$10,5,0) -> Bin | M17: =J17/K17 -> 21 | O17: HR47E7907 | P17: 12505Q100043
A18: G/I/25-26/01547 | B18: 07N618015646AC5 | C18: 55402M58U00 | D18: =VLOOKUP($C18,Sheet1!$A$2:$D$10,2,0) -> 141150-91211 | E18: CALIPER ASSY,REAR BRAKE,L | F18: 46029 | G18: 0.35416667 | H18: CA-21 | I18: AC5 | J18: 42 | K18: =VLOOKUP($C18,Sheet1!$A$2:$D$10,4,0) -> 2 | L18: =VLOOKUP($C18,Sheet1!$A$2:$E$10,5,0) -> Bin | M18: =J18/K18 -> 21 | O18: HR47E7907 | P18: 12505Q100043
A19: G/I/25-26/01547 | B19: 07N618015689AC5 | C19: 55611M58U00 | D19: =VLOOKUP($C19,Sheet1!$A$2:$D$10,2,0) -> 141186-74360 | E19: DISC,REAR BRAKE | F19: 46029 | G19: 0.35416667 | H19: CA-21 | I19: AC5 | J19: 80 | K19: =VLOOKUP($C19,Sheet1!$A$2:$D$10,4,0) -> 40 | L19: =VLOOKUP($C19,Sheet1!$A$2:$E$10,5,0) -> Trolley | N19: =J19/K19 -> 2 | O19: HR47E7907 | P19: 910104658
A20: G/I/25-26/01548 | B20: 07N618015719AC5 | C20: 56110M58UA1 | D20: =VLOOKUP($C20,Sheet1!$A$2:$D$10,2,0) -> 116040-92240 | E20: ACTUATOR ASSY,NO VARIANT ESP | F20: 46029 | G20: 0.35416667 | H20: CA-01 | I20: AC5 | J20: 42 | K20: =VLOOKUP($C20,Sheet1!$A$2:$D$10,4,0) -> 6 | L20: =VLOOKUP($C20,Sheet1!$A$2:$E$10,5,0) -> Bin | M20: =J20/K20 -> 7 | O20: HR47E7907 | P20: 12506Q100012
A21: G/I/25-26/01548 | B21: 07N618015751AC5 | C21: 5A120M58U01 | D21: =VLOOKUP($C21,Sheet1!$A$2:$D$10,2,0) -> 114010-50820 | E21: CYLINDER ASSY,BK MASTER W/ECU | F21: 46029 | G21: 0.35416667 | H21: CA-01 | I21: AC5 | J21: 16 | K21: =VLOOKUP($C21,Sheet1!$A$2:$D$10,4,0) -> 1 | L21: =VLOOKUP($C21,Sheet1!$A$2:$E$10,5,0) -> Bin | M21: =J21/K21 -> 16 | O21: HR47E7907 | P21: 12505Q100051
A22: G/I/25-26/01548 | B22: 07N618015794AC5 | C22: 5A120M58U50 | D22: =VLOOKUP($C22,Sheet1!$A$2:$D$10,2,0) -> 114010-50830 | E22: CYLINDER ASSY,BK MASTER W/ECU | F22: 46029 | G22: 0.35416667 | H22: CA-01 | I22: AC5 | J22: 26 | K22: =VLOOKUP($C22,Sheet1!$A$2:$D$10,4,0) -> 1 | L22: =VLOOKUP($C22,Sheet1!$A$2:$E$10,5,0) -> Bin | M22: =J22/K22 -> 26 | O22: HR47E7907 | P22: 12505Q100043
M23: 91 | N23: 6
A24: G/I/25-26/01549 | B24: 07N618088716AC5 | C24: 55101M58U10 | D24: =VLOOKUP($C24,Sheet1!$A$2:$D$10,2,0) -> 141110-14600 | E24: CALIPER ASSY,FRONT BRAKE,R | F24: 46029 | G24: 0.4375 | H24: CA-07 | I24: AC5 | J24: 18 | K24: =VLOOKUP($C24,Sheet1!$A$2:$D$10,4,0) -> 18 | L24: =VLOOKUP($C24,Sheet1!$A$2:$E$10,5,0) -> Trolley (H) | N24: 1 | O24: HR47E8635 | P24: AN0250010835
A25: G/I/25-26/01549 | B25: 07N618091768AC5 | C25: 55102M58U10 | D25: =VLOOKUP($C25,Sheet1!$A$2:$D$10,2,0) -> 141120-14600 | E25: CALIPER ASSY,FRONT BRAKE,L | F25: 46029 | G25: 0.4375 | H25: CA-07 | I25: AC5 | J25: 18 | K25: =VLOOKUP($C25,Sheet1!$A$2:$D$10,4,0) -> 18 | L25: =VLOOKUP($C25,Sheet1!$A$2:$E$10,5,0) -> Trolley (H) | O25: HR47E8635 | P25: AN0250010835
A26: G/I/25-26/01549 | B26: 07N618092624AC5 | C26: 55311M58U00 | D26: =VLOOKUP($C26,Sheet1!$A$2:$D$10,2,0) -> 141185-74670 | E26: DISC,FRONT BRAKE | F26: 46029 | G26: 0.4375 | H26: CA-07 | I26: AC5 | J26: 40 | K26: =VLOOKUP($C26,Sheet1!$A$2:$D$10,4,0) -> 40 | L26: =VLOOKUP($C26,Sheet1!$A$2:$E$10,5,0) -> Trolley | N26: =J26/K26 -> 1 | O26: HR47E8635 | P26: 910104658
A27: G/I/25-26/01549 | B27: 07N618092195AC5 | C27: 55401M58U00 | D27: =VLOOKUP($C27,Sheet1!$A$2:$D$10,2,0) -> 141140-91211 | E27: CALIPER ASSY,REAR BRAKE,R | F27: 46029 | G27: 0.4375 | H27: CA-21 | I27: AC5 | J27: 14 | K27: =VLOOKUP($C27,Sheet1!$A$2:$D$10,4,0) -> 2 | L27: =VLOOKUP($C27,Sheet1!$A$2:$E$10,5,0) -> Bin | M27: =J27/K27 -> 7 | O27: HR47E8635 | P27: 12505Q100043
A28: G/I/25-26/01549 | B28: 07N618093183AC5 | C28: 55402M58U00 | D28: =VLOOKUP($C28,Sheet1!$A$2:$D$10,2,0) -> 141150-91211 | E28: CALIPER ASSY,REAR BRAKE,L | F28: 46029 | G28: 0.4375 | H28: CA-21 | I28: AC5 | J28: 14 | K28: =VLOOKUP($C28,Sheet1!$A$2:$D$10,4,0) -> 2 | L28: =VLOOKUP($C28,Sheet1!$A$2:$E$10,5,0) -> Bin | M28: =J28/K28 -> 7 | O28: HR47E8635 | P28: 12505Q100043
A29: G/I/25-26/01550 | B29: 07N618089976AC5 | C29: 56110M58UA1 | D29: =VLOOKUP($C29,Sheet1!$A$2:$D$10,2,0) -> 116040-92240 | E29: ACTUATOR ASSY,NO VARIANT ESP | F29: 46029 | G29: 0.4375 | H29: CA-01 | I29: AC5 | J29: 18 | K29: =VLOOKUP($C29,Sheet1!$A$2:$D$10,4,0) -> 6 | L29: =VLOOKUP($C29,Sheet1!$A$2:$E$10,5,0) -> Bin | M29: =J29/K29 -> 3 | O29: HR47E8635 | P29: 12506Q100012
A30: G/I/25-26/01550 | B30: 07N618090281AC5 | C30: 5A120M58U01 | D30: =VLOOKUP($C30,Sheet1!$A$2:$D$10,2,0) -> 114010-50820 | E30: CYLINDER ASSY,BK MASTER W/ECU | F30: 46029 | G30: 0.4375 | H30: CA-01 | I30: AC5 | J30: 9 | K30: =VLOOKUP($C30,Sheet1!$A$2:$D$10,4,0) -> 1 | L30: =VLOOKUP($C30,Sheet1!$A$2:$E$10,5,0) -> Bin | M30: =J30/K30 -> 9 | O30: HR47E8635 | P30: 12505Q100051
A31: G/I/25-26/01550 | B31: 07N618089500AC5 | C31: 5A120M58U50 | D31: =VLOOKUP($C31,Sheet1!$A$2:$D$10,2,0) -> 114010-50830 | E31: CYLINDER ASSY,BK MASTER W/ECU | F31: 46029 | G31: 0.4375 | H31: CA-01 | I31: AC5 | J31: 11 | K31: =VLOOKUP($C31,Sheet1!$A$2:$D$10,4,0) -> 1 | L31: =VLOOKUP($C31,Sheet1!$A$2:$E$10,5,0) -> Bin | M31: =J31/K31 -> 11 | O31: HR47E8635 | P31: 12505Q100043
A32: G/I/25-26/01551 | B32: 07N618015506AC5 | C32: 55101M58U10 | D32: =VLOOKUP($C32,Sheet1!$A$2:$D$10,2,0) -> 141110-14600 | E32: CALIPER ASSY,FRONT BRAKE,R | F32: 46029 | G32: 0.5625 | H32: CA-07 | I32: AC5 | J32: 36 | K32: =VLOOKUP($C32,Sheet1!$A$2:$D$10,4,0) -> 18 | L32: =VLOOKUP($C32,Sheet1!$A$2:$E$10,5,0) -> Trolley (H) | N32: 2 | O32: HR47E8635 | P32: AN0250010835-30 Qty. / AN0250010911 -6 Qty.
A33: G/I/25-26/01551 | B33: 07N618015549AC5 | C33: 55102M58U10 | D33: =VLOOKUP($C33,Sheet1!$A$2:$D$10,2,0) -> 141120-14600 | E33: CALIPER ASSY,FRONT BRAKE,L | F33: 46029 | G33: 0.5625 | H33: CA-07 | I33: AC5 | J33: 36 | K33: =VLOOKUP($C33,Sheet1!$A$2:$D$10,4,0) -> 18 | L33: =VLOOKUP($C33,Sheet1!$A$2:$E$10,5,0) -> Trolley (H) | O33: HR47E8635 | P33: AN0250010835-31 Qty. / AN0250010911 -5 Qty.
A34: G/I/25-26/01551 | B34: 07N618015581AC5 | C34: 55311M58U00 | D34: =VLOOKUP($C34,Sheet1!$A$2:$D$10,2,0) -> 141185-74670 | E34: DISC,FRONT BRAKE | F34: 46029 | G34: 0.5625 | H34: CA-07 | I34: AC5 | J34: 80 | K34: =VLOOKUP($C34,Sheet1!$A$2:$D$10,4,0) -> 40 | L34: =VLOOKUP($C34,Sheet1!$A$2:$E$10,5,0) -> Trolley | N34: =J34/K34 -> 2 | O34: HR47E8635 | P34: 910104658
A35: G/I/25-26/01551 | B35: 07N618015611AC5 | C35: 55401M58U00 | D35: =VLOOKUP($C35,Sheet1!$A$2:$D$10,2,0) -> 141140-91211 | E35: CALIPER ASSY,REAR BRAKE,R | F35: 46029 | G35: 0.5625 | H35: CA-21 | I35: AC5 | J35: 30 | K35: =VLOOKUP($C35,Sheet1!$A$2:$D$10,4,0) -> 2 | L35: =VLOOKUP($C35,Sheet1!$A$2:$E$10,5,0) -> Bin | M35: =J35/K35 -> 15 | O35: HR47E8635 | P35: 12505Q100043
A36: G/I/25-26/01551 | B36: 07N618015654AC5 | C36: 55402M58U00 | D36: =VLOOKUP($C36,Sheet1!$A$2:$D$10,2,0) -> 141150-91211 | E36: CALIPER ASSY,REAR BRAKE,L | F36: 46029 | G36: 0.5625 | H36: CA-21 | I36: AC5 | J36: 30 | K36: =VLOOKUP($C36,Sheet1!$A$2:$D$10,4,0) -> 2 | L36: =VLOOKUP($C36,Sheet1!$A$2:$E$10,5,0) -> Bin | M36: =J36/K36 -> 15 | O36: HR47E8635 | P36: 12505Q100043
A37: G/I/25-26/01551 | B37: 07N618015697AC5 | C37: 55611M58U00 | D37: =VLOOKUP($C37,Sheet1!$A$2:$D$10,2,0) -> 141186-74360 | E37: DISC,REAR BRAKE | F37: 46029 | G37: 0.5625 | H37: CA-21 | I37: AC5 | J37: 80 | K37: =VLOOKUP($C37,Sheet1!$A$2:$D$10,4,0) -> 40 | L37: =VLOOKUP($C37,Sheet1!$A$2:$E$10,5,0) -> Trolley | N37: =J37/K37 -> 2 | O37: HR47E8635 | P37: AT/RGP/25-26/WA-168-62 Qty/910104658-18 Qty.
A38: G/I/25-26/01552 | B38: 07N618015727AC5 | C38: 56110M58UA1 | D38: =VLOOKUP($C38,Sheet1!$A$2:$D$10,2,0) -> 116040-92240 | E38: ACTUATOR ASSY,NO VARIANT ESP | F38: 46029 | G38: 0.5625 | H38: CA-01 | I38: AC5 | J38: 30 | K38: =VLOOKUP($C38,Sheet1!$A$2:$D$10,4,0) -> 6 | L38: =VLOOKUP($C38,Sheet1!$A$2:$E$10,5,0) -> Bin | M38: =J38/K38 -> 5 | O38: HR47E8635 | P38: 12506Q100012
A39: G/I/25-26/01552 | B39: 07N618015760AC5 | C39: 5A120M58U01 | D39: =VLOOKUP($C39,Sheet1!$A$2:$D$10,2,0) -> 114010-50820 | E39: CYLINDER ASSY,BK MASTER W/ECU | F39: 46029 | G39: 0.5625 | H39: CA-01 | I39: AC5 | J39: 11 | K39: =VLOOKUP($C39,Sheet1!$A$2:$D$10,4,0) -> 1 | L39: =VLOOKUP($C39,Sheet1!$A$2:$E$10,5,0) -> Bin | M39: =J39/K39 -> 11 | O39: HR47E8635 | P39: 12505Q100051
A40: G/I/25-26/01552 | B40: 07N618015808AC5 | C40: 5A120M58U50 | D40: =VLOOKUP($C40,Sheet1!$A$2:$D$10,2,0) -> 114010-50830 | E40: CYLINDER ASSY,BK MASTER W/ECU | F40: 46029 | G40: 0.5625 | H40: CA-01 | I40: AC5 | J40: 19 | K40: =VLOOKUP($C40,Sheet1!$A$2:$D$10,4,0) -> 1 | L40: =VLOOKUP($C40,Sheet1!$A$2:$E$10,5,0) -> Bin | M40: =J40/K40 -> 19 | O40: HR47E8635 | P40: 12505Q100043
...

Sheet 08-01-2026
J1: 24AACCN5739J1ZA
A2: Supply Month | B2: 46030 | L2: Vehicle No
A3: INVOICE NO | B3: KANBAN NO | C3: PART NUMBER | D3: Material Code | E3: PART NAME | F3: SUPPLY DATE | G3: SUPPLY TIME | H3: UNLOADING LOC | I3: Line | J3: Qty Req | K3: Packing Standerd | L3: Packed in | M3: TTL Bin | N3: TORLLY | O3: Vehicle No | P3: INV NO
A4: G/I/25-26/01557 | B4: 08N618723683AC5 | C4: 55101M58U10 | D4: =VLOOKUP($C4,Sheet1!$A$2:$D$10,2,0) -> 141110-14600 | E4: CALIPER ASSY,FRONT BRAKE,R | F4: 46030 | G4: 0.35416667 | H4: CA-07 | I4: AC5 | J4: 54 | K4: =VLOOKUP($C4,Sheet1!$A$2:$D$10,4,0) -> 18 | L4: =VLOOKUP($C4,Sheet1!$A$2:$E$10,5,0) -> Trolley (H) | N4: 3 | O4: HR47H5465 | P4: AN0250010911
A5: G/I/25-26/01557 | B5: 08N618723721AC5 | C5: 55102M58U10 | D5: =VLOOKUP($C5,Sheet1!$A$2:$D$10,2,0) -> 141120-14600 | E5: CALIPER ASSY,FRONT BRAKE,L | F5: 46030 | G5: 0.35416667 | H5: CA-07 | I5: AC5 | J5: 54 | K5: =VLOOKUP($C5,Sheet1!$A$2:$D$10,4,0) -> 18 | L5: =VLOOKUP($C5,Sheet1!$A$2:$E$10,5,0) -> Trolley (H) | O5: HR47H5465 | P5: AN0250010911
A6: G/I/25-26/01557 | B6: 08N618723764AC5 | C6: 55311M58U00 | D6: =VLOOKUP($C6,Sheet1!$A$2:$D$10,2,0) -> 141185-74670 | E6: DISC,FRONT BRAKE | F6: 46030 | G6: 0.35416667 | H6: CA-07 | I6: AC5 | J6: 120 | K6: =VLOOKUP($C6,Sheet1!$A$2:$D$10,4,0) -> 40 | L6: =VLOOKUP($C6,Sheet1!$A$2:$E$10,5,0) -> Trolley | N6: =J6/K6 -> 3 | O6: HR47H5465 | P6: 910104658
A7: G/I/25-26/01557 | B7: 07N618102816AC5 | C7: 55401M58U00 | D7: =VLOOKUP($C7,Sheet1!$A$2:$D$10,2,0) -> 141140-91211 | E7: CALIPER ASSY,REAR BRAKE,R | F7: 46030 | G7: 0.35416667 | H7: CA-21 | I7: AC5 | J7: 4 | K7: =VLOOKUP($C7,Sheet1!$A$2:$D$10,4,0) -> 2 | L7: =VLOOKUP($C7,Sheet1!$A$2:$E$10,5,0) -> Bin | M7: =J7/K7 -> 2 | O7: HR47H5465 | P7: 12505Q100043
A8: G/I/25-26/01557 | B8: 08N618723802AC5 | C8: 55401M58U00 | D8: =VLOOKUP($C8,Sheet1!$A$2:$D$10,2,0) -> 141140-91211 | E8: CALIPER ASSY,REAR BRAKE,R | F8: 46030 | G8: 0.35416667 | H8: CA-21 | I8: AC5 | J8: 60 | K8: =VLOOKUP($C8,Sheet1!$A$2:$D$10,4,0) -> 2 | L8: =VLOOKUP($C8,Sheet1!$A$2:$E$10,5,0) -> Bin | M8: =J8/K8 -> 30 | O8: HR47H5465 | P8: 12505Q100043
A9: G/I/25-26/01557 | B9: 07N618101747AC5 | C9: 55402M58U00 | D9: =VLOOKUP($C9,Sheet1!$A$2:$D$10,2,0) -> 141150-91211 | E9: CALIPER ASSY,REAR BRAKE,L | F9: 46030 | G9: 0.35416667 | H9: CA-21 | I9: AC5 | J9: 4 | K9: =VLOOKUP($C9,Sheet1!$A$2:$D$10,4,0) -> 2 | L9: =VLOOKUP($C9,Sheet1!$A$2:$E$10,5,0) -> Bin | M9: =J9/K9 -> 2 | O9: HR47H5465 | P9: 12505Q100043
A10: G/I/25-26/01557 | B10: 08N618723845AC5 | C10: 55402M58U00 | D10: =VLOOKUP($C10,Sheet1!$A$2:$D$10,2,0) -> 141150-91211 | E10: CALIPER ASSY,REAR BRAKE,L | F10: 46030 | G10: 0.35416667 | H10: CA-21 | I10: AC5 | J10: 60 | K10: =VLOOKUP($C10,Sheet1!$A$2:$D$10,4,0) -> 2 | L10: =VLOOKUP($C10,Sheet1!$A$2:$E$10,5,0) -> Bin | M10: =J10/K10 -> 30 | O10: HR47H5465 | P10: 12505Q100043
A11: G/I/25-26/01557 | B11: 07N618103022AC5 | C11: 55611M58U00 | D11: =VLOOKUP($C11,Sheet1!$A$2:$D$10,2,0) -> 141186-74360 | E11: DISC,REAR BRAKE | F11: 46030 | G11: 0.35416667 | H11: CA-21 | I11: AC5 | J11: 40 | K11: =VLOOKUP($C11,Sheet1!$A$2:$D$10,4,0) -> 40 | L11: =VLOOKUP($C11,Sheet1!$A$2:$E$10,5,0) -> Trolley | N11: 1 | O11: HR47H5465 | P11: 910104658
A12: G/I/25-26/01557 | B12: 08N618809847AC5 | C12: 55611M58U00 | D12: =VLOOKUP($C12,Sheet1!$A$2:$D$10,2,0) -> 141186-74360 | E12: DISC,REAR BRAKE | F12: 46030 | G12: 0.35416667 | H12: CA-21 | I12: AC5 | J12: 40 | K12: =VLOOKUP($C12,Sheet1!$A$2:$D$10,4,0) -> 40 | L12: =VLOOKUP($C12,Sheet1!$A$2:$E$10,5,0) -> Trolley | N12: 1 | O12: HR47H5465 | P12: 910104658
A13: G/I/25-26/01558 | B13: 08N618809065AC5 | C13: 56110M58UA1 | D13: =VLOOKUP($C13,Sheet1!$A$2:$D$10,2,0) -> 116040-92240 | E13: ACTUATOR ASSY,NO VARIANT ESP | F13: 46030 | G13: 0.35416667 | H13: CA-01 | I13: AC5 | J13: 36 | K13: =VLOOKUP($C13,Sheet1!$A$2:$D$10,4,0) -> 6 | L13: =VLOOKUP($C13,Sheet1!$A$2:$E$10,5,0) -> Bin | M13: =J13/K13 -> 6 | O13: HR47H5465 | P13: 12506Q100012
A14: G/I/25-26/01558 | B14: 08N618810128AC5 | C14: 5A120M58U01 | D14: =VLOOKUP($C14,Sheet1!$A$2:$D$10,2,0) -> 114010-50820 | E14: CYLINDER ASSY,BK MASTER W/ECU | F14: 46030 | G14: 0.35416667 | H14: CA-01 | I14: AC5 | J14: 13 | K14: =VLOOKUP($C14,Sheet1!$A$2:$D$10,4,0) -> 1 | L14: =VLOOKUP($C14,Sheet1!$A$2:$E$10,5,0) -> Bin | M14: =J14/K14 -> 13 | O14: HR47H5465 | P14: 12505Q100086
A15: G/I/25-26/01558 | B15: 08N618811132AC5 | C15: 5A120M58U50 | D15: =VLOOKUP($C15,Sheet1!$A$2:$D$10,2,0) -> 114010-50830 | E15: CYLINDER ASSY,BK MASTER W/ECU | F15: 46030 | G15: 0.35416667 | H15: CA-01 | I15: AC5 | J15: 23 | K15: =VLOOKUP($C15,Sheet1!$A$2:$D$10,4,0) -> 1 | L15: =VLOOKUP($C15,Sheet1!$A$2:$E$10,5,0) -> Bin | M15: =J15/K15 -> 23 | O15: HR47H5465 | P15: 12505Q100043
M16: 106 | N16: 8
A17: G/I/25-26/01559 | B17: 08N618808662AC5 | C17: 55101M58U10 | D17: =VLOOKUP($C17,Sheet1!$A$2:$D$10,2,0) -> 141110-14600 | E17: CALIPER ASSY,FRONT BRAKE,R | F17: 46030 | G17: 0.35416667 | H17: CA-07 | I17: AC5 | J17: 36 | K17: =VLOOKUP($C17,Sheet1!$A$2:$D$10,4,0) -> 18 | L17: =VLOOKUP($C17,Sheet1!$A$2:$E$10,5,0) -> Trolley (H) | N17: 2 | O17: HR47E8635 | P17: AN0250010911
A18: G/I/25-26/01559 | B18: 08N618802850AC5 | C18: 55102M58U10 | D18: =VLOOKUP($C18,Sheet1!$A$2:$D$10,2,0) -> 141120-14600 | E18: CALIPER ASSY,FRONT BRAKE,L | F18: 46030 | G18: 0.35416667 | H18: CA-07 | I18: AC5 | J18: 36 | K18: =VLOOKUP($C18,Sheet1!$A$2:$D$10,4,0) -> 18 | L18: =VLOOKUP($C18,Sheet1!$A$2:$E$10,5,0) -> Trolley (H) | O18: HR47E8635 | P18: AN0250010911
A19: G/I/25-26/01559 | B19: 08N618723683AC5 | C19: 55101M58U10 | D19: =VLOOKUP($C19,Sheet1!$A$2:$D$10,2,0) -> 141110-14600 | E19: CALIPER ASSY,FRONT BRAKE,R | F19: 46030 | G19: 0.35416667 | H19: CA-07 | I19: AC5 | J19: 18 | K19: =VLOOKUP($C19,Sheet1!$A$2:$D$10,4,0) -> 18 | L19: =VLOOKUP($C19,Sheet1!$A$2:$E$10,5,0) -> Trolley (H) | N19: 1 | O19: HR47E8635 | P19: AN0250010911
A20: G/I/25-26/01559 | B20: 08N618723721AC5 | C20: 55102M58U10 | D20: =VLOOKUP($C20,Sheet1!$A$2:$D$10,2,0) -> 141120-14600 | E20: CALIPER ASSY,FRONT BRAKE,L | F20: 46030 | G20: 0.35416667 | H20: CA-07 | I20: AC5 | J20: 18 | K20: =VLOOKUP($C20,Sheet1!$A$2:$D$10,4,0) -> 18 | L20: =VLOOKUP($C20,Sheet1!$A$2:$E$10,5,0) -> Trolley (H) | O20: HR47E8635 | P20: AN0250010911
A21: G/I/25-26/01559 | B21: 08N618812414AC5 | C21: 55311M58U00 | D21: =VLOOKUP($C21,Sheet1!$A$2:$D$10,2,0) -> 141185-74670 | E21: DISC,FRONT BRAKE | F21: 46030 | G21: 0.35416667 | H21: CA-07 | I21: AC5 | J21: 80 | K21: =VLOOKUP($C21,Sheet1!$A$2:$D$10,4,0) -> 40 | L21: =VLOOKUP($C21,Sheet1!$A$2:$E$10,5,0) -> Trolley | N21: =J21/K21 -> 2 | O21: HR47E8635 | P21: 910104658
A22: G/I/25-26/01559 | B22: 08N618809570AC5 | C22: 55401M58U00 | D22: =VLOOKUP($C22,Sheet1!$A$2:$D$10,2,0) -> 141140-91211 | E22: CALIPER ASSY,REAR BRAKE,R | F22: 46030 | G22: 0.35416667 | H22: CA-21 | I22: AC5 | J22: 36 | K22: =VLOOKUP($C22,Sheet1!$A$2:$D$10,4,0) -> 2 | L22: =VLOOKUP($C22,Sheet1!$A$2:$E$10,5,0) -> Bin | M22: =J22/K22 -> 18 | O22: HR47E8635 | P22: 12505Q100043
A23: G/I/25-26/01559 | B23: 08N618808506AC5 | C23: 55402M58U00 | D23: =VLOOKUP($C23,Sheet1!$A$2:$D$10,2,0) -> 141150-91211 | E23: CALIPER ASSY,REAR BRAKE,L | F23: 46030 | G23: 0.35416667 | H23: CA-21 | I23: AC5 | J23: 36 | K23: =VLOOKUP($C23,Sheet1!$A$2:$D$10,4,0) -> 2 | L23: =VLOOKUP($C23,Sheet1!$A$2:$E$10,5,0) -> Bin | M23: =J23/K23 -> 18 | O23: HR47E8635 | P23: 12505Q100031
A24: G/I/25-26/01559 | B24: 08N618723888AC5 | C24: 55611M58U00 | D24: =VLOOKUP($C24,Sheet1!$A$2:$D$10,2,0) -> 141186-74360 | E24: DISC,REAR BRAKE | F24: 46030 | G24: 0.35416667 | H24: CA-21 | I24: AC5 | J24: 120 | K24: =VLOOKUP($C24,Sheet1!$A$2:$D$10,4,0) -> 40 | L24: =VLOOKUP($C24,Sheet1!$A$2:$E$10,5,0) -> Trolley | N24: 3 | O24: HR47E8635 | P24: 910104658-110 Qty. / 910104269-10 Qty.
A25: G/I/25-26/01560 | B25: 08N618723926AC5 | C25: 56110M58UA1 | D25: =VLOOKUP($C25,Sheet1!$A$2:$D$10,2,0) -> 116040-92240 | E25: ACTUATOR ASSY,NO VARIANT ESP | F25: 46030 | G25: 0.35416667 | H25: CA-01 | I25: AC5 | J25: 60 | K25: =VLOOKUP($C25,Sheet1!$A$2:$D$10,4,0) -> 6 | L25: =VLOOKUP($C25,Sheet1!$A$2:$E$10,5,0) -> Bin | M25: =J25/K25 -> 10 | O25: HR47E8635 | P25: 12506Q100012
A26: G/I/25-26/01560 | B26: 07N618102328AC5 | C26: 5A120M58U01 | D26: =VLOOKUP($C26,Sheet1!$A$2:$D$10,2,0) -> 114010-50820 | E26: CYLINDER ASSY,BK MASTER W/ECU | F26: 46030 | G26: 0.35416667 | H26: CA-01 | I26: AC5 | J26: 3 | K26: =VLOOKUP($C26,Sheet1!$A$2:$D$10,4,0) -> 1 | L26: =VLOOKUP($C26,Sheet1!$A$2:$E$10,5,0) -> Bin | M26: =J26/K26 -> 3 | O26: HR47E8635 | P26: 12505Q100051
A27: G/I/25-26/01560 | B27: 08N618723969AC5 | C27: 5A120M58U01 | D27: =VLOOKUP($C27,Sheet1!$A$2:$D$10,2,0) -> 114010-50820 | E27: CYLINDER ASSY,BK MASTER W/ECU | F27: 46030 | G27: 0.35416667 | H27: CA-01 | I27: AC5 | J27: 17 | K27: =VLOOKUP($C27,Sheet1!$A$2:$D$10,4,0) -> 1 | L27: =VLOOKUP($C27,Sheet1!$A$2:$E$10,5,0) -> Bin | M27: =J27/K27 -> 17 | O27: HR47E8635 | P27: 12505Q100051
A28: G/I/25-26/01560 | B28: 08N618724000AC5 | C28: 5A120M58U50 | D28: =VLOOKUP($C28,Sheet1!$A$2:$D$10,2,0) -> 114010-50830 | E28: CYLINDER ASSY,BK MASTER W/ECU | F28: 46030 | G28: 0.35416667 | H28: CA-01 | I28: AC5 | J28: 44 | K28: =VLOOKUP($C28,Sheet1!$A$2:$D$10,4,0) -> 1 | L28: =VLOOKUP($C28,Sheet1!$A$2:$E$10,5,0) -> Bin | M28: =J28/K28 -> 44 | O28: HR47E8635 | P28: 12505Q100064-20 Qt. / 12505Q100086 -24 Qty.
M29: 110 | N29: 8
A30: G/I/25-26/01561 | B30: 08N618723691AC5 | C30: 55101M58U10 | D30: =VLOOKUP($C30,Sheet1!$A$2:$D$10,2,0) -> 141110-14600 | E30: CALIPER ASSY,FRONT BRAKE,R | F30: 46030 | G30: 0.5625 | H30: CA-07 | I30: AC5 | J30: 36 | K30: =VLOOKUP($C30,Sheet1!$A$2:$D$10,4,0) -> 18 | L30: =VLOOKUP($C30,Sheet1!$A$2:$E$10,5,0) -> Trolley (H) | N30: 2 | O30: HR47E2937 | P30: AN0250010911
A31: G/I/25-26/01561 | B31: 08N618723730AC5 | C31: 55102M58U10 | D31: =VLOOKUP($C31,Sheet1!$A$2:$D$10,2,0) -> 141120-14600 | E31: CALIPER ASSY,FRONT BRAKE,L | F31: 46030 | G31: 0.5625 | H31: CA-07 | I31: AC5 | J31: 36 | K31: =VLOOKUP($C31,Sheet1!$A$2:$D$10,4,0) -> 18 | L31: =VLOOKUP($C31,Sheet1!$A$2:$E$10,5,0) -> Trolley (H) | O31: HR47E2937 | P31: AN0250010911
A32: G/I/25-26/01561 | B32: 08N618723772AC5 | C32: 55311M58U00 | D32: =VLOOKUP($C32,Sheet1!$A$2:$D$10,2,0) -> 141185-74670 | E32: DISC,FRONT BRAKE | F32: 46030 | G32: 0.5625 | H32: CA-07 | I32: AC5 | J32: 80 | K32: =VLOOKUP($C32,Sheet1!$A$2:$D$10,4,0) -> 40 | L32: =VLOOKUP($C32,Sheet1!$A$2:$E$10,5,0) -> Trolley | N32: =J32/K32 -> 2 | O32: HR47E2937 | P32: 910104658
A33: G/I/25-26/01561 | B33: 08N618723810AC5 | C33: 55401M58U00 | D33: =VLOOKUP($C33,Sheet1!$A$2:$D$10,2,0) -> 141140-91211 | E33: CALIPER ASSY,REAR BRAKE,R | F33: 46030 | G33: 0.5625 | H33: CA-21 | I33: AC5 | J33: 44 | K33: =VLOOKUP($C33,Sheet1!$A$2:$D$10,4,0) -> 2 | L33: =VLOOKUP($C33,Sheet1!$A$2:$E$10,5,0) -> Bin | M33: =J33/K33 -> 22 | O33: HR47E2937 | P33: 12505Q100043
A34: G/I/25-26/01561 | B34: 08N618723853AC5 | C34: 55402M58U00 | D34: =VLOOKUP($C34,Sheet1!$A$2:$D$10,2,0) -> 141150-91211 | E34: CALIPER ASSY,REAR BRAKE,L | F34: 46030 | G34: 0.5625 | H34: CA-21 | I34: AC5 | J34: 44 | K34: =VLOOKUP($C34,Sheet1!$A$2:$D$10,4,0) -> 2 | L34: =VLOOKUP($C34,Sheet1!$A$2:$E$10,5,0) -> Bin | M34: =J34/K34 -> 22 | O34: HR47E2937 | P34: 12505Q100031
A35: G/I/25-26/01561 | B35: 08N618723896AC5 | C35: 55611M58U00 | D35: =VLOOKUP($C35,Sheet1!$A$2:$D$10,2,0) -> 141186-74360 | E35: DISC,REAR BRAKE | F35: 46030 | G35: 0.5625 | H35: CA-21 | I35: AC5 | J35: 80 | K35: =VLOOKUP($C35,Sheet1!$A$2:$D$10,4,0) -> 40 | L35: =VLOOKUP($C35,Sheet1!$A$2:$E$10,5,0) -> Trolley | N35: =J35/K35 -> 2 | O35: HR47E2937 | P35: 910104269-53 Qty. / 910104658-27 Qty.
A36: G/I/25-26/01562 | B36: 08N618723934AC5 | C36: 56110M58UA1 | D36: =VLOOKUP($C36,Sheet1!$A$2:$D$10,2,0) -> 116040-92240 | E36: ACTUATOR ASSY,NO VARIANT ESP | F36: 46030 | G36: 0.5625 | H36: CA-01 | I36: AC5 | J36: 48 | K36: =VLOOKUP($C36,Sheet1!$A$2:$D$10,4,0) -> 6 | L36: =VLOOKUP($C36,Sheet1!$A$2:$E$10,5,0) -> Bin | M36: =J36/K36 -> 8 | O36: HR47E2937 | P36: 12506Q100012
A37: G/I/25-26/01562 | B37: 08N618723977AC5 | C37: 5A120M58U01 | D37: =VLOOKUP($C37,Sheet1!$A$2:$D$10,2,0) -> 114010-50820 | E37: CYLINDER ASSY,BK MASTER W/ECU | F37: 46030 | G37: 0.5625 | H37: CA-01 | I37: AC5 | J37: 17 | K37: =VLOOKUP($C37,Sheet1!$A$2:$D$10,4,0) -> 1 | L37: =VLOOKUP($C37,Sheet1!$A$2:$E$10,5,0) -> Bin | M37: =J37/K37 -> 17 | O37: HR47E2937 | P37: 12505Q100051
A38: G/I/25-26/01562 | B38: 08N618724019AC5 | C38: 5A120M58U50 | D38: =VLOOKUP($C38,Sheet1!$A$2:$D$10,2,0) -> 114010-50830 | E38: CYLINDER ASSY,BK MASTER W/ECU | F38: 46030 | G38: 0.5625 | H38: CA-01 | I38: AC5 | J38: 26 | K38: =VLOOKUP($C38,Sheet1!$A$2:$D$10,4,0) -> 1 | L38: =VLOOKUP($C38,Sheet1!$A$2:$E$10,5,0) -> Bin | M38: =J38/K38 -> 26 | O38: HR47E2937 | P38: 12505Q100086
M39: 95 | N39: 6
A40: G/I/25-26/01567 | B40: AR446644558AD2 | C40: 55101M58U10 | D40: =VLOOKUP($C40,Sheet1!$A$2:$D$10,2,0) -> 141110-14600 | F40: 46030 | G40: DI YMC | H40: DA-01 | J40: 27 | K40: =VLOOKUP($C40,Sheet1!$A$2:$D$10,4,0) -> 18 | L40: =VLOOKUP($C40,Sheet1!$A$2:$E$10,5,0) -> Trolley (H) | N40: 2 | O40: HR47G9416 | P40: AN0250010996
...

Sheet 09-01-2026
J1: 24AACCN5739J1ZA
A2: Supply Month | B2: 46031 | L2: Vehicle No
A3: INVOICE NO | B3: KANBAN NO | C3: PART NUMBER | D3: Material Code | E3: PART NAME | F3: SUPPLY DATE | G3: SUPPLY TIME | H3: UNLOADING LOC | I3: Line | J3: Qty Req | K3: Packing Standerd | L3: Packed in | M3: TTL Bin | N3: TORLLY | O3: Vehicle No | P3: INV NO
A4: G/I/25-26/01570 | B4: 09N619382731AC5 | C4: 55101M58U10 | D4: =VLOOKUP($C4,Sheet1!$A$2:$D$10,2,0) -> 141110-14600 | E4: CALIPER ASSY,FRONT BRAKE,R | F4: 46031 | G4: 0.35416667 | H4: CA-07 | I4: AC5 | J4: 54 | K4: =VLOOKUP($C4,Sheet1!$A$2:$D$10,4,0) -> 18 | L4: =VLOOKUP($C4,Sheet1!$A$2:$E$10,5,0) -> Trolley (H) | N4: 3 | O4: HR47E2937 | P4: AN0250010911-42 Qty. / AN0250010996 -12 Qty.
A5: G/I/25-26/01570 | B5: 09N619382774AC5 | C5: 55102M58U10 | D5: =VLOOKUP($C5,Sheet1!$A$2:$D$10,2,0) -> 141120-14600 | E5: CALIPER ASSY,FRONT BRAKE,L | F5: 46031 | G5: 0.35416667 | H5: CA-07 | I5: AC5 | J5: 54 | K5: =VLOOKUP($C5,Sheet1!$A$2:$D$10,4,0) -> 18 | L5: =VLOOKUP($C5,Sheet1!$A$2:$E$10,5,0) -> Trolley (H) | O5: HR47E2937 | P5: AN0250010911-43 Qty. / AN0250010996 -11 Qty.
A6: G/I/25-26/01570 | B6: 09N619382812AC5 | C6: 55311M58U00 | D6: =VLOOKUP($C6,Sheet1!$A$2:$D$10,2,0) -> 141185-74670 | E6: DISC,FRONT BRAKE | F6: 46031 | G6: 0.35416667 | H6: CA-07 | I6: AC5 | J6: 120 | K6: =VLOOKUP($C6,Sheet1!$A$2:$D$10,4,0) -> 40 | L6: =VLOOKUP($C6,Sheet1!$A$2:$E$10,5,0) -> Trolley | N6: =J6/K6 -> 3 | O6: HR47E2937 | P6: 910104658
A7: G/I/25-26/01570 | B7: 09N619382855AC5 | C7: 55401M58U00 | D7: =VLOOKUP($C7,Sheet1!$A$2:$D$10,2,0) -> 141140-91211 | E7: CALIPER ASSY,REAR BRAKE,R | F7: 46031 | G7: 0.35416667 | H7: CA-21 | I7: AC5 | J7: 76 | K7: =VLOOKUP($C7,Sheet1!$A$2:$D$10,4,0) -> 2 | L7: =VLOOKUP($C7,Sheet1!$A$2:$E$10,5,0) -> Bin | M7: =J7/K7 -> 38 | O7: HR47E2937 | P7: 12505Q100031
